package com.eternaldoom.realmsofchaos.gen;

import java.util.List;
import java.util.Random;

import net.minecraft.block.Block;
import net.minecraft.init.Blocks;
import net.minecraft.init.Items;
import net.minecraft.item.Item;
import net.minecraft.tileentity.TileEntityMobSpawner;
import net.minecraft.util.BlockPos;
import net.minecraft.util.WeightedRandomChestContent;
import net.minecraft.world.World;
import net.minecraft.world.gen.feature.WorldGenerator;

import com.eternaldoom.realmsofchaos.blocks.ROCBlocks;
import com.eternaldoom.realmsofchaos.blocks.TileEntityNetherChest;
import com.eternaldoom.realmsofchaos.items.ROCItems;
import com.google.common.collect.Lists;

public class WorldGenNetherDungeon extends WorldGenerator {
    public static final List cheststuff = Lists.newArrayList(new WeightedRandomChestContent[] {new WeightedRandomChestContent(Items.diamond, 0, 1, 3, 3), new WeightedRandomChestContent(ROCItems.xylite_ingot, 0, 1, 2, 1), new WeightedRandomChestContent(Item.getItemFromBlock(Blocks.gold_block), 0, 1, 2, 2), new WeightedRandomChestContent(Items.golden_horse_armor, 0, 1, 1, 2), new WeightedRandomChestContent(Items.diamond_horse_armor, 0, 1, 1, 1), new WeightedRandomChestContent(Items.saddle, 0, 1, 1, 2), new WeightedRandomChestContent(ROCItems.scorpion_stone, 0, 1, 1, 1)});
	
    private BlockPos helperPos = new BlockPos(0, 0, 0);
    private World helperWorld = null;
    
    public boolean generate(World world, Random rand, BlockPos pos) {
    	
    	int i = pos.getX(), j = pos.getY(), k = pos.getZ();
    	helperWorld = world;

		if(world.getBlockState(pos.add(20, 0, 0)).getBlock() == Blocks.netherrack && world.getBlockState(pos.add(20, 6, 0)).getBlock() == Blocks.netherrack && world.getBlockState(pos.add(20, 0, 20)).getBlock() == Blocks.netherrack && world.getBlockState(pos.add(20, 6, 20)).getBlock() == Blocks.netherrack && world.getBlockState(pos.add(0, 0, 20)).getBlock() == Blocks.netherrack && world.getBlockState(pos.add(0, 6, 20)).getBlock() == Blocks.netherrack){
		
			setBlock(i + 0, j + 0, k + 0, Blocks.netherrack);
			setBlock(i + 0, j + 0, k + 1, Blocks.netherrack);
			setBlock(i + 0, j + 0, k + 2, Blocks.netherrack);
			setBlock(i + 0, j + 0, k + 3, Blocks.netherrack);
			setBlock(i + 0, j + 0, k + 4, Blocks.netherrack);
			setBlock(i + 0, j + 0, k + 5, Blocks.netherrack);
			setBlock(i + 0, j + 0, k + 6, Blocks.netherrack);
			setBlock(i + 0, j + 0, k + 7, Blocks.nether_brick);
			setBlock(i + 0, j + 0, k + 8, Blocks.nether_brick);
			setBlock(i + 0, j + 0, k + 9, Blocks.netherrack);
			setBlock(i + 0, j + 0, k + 10, Blocks.netherrack);
			setBlock(i + 0, j + 0, k + 11, Blocks.netherrack);
			setBlock(i + 0, j + 0, k + 12, Blocks.netherrack);
			setBlock(i + 0, j + 0, k + 13, Blocks.netherrack);
			setBlock(i + 0, j + 0, k + 14, Blocks.netherrack);
			setBlock(i + 0, j + 0, k + 15, Blocks.netherrack);
			setBlock(i + 0, j + 1, k + 0, Blocks.netherrack);
			setBlock(i + 0, j + 1, k + 1, Blocks.netherrack);
			setBlock(i + 0, j + 1, k + 2, Blocks.netherrack);
			setBlock(i + 0, j + 1, k + 3, Blocks.netherrack);
			setBlock(i + 0, j + 1, k + 4, Blocks.netherrack);
			setBlock(i + 0, j + 1, k + 5, Blocks.netherrack);
			setBlock(i + 0, j + 1, k + 6, Blocks.netherrack);
			setBlock(i + 0, j + 1, k + 7, ROCBlocks.netherrack_bricks);
			setBlock(i + 0, j + 1, k + 8, ROCBlocks.netherrack_bricks);
			setBlock(i + 0, j + 1, k + 9, Blocks.netherrack);
			setBlock(i + 0, j + 1, k + 10, Blocks.netherrack);
			setBlock(i + 0, j + 1, k + 11, Blocks.netherrack);
			setBlock(i + 0, j + 1, k + 12, Blocks.netherrack);
			setBlock(i + 0, j + 1, k + 13, Blocks.netherrack);
			setBlock(i + 0, j + 1, k + 14, Blocks.netherrack);
			setBlock(i + 0, j + 1, k + 15, Blocks.netherrack);
			setBlock(i + 0, j + 2, k + 0, Blocks.netherrack);
			setBlock(i + 0, j + 2, k + 1, Blocks.netherrack);
			setBlock(i + 0, j + 2, k + 2, Blocks.netherrack);
			setBlock(i + 0, j + 2, k + 3, Blocks.netherrack);
			setBlock(i + 0, j + 2, k + 4, Blocks.netherrack);
			setBlock(i + 0, j + 2, k + 5, Blocks.netherrack);
			setBlock(i + 0, j + 2, k + 6, Blocks.netherrack);
			setBlock(i + 0, j + 2, k + 7, ROCBlocks.netherrack_bricks);
			setBlock(i + 0, j + 2, k + 8, ROCBlocks.netherrack_bricks);
			setBlock(i + 0, j + 2, k + 9, Blocks.netherrack);
			setBlock(i + 0, j + 2, k + 10, Blocks.netherrack);
			setBlock(i + 0, j + 2, k + 11, Blocks.netherrack);
			setBlock(i + 0, j + 2, k + 12, Blocks.netherrack);
			setBlock(i + 0, j + 2, k + 13, Blocks.netherrack);
			setBlock(i + 0, j + 2, k + 14, Blocks.netherrack);
			setBlock(i + 0, j + 2, k + 15, Blocks.netherrack);
			setBlock(i + 0, j + 3, k + 0, Blocks.netherrack);
			setBlock(i + 0, j + 3, k + 1, Blocks.netherrack);
			setBlock(i + 0, j + 3, k + 2, Blocks.netherrack);
			setBlock(i + 0, j + 3, k + 3, Blocks.netherrack);
			setBlock(i + 0, j + 3, k + 4, Blocks.netherrack);
			setBlock(i + 0, j + 3, k + 5, Blocks.netherrack);
			setBlock(i + 0, j + 3, k + 6, Blocks.netherrack);
			setBlock(i + 0, j + 3, k + 7, ROCBlocks.netherrack_bricks);
			setBlock(i + 0, j + 3, k + 8, ROCBlocks.netherrack_bricks);
			setBlock(i + 0, j + 3, k + 9, Blocks.netherrack);
			setBlock(i + 0, j + 3, k + 10, Blocks.netherrack);
			setBlock(i + 0, j + 3, k + 11, Blocks.netherrack);
			setBlock(i + 0, j + 3, k + 12, Blocks.netherrack);
			setBlock(i + 0, j + 3, k + 13, Blocks.netherrack);
			setBlock(i + 0, j + 3, k + 14, Blocks.netherrack);
			setBlock(i + 0, j + 3, k + 15, Blocks.netherrack);
			setBlock(i + 0, j + 4, k + 0, Blocks.netherrack);
			setBlock(i + 0, j + 4, k + 1, Blocks.netherrack);
			setBlock(i + 0, j + 4, k + 2, Blocks.netherrack);
			setBlock(i + 0, j + 4, k + 3, Blocks.netherrack);
			setBlock(i + 0, j + 4, k + 4, Blocks.netherrack);
			setBlock(i + 0, j + 4, k + 5, Blocks.netherrack);
			setBlock(i + 0, j + 4, k + 6, Blocks.netherrack);
			setBlock(i + 0, j + 4, k + 7, ROCBlocks.netherrack_bricks);
			setBlock(i + 0, j + 4, k + 8, ROCBlocks.netherrack_bricks);
			setBlock(i + 0, j + 4, k + 9, Blocks.netherrack);
			setBlock(i + 0, j + 4, k + 10, Blocks.netherrack);
			setBlock(i + 0, j + 4, k + 11, Blocks.netherrack);
			setBlock(i + 0, j + 4, k + 12, Blocks.netherrack);
			setBlock(i + 0, j + 4, k + 13, Blocks.netherrack);
			setBlock(i + 0, j + 4, k + 14, Blocks.netherrack);
			setBlock(i + 0, j + 4, k + 15, Blocks.netherrack);
			setBlock(i + 1, j + 0, k + 0, Blocks.netherrack);
			setBlock(i + 1, j + 0, k + 1, Blocks.netherrack);
			setBlock(i + 1, j + 0, k + 2, Blocks.netherrack);
			setBlock(i + 1, j + 0, k + 3, Blocks.netherrack);
			setBlock(i + 1, j + 0, k + 4, Blocks.netherrack);
			setBlock(i + 1, j + 0, k + 5, Blocks.nether_brick);
			setBlock(i + 1, j + 0, k + 6, Blocks.nether_brick);
			setBlock(i + 1, j + 0, k + 7, Blocks.nether_brick);
			setBlock(i + 1, j + 0, k + 8, Blocks.nether_brick);
			setBlock(i + 1, j + 0, k + 9, Blocks.nether_brick);
			setBlock(i + 1, j + 0, k + 10, Blocks.nether_brick);
			setBlock(i + 1, j + 0, k + 11, Blocks.netherrack);
			setBlock(i + 1, j + 0, k + 12, Blocks.netherrack);
			setBlock(i + 1, j + 0, k + 13, Blocks.netherrack);
			setBlock(i + 1, j + 0, k + 14, Blocks.netherrack);
			setBlock(i + 1, j + 0, k + 15, Blocks.netherrack);
			setBlock(i + 1, j + 1, k + 0, Blocks.netherrack);
			setBlock(i + 1, j + 1, k + 1, Blocks.netherrack);
			setBlock(i + 1, j + 1, k + 2, Blocks.netherrack);
			setBlock(i + 1, j + 1, k + 3, Blocks.netherrack);
			setBlock(i + 1, j + 1, k + 4, Blocks.netherrack);
			setBlock(i + 1, j + 1, k + 5, ROCBlocks.netherrack_bricks);
			setBlock(i + 1, j + 1, k + 6, ROCBlocks.netherrack_bricks);
			setBlock(i + 1, j + 1, k + 7, ROCBlocks.nether_chest, 5, 2);
			setBlock(i + 1, j + 1, k + 8, ROCBlocks.nether_chest, 5, 2);
			TileEntityNetherChest chest = (TileEntityNetherChest)world.getTileEntity(pos.add(1, 1, 8));
			if (chest != null) WeightedRandomChestContent.generateChestContents(rand, cheststuff, chest, 10);
			setBlock(i + 1, j + 1, k + 9, ROCBlocks.netherrack_bricks);
			setBlock(i + 1, j + 1, k + 10, ROCBlocks.netherrack_bricks);
			setBlock(i + 1, j + 1, k + 11, Blocks.netherrack);
			setBlock(i + 1, j + 1, k + 12, Blocks.netherrack);
			setBlock(i + 1, j + 1, k + 13, Blocks.netherrack);
			setBlock(i + 1, j + 1, k + 14, Blocks.netherrack);
			setBlock(i + 1, j + 1, k + 15, Blocks.netherrack);
			setBlock(i + 1, j + 2, k + 0, Blocks.netherrack);
			setBlock(i + 1, j + 2, k + 1, Blocks.netherrack);
			setBlock(i + 1, j + 2, k + 2, Blocks.netherrack);
			setBlock(i + 1, j + 2, k + 3, Blocks.netherrack);
			setBlock(i + 1, j + 2, k + 4, Blocks.netherrack);
			setBlock(i + 1, j + 2, k + 5, ROCBlocks.netherrack_bricks);
			setBlock(i + 1, j + 2, k + 6, ROCBlocks.netherrack_bricks);
			setBlock(i + 1, j + 2, k + 7, Blocks.air);
			setBlock(i + 1, j + 2, k + 8, Blocks.air);
			setBlock(i + 1, j + 2, k + 9, ROCBlocks.netherrack_bricks);
			setBlock(i + 1, j + 2, k + 10, ROCBlocks.netherrack_bricks);
			setBlock(i + 1, j + 2, k + 11, Blocks.netherrack);
			setBlock(i + 1, j + 2, k + 12, Blocks.netherrack);
			setBlock(i + 1, j + 2, k + 13, Blocks.netherrack);
			setBlock(i + 1, j + 2, k + 14, Blocks.netherrack);
			setBlock(i + 1, j + 2, k + 15, Blocks.netherrack);
			setBlock(i + 1, j + 3, k + 0, Blocks.netherrack);
			setBlock(i + 1, j + 3, k + 1, Blocks.netherrack);
			setBlock(i + 1, j + 3, k + 2, Blocks.netherrack);
			setBlock(i + 1, j + 3, k + 3, Blocks.netherrack);
			setBlock(i + 1, j + 3, k + 4, Blocks.netherrack);
			setBlock(i + 1, j + 3, k + 5, ROCBlocks.netherrack_bricks);
			setBlock(i + 1, j + 3, k + 6, ROCBlocks.netherrack_bricks);
			setBlock(i + 1, j + 3, k + 7, Blocks.air);
			setBlock(i + 1, j + 3, k + 8, Blocks.air);
			setBlock(i + 1, j + 3, k + 9, ROCBlocks.netherrack_bricks);
			setBlock(i + 1, j + 3, k + 10, ROCBlocks.netherrack_bricks);
			setBlock(i + 1, j + 3, k + 11, Blocks.netherrack);
			setBlock(i + 1, j + 3, k + 12, Blocks.netherrack);
			setBlock(i + 1, j + 3, k + 13, Blocks.netherrack);
			setBlock(i + 1, j + 3, k + 14, Blocks.netherrack);
			setBlock(i + 1, j + 3, k + 15, Blocks.netherrack);
			setBlock(i + 1, j + 4, k + 0, Blocks.netherrack);
			setBlock(i + 1, j + 4, k + 1, Blocks.netherrack);
			setBlock(i + 1, j + 4, k + 2, Blocks.netherrack);
			setBlock(i + 1, j + 4, k + 3, Blocks.netherrack);
			setBlock(i + 1, j + 4, k + 4, Blocks.netherrack);
			setBlock(i + 1, j + 4, k + 5, ROCBlocks.netherrack_bricks);
			setBlock(i + 1, j + 4, k + 6, ROCBlocks.netherrack_bricks);
			setBlock(i + 1, j + 4, k + 7, ROCBlocks.charwood_log);
			setBlock(i + 1, j + 4, k + 8, ROCBlocks.charwood_log);
			setBlock(i + 1, j + 4, k + 9, ROCBlocks.netherrack_bricks);
			setBlock(i + 1, j + 4, k + 10, ROCBlocks.netherrack_bricks);
			setBlock(i + 1, j + 4, k + 11, Blocks.netherrack);
			setBlock(i + 1, j + 4, k + 12, Blocks.netherrack);
			setBlock(i + 1, j + 4, k + 13, Blocks.netherrack);
			setBlock(i + 1, j + 4, k + 14, Blocks.netherrack);
			setBlock(i + 1, j + 4, k + 15, Blocks.netherrack);
			setBlock(i + 2, j + 0, k + 0, Blocks.netherrack);
			setBlock(i + 2, j + 0, k + 1, Blocks.netherrack);
			setBlock(i + 2, j + 0, k + 2, Blocks.netherrack);
			setBlock(i + 2, j + 0, k + 3, Blocks.nether_brick);
			setBlock(i + 2, j + 0, k + 4, Blocks.nether_brick);
			setBlock(i + 2, j + 0, k + 5, Blocks.nether_brick);
			setBlock(i + 2, j + 0, k + 6, Blocks.nether_brick);
			setBlock(i + 2, j + 0, k + 7, Blocks.nether_brick);
			setBlock(i + 2, j + 0, k + 8, Blocks.nether_brick);
			setBlock(i + 2, j + 0, k + 9, Blocks.nether_brick);
			setBlock(i + 2, j + 0, k + 10, Blocks.nether_brick);
			setBlock(i + 2, j + 0, k + 11, Blocks.nether_brick);
			setBlock(i + 2, j + 0, k + 12, Blocks.nether_brick);
			setBlock(i + 2, j + 0, k + 13, Blocks.netherrack);
			setBlock(i + 2, j + 0, k + 14, Blocks.netherrack);
			setBlock(i + 2, j + 0, k + 15, Blocks.netherrack);
			setBlock(i + 2, j + 1, k + 0, Blocks.netherrack);
			setBlock(i + 2, j + 1, k + 1, Blocks.netherrack);
			setBlock(i + 2, j + 1, k + 2, Blocks.netherrack);
			setBlock(i + 2, j + 1, k + 3, ROCBlocks.netherrack_bricks);
			setBlock(i + 2, j + 1, k + 4, ROCBlocks.netherrack_bricks);
			setBlock(i + 2, j + 1, k + 5, Blocks.air);
			setBlock(i + 2, j + 1, k + 6, Blocks.air);
			setBlock(i + 2, j + 1, k + 7, Blocks.air);
			setBlock(i + 2, j + 1, k + 8, Blocks.air);
			setBlock(i + 2, j + 1, k + 9, Blocks.air);
			setBlock(i + 2, j + 1, k + 10, Blocks.air);
			setBlock(i + 2, j + 1, k + 11, ROCBlocks.netherrack_bricks);
			setBlock(i + 2, j + 1, k + 12, ROCBlocks.netherrack_bricks);
			setBlock(i + 2, j + 1, k + 13, Blocks.netherrack);
			setBlock(i + 2, j + 1, k + 14, Blocks.netherrack);
			setBlock(i + 2, j + 1, k + 15, Blocks.netherrack);
			setBlock(i + 2, j + 2, k + 0, Blocks.netherrack);
			setBlock(i + 2, j + 2, k + 1, Blocks.netherrack);
			setBlock(i + 2, j + 2, k + 2, Blocks.netherrack);
			setBlock(i + 2, j + 2, k + 3, ROCBlocks.netherrack_bricks);
			setBlock(i + 2, j + 2, k + 4, ROCBlocks.netherrack_bricks);
			setBlock(i + 2, j + 2, k + 5, Blocks.air);
			setBlock(i + 2, j + 2, k + 6, Blocks.air);
			setBlock(i + 2, j + 2, k + 7, Blocks.air);
			setBlock(i + 2, j + 2, k + 8, Blocks.air);
			setBlock(i + 2, j + 2, k + 9, Blocks.air);
			setBlock(i + 2, j + 2, k + 10, Blocks.air);
			setBlock(i + 2, j + 2, k + 11, ROCBlocks.netherrack_bricks);
			setBlock(i + 2, j + 2, k + 12, ROCBlocks.netherrack_bricks);
			setBlock(i + 2, j + 2, k + 13, Blocks.netherrack);
			setBlock(i + 2, j + 2, k + 14, Blocks.netherrack);
			setBlock(i + 2, j + 2, k + 15, Blocks.netherrack);
			setBlock(i + 2, j + 3, k + 0, Blocks.netherrack);
			setBlock(i + 2, j + 3, k + 1, Blocks.netherrack);
			setBlock(i + 2, j + 3, k + 2, Blocks.netherrack);
			setBlock(i + 2, j + 3, k + 3, ROCBlocks.netherrack_bricks);
			setBlock(i + 2, j + 3, k + 4, ROCBlocks.netherrack_bricks);
			setBlock(i + 2, j + 3, k + 5, Blocks.air);
			setBlock(i + 2, j + 3, k + 6, Blocks.air);
			setBlock(i + 2, j + 3, k + 7, Blocks.air);
			setBlock(i + 2, j + 3, k + 8, Blocks.air);
			setBlock(i + 2, j + 3, k + 9, Blocks.air);
			setBlock(i + 2, j + 3, k + 10, Blocks.air);
			setBlock(i + 2, j + 3, k + 11, ROCBlocks.netherrack_bricks);
			setBlock(i + 2, j + 3, k + 12, ROCBlocks.netherrack_bricks);
			setBlock(i + 2, j + 3, k + 13, Blocks.netherrack);
			setBlock(i + 2, j + 3, k + 14, Blocks.netherrack);
			setBlock(i + 2, j + 3, k + 15, Blocks.netherrack);
			setBlock(i + 2, j + 4, k + 0, Blocks.netherrack);
			setBlock(i + 2, j + 4, k + 1, Blocks.netherrack);
			setBlock(i + 2, j + 4, k + 2, Blocks.netherrack);
			setBlock(i + 2, j + 4, k + 3, ROCBlocks.netherrack_bricks);
			setBlock(i + 2, j + 4, k + 4, ROCBlocks.netherrack_bricks);
			setBlock(i + 2, j + 4, k + 5, ROCBlocks.charwood_log);
			setBlock(i + 2, j + 4, k + 6, ROCBlocks.charwood_log);
			setBlock(i + 2, j + 4, k + 7, ROCBlocks.charwood_log);
			setBlock(i + 2, j + 4, k + 8, ROCBlocks.charwood_log);
			setBlock(i + 2, j + 4, k + 9, ROCBlocks.charwood_log);
			setBlock(i + 2, j + 4, k + 10, ROCBlocks.charwood_log);
			setBlock(i + 2, j + 4, k + 11, ROCBlocks.netherrack_bricks);
			setBlock(i + 2, j + 4, k + 12, ROCBlocks.netherrack_bricks);
			setBlock(i + 2, j + 4, k + 13, Blocks.netherrack);
			setBlock(i + 2, j + 4, k + 14, Blocks.netherrack);
			setBlock(i + 2, j + 4, k + 15, Blocks.netherrack);
			setBlock(i + 3, j + 0, k + 0, Blocks.netherrack);
			setBlock(i + 3, j + 0, k + 1, Blocks.netherrack);
			setBlock(i + 3, j + 0, k + 2, Blocks.nether_brick);
			setBlock(i + 3, j + 0, k + 3, Blocks.nether_brick);
			setBlock(i + 3, j + 0, k + 4, Blocks.nether_brick);
			setBlock(i + 3, j + 0, k + 5, Blocks.nether_brick);
			setBlock(i + 3, j + 0, k + 6, Blocks.nether_brick);
			setBlock(i + 3, j + 0, k + 7, Blocks.nether_brick);
			setBlock(i + 3, j + 0, k + 8, Blocks.nether_brick);
			setBlock(i + 3, j + 0, k + 9, Blocks.nether_brick);
			setBlock(i + 3, j + 0, k + 10, Blocks.nether_brick);
			setBlock(i + 3, j + 0, k + 11, Blocks.nether_brick);
			setBlock(i + 3, j + 0, k + 12, Blocks.nether_brick);
			setBlock(i + 3, j + 0, k + 13, Blocks.nether_brick);
			setBlock(i + 3, j + 0, k + 14, Blocks.netherrack);
			setBlock(i + 3, j + 0, k + 15, Blocks.netherrack);
			setBlock(i + 3, j + 1, k + 0, Blocks.netherrack);
			setBlock(i + 3, j + 1, k + 1, Blocks.netherrack);
			setBlock(i + 3, j + 1, k + 2, ROCBlocks.netherrack_bricks);
			setBlock(i + 3, j + 1, k + 3, Blocks.air);
			setBlock(i + 3, j + 1, k + 4, Blocks.air);
			setBlock(i + 3, j + 1, k + 5, Blocks.air);
			setBlock(i + 3, j + 1, k + 6, Blocks.air);
			setBlock(i + 3, j + 1, k + 7, Blocks.air);
			setBlock(i + 3, j + 1, k + 8, Blocks.air);
			setBlock(i + 3, j + 1, k + 9, Blocks.air);
			setBlock(i + 3, j + 1, k + 10, Blocks.air);
			setBlock(i + 3, j + 1, k + 11, Blocks.air);
			setBlock(i + 3, j + 1, k + 12, Blocks.air);
			setBlock(i + 3, j + 1, k + 13, ROCBlocks.netherrack_bricks);
			setBlock(i + 3, j + 1, k + 14, Blocks.netherrack);
			setBlock(i + 3, j + 1, k + 15, Blocks.netherrack);
			setBlock(i + 3, j + 2, k + 0, Blocks.netherrack);
			setBlock(i + 3, j + 2, k + 1, Blocks.netherrack);
			setBlock(i + 3, j + 2, k + 2, ROCBlocks.netherrack_bricks);
			setBlock(i + 3, j + 2, k + 3, Blocks.air);
			setBlock(i + 3, j + 2, k + 4, Blocks.air);
			setBlock(i + 3, j + 2, k + 5, Blocks.air);
			setBlock(i + 3, j + 2, k + 6, Blocks.air);
			setBlock(i + 3, j + 2, k + 7, Blocks.air);
			setBlock(i + 3, j + 2, k + 8, Blocks.air);
			setBlock(i + 3, j + 2, k + 9, Blocks.air);
			setBlock(i + 3, j + 2, k + 10, Blocks.air);
			setBlock(i + 3, j + 2, k + 11, Blocks.air);
			setBlock(i + 3, j + 2, k + 12, Blocks.air);
			setBlock(i + 3, j + 2, k + 13, ROCBlocks.netherrack_bricks);
			setBlock(i + 3, j + 2, k + 14, Blocks.netherrack);
			setBlock(i + 3, j + 2, k + 15, Blocks.netherrack);
			setBlock(i + 3, j + 3, k + 0, Blocks.netherrack);
			setBlock(i + 3, j + 3, k + 1, Blocks.netherrack);
			setBlock(i + 3, j + 3, k + 2, ROCBlocks.netherrack_bricks);
			setBlock(i + 3, j + 3, k + 3, Blocks.air);
			setBlock(i + 3, j + 3, k + 4, Blocks.air);
			setBlock(i + 3, j + 3, k + 5, Blocks.air);
			setBlock(i + 3, j + 3, k + 6, Blocks.air);
			setBlock(i + 3, j + 3, k + 7, Blocks.air);
			setBlock(i + 3, j + 3, k + 8, Blocks.air);
			setBlock(i + 3, j + 3, k + 9, Blocks.air);
			setBlock(i + 3, j + 3, k + 10, Blocks.air);
			setBlock(i + 3, j + 3, k + 11, Blocks.air);
			setBlock(i + 3, j + 3, k + 12, Blocks.air);
			setBlock(i + 3, j + 3, k + 13, ROCBlocks.netherrack_bricks);
			setBlock(i + 3, j + 3, k + 14, Blocks.netherrack);
			setBlock(i + 3, j + 3, k + 15, Blocks.netherrack);
			setBlock(i + 3, j + 4, k + 0, Blocks.netherrack);
			setBlock(i + 3, j + 4, k + 1, Blocks.netherrack);
			setBlock(i + 3, j + 4, k + 2, ROCBlocks.netherrack_bricks);
			setBlock(i + 3, j + 4, k + 3, ROCBlocks.charwood_log);
			setBlock(i + 3, j + 4, k + 4, ROCBlocks.charwood_log);
			setBlock(i + 3, j + 4, k + 5, ROCBlocks.charwood_log);
			setBlock(i + 3, j + 4, k + 6, ROCBlocks.charwood_log);
			setBlock(i + 3, j + 4, k + 7, ROCBlocks.charwood_log);
			setBlock(i + 3, j + 4, k + 8, ROCBlocks.charwood_log);
			setBlock(i + 3, j + 4, k + 9, ROCBlocks.charwood_log);
			setBlock(i + 3, j + 4, k + 10, ROCBlocks.charwood_log);
			setBlock(i + 3, j + 4, k + 11, ROCBlocks.charwood_log);
			setBlock(i + 3, j + 4, k + 12, ROCBlocks.charwood_log);
			setBlock(i + 3, j + 4, k + 13, ROCBlocks.netherrack_bricks);
			setBlock(i + 3, j + 4, k + 14, Blocks.netherrack);
			setBlock(i + 3, j + 4, k + 15, Blocks.netherrack);
			setBlock(i + 4, j + 0, k + 0, Blocks.netherrack);
			setBlock(i + 4, j + 0, k + 1, Blocks.nether_brick);
			setBlock(i + 4, j + 0, k + 2, Blocks.nether_brick);
			setBlock(i + 4, j + 0, k + 3, Blocks.nether_brick);
			setBlock(i + 4, j + 0, k + 4, Blocks.nether_brick);
			setBlock(i + 4, j + 0, k + 5, Blocks.nether_brick);
			setBlock(i + 4, j + 0, k + 6, Blocks.nether_brick);
			setBlock(i + 4, j + 0, k + 7, Blocks.nether_brick);
			setBlock(i + 4, j + 0, k + 8, Blocks.nether_brick);
			setBlock(i + 4, j + 0, k + 9, Blocks.nether_brick);
			setBlock(i + 4, j + 0, k + 10, Blocks.nether_brick);
			setBlock(i + 4, j + 0, k + 11, Blocks.nether_brick);
			setBlock(i + 4, j + 0, k + 12, Blocks.nether_brick);
			setBlock(i + 4, j + 0, k + 13, Blocks.nether_brick);
			setBlock(i + 4, j + 0, k + 14, Blocks.nether_brick);
			setBlock(i + 4, j + 0, k + 15, Blocks.netherrack);
			setBlock(i + 4, j + 1, k + 0, Blocks.netherrack);
			setBlock(i + 4, j + 1, k + 1, ROCBlocks.netherrack_bricks);
			setBlock(i + 4, j + 1, k + 2, Blocks.air);
			setBlock(i + 4, j + 1, k + 3, Blocks.air);
			setBlock(i + 4, j + 1, k + 4, Blocks.air);
			setBlock(i + 4, j + 1, k + 5, Blocks.air);
			setBlock(i + 4, j + 1, k + 6, Blocks.air);
			setBlock(i + 4, j + 1, k + 7, Blocks.air);
			setBlock(i + 4, j + 1, k + 8, Blocks.air);
			setBlock(i + 4, j + 1, k + 9, Blocks.air);
			setBlock(i + 4, j + 1, k + 10, Blocks.air);
			setBlock(i + 4, j + 1, k + 11, Blocks.air);
			setBlock(i + 4, j + 1, k + 12, Blocks.air);
			setBlock(i + 4, j + 1, k + 13, Blocks.air);
			setBlock(i + 4, j + 1, k + 14, ROCBlocks.netherrack_bricks);
			setBlock(i + 4, j + 1, k + 15, Blocks.netherrack);
			setBlock(i + 4, j + 2, k + 0, Blocks.netherrack);
			setBlock(i + 4, j + 2, k + 1, ROCBlocks.netherrack_bricks);
			setBlock(i + 4, j + 2, k + 2, Blocks.air);
			setBlock(i + 4, j + 2, k + 3, Blocks.air);
			setBlock(i + 4, j + 2, k + 4, Blocks.air);
			setBlock(i + 4, j + 2, k + 5, Blocks.air);
			setBlock(i + 4, j + 2, k + 6, Blocks.air);
			setBlock(i + 4, j + 2, k + 7, Blocks.air);
			setBlock(i + 4, j + 2, k + 8, Blocks.air);
			setBlock(i + 4, j + 2, k + 9, Blocks.air);
			setBlock(i + 4, j + 2, k + 10, Blocks.air);
			setBlock(i + 4, j + 2, k + 11, Blocks.air);
			setBlock(i + 4, j + 2, k + 12, Blocks.air);
			setBlock(i + 4, j + 2, k + 13, Blocks.air);
			setBlock(i + 4, j + 2, k + 14, ROCBlocks.netherrack_bricks);
			setBlock(i + 4, j + 2, k + 15, Blocks.netherrack);
			setBlock(i + 4, j + 3, k + 0, Blocks.netherrack);
			setBlock(i + 4, j + 3, k + 1, ROCBlocks.netherrack_bricks);
			setBlock(i + 4, j + 3, k + 2, Blocks.air);
			setBlock(i + 4, j + 3, k + 3, Blocks.air);
			setBlock(i + 4, j + 3, k + 4, Blocks.air);
			setBlock(i + 4, j + 3, k + 5, Blocks.air);
			setBlock(i + 4, j + 3, k + 6, Blocks.air);
			setBlock(i + 4, j + 3, k + 7, Blocks.air);
			setBlock(i + 4, j + 3, k + 8, Blocks.air);
			setBlock(i + 4, j + 3, k + 9, Blocks.air);
			setBlock(i + 4, j + 3, k + 10, Blocks.air);
			setBlock(i + 4, j + 3, k + 11, Blocks.air);
			setBlock(i + 4, j + 3, k + 12, Blocks.air);
			setBlock(i + 4, j + 3, k + 13, Blocks.air);
			setBlock(i + 4, j + 3, k + 14, ROCBlocks.netherrack_bricks);
			setBlock(i + 4, j + 3, k + 15, Blocks.netherrack);
			setBlock(i + 4, j + 4, k + 0, Blocks.netherrack);
			setBlock(i + 4, j + 4, k + 1, ROCBlocks.netherrack_bricks);
			setBlock(i + 4, j + 4, k + 2, ROCBlocks.charwood_log);
			setBlock(i + 4, j + 4, k + 3, ROCBlocks.charwood_log);
			setBlock(i + 4, j + 4, k + 4, ROCBlocks.charwood_log);
			setBlock(i + 4, j + 4, k + 5, ROCBlocks.charwood_log);
			setBlock(i + 4, j + 4, k + 6, ROCBlocks.charwood_log);
			setBlock(i + 4, j + 4, k + 7, ROCBlocks.charwood_log);
			setBlock(i + 4, j + 4, k + 8, ROCBlocks.charwood_log);
			setBlock(i + 4, j + 4, k + 9, ROCBlocks.charwood_log);
			setBlock(i + 4, j + 4, k + 10, ROCBlocks.charwood_log);
			setBlock(i + 4, j + 4, k + 11, ROCBlocks.charwood_log);
			setBlock(i + 4, j + 4, k + 12, ROCBlocks.charwood_log);
			setBlock(i + 4, j + 4, k + 13, ROCBlocks.charwood_log);
			setBlock(i + 4, j + 4, k + 14, ROCBlocks.netherrack_bricks);
			setBlock(i + 4, j + 4, k + 15, Blocks.netherrack);
			setBlock(i + 5, j + 0, k + 0, Blocks.netherrack);
			setBlock(i + 5, j + 0, k + 1, Blocks.nether_brick);
			setBlock(i + 5, j + 0, k + 2, Blocks.nether_brick);
			setBlock(i + 5, j + 0, k + 3, Blocks.nether_brick);
			setBlock(i + 5, j + 0, k + 4, Blocks.nether_brick);
			setBlock(i + 5, j + 0, k + 5, Blocks.nether_brick);
			setBlock(i + 5, j + 0, k + 6, Blocks.nether_brick);
			setBlock(i + 5, j + 0, k + 7, Blocks.nether_brick);
			setBlock(i + 5, j + 0, k + 8, Blocks.nether_brick);
			setBlock(i + 5, j + 0, k + 9, Blocks.nether_brick);
			setBlock(i + 5, j + 0, k + 10, Blocks.nether_brick);
			setBlock(i + 5, j + 0, k + 11, Blocks.nether_brick);
			setBlock(i + 5, j + 0, k + 12, Blocks.nether_brick);
			setBlock(i + 5, j + 0, k + 13, Blocks.nether_brick);
			setBlock(i + 5, j + 0, k + 14, Blocks.nether_brick);
			setBlock(i + 5, j + 0, k + 15, Blocks.netherrack);
			setBlock(i + 5, j + 1, k + 0, Blocks.netherrack);
			setBlock(i + 5, j + 1, k + 1, ROCBlocks.netherrack_bricks);
			setBlock(i + 5, j + 1, k + 2, Blocks.air);
			setBlock(i + 5, j + 1, k + 3, Blocks.air);
			setBlock(i + 5, j + 1, k + 4, Blocks.air);
			setBlock(i + 5, j + 1, k + 5, Blocks.air);
			setBlock(i + 5, j + 1, k + 6, Blocks.air);
			setBlock(i + 5, j + 1, k + 7, Blocks.air);
			setBlock(i + 5, j + 1, k + 8, Blocks.air);
			setBlock(i + 5, j + 1, k + 9, Blocks.air);
			setBlock(i + 5, j + 1, k + 10, Blocks.air);
			setBlock(i + 5, j + 1, k + 11, Blocks.air);
			setBlock(i + 5, j + 1, k + 12, Blocks.air);
			setBlock(i + 5, j + 1, k + 13, Blocks.air);
			setBlock(i + 5, j + 1, k + 14, ROCBlocks.netherrack_bricks);
			setBlock(i + 5, j + 1, k + 15, Blocks.netherrack);
			setBlock(i + 5, j + 2, k + 0, Blocks.netherrack);
			setBlock(i + 5, j + 2, k + 1, ROCBlocks.netherrack_bricks);
			setBlock(i + 5, j + 2, k + 2, Blocks.air);
			setBlock(i + 5, j + 2, k + 3, Blocks.air);
			setBlock(i + 5, j + 2, k + 4, Blocks.air);
			setBlock(i + 5, j + 2, k + 5, Blocks.air);
			setBlock(i + 5, j + 2, k + 6, Blocks.air);
			setBlock(i + 5, j + 2, k + 7, Blocks.air);
			setBlock(i + 5, j + 2, k + 8, Blocks.air);
			setBlock(i + 5, j + 2, k + 9, Blocks.air);
			setBlock(i + 5, j + 2, k + 10, Blocks.air);
			setBlock(i + 5, j + 2, k + 11, Blocks.air);
			setBlock(i + 5, j + 2, k + 12, Blocks.air);
			setBlock(i + 5, j + 2, k + 13, Blocks.air);
			setBlock(i + 5, j + 2, k + 14, ROCBlocks.netherrack_bricks);
			setBlock(i + 5, j + 2, k + 15, Blocks.netherrack);
			setBlock(i + 5, j + 3, k + 0, Blocks.netherrack);
			setBlock(i + 5, j + 3, k + 1, ROCBlocks.netherrack_bricks);
			setBlock(i + 5, j + 3, k + 2, Blocks.air);
			setBlock(i + 5, j + 3, k + 3, Blocks.air);
			setBlock(i + 5, j + 3, k + 4, Blocks.air);
			setBlock(i + 5, j + 3, k + 5, Blocks.air);
			setBlock(i + 5, j + 3, k + 6, Blocks.air);
			setBlock(i + 5, j + 3, k + 7, Blocks.air);
			setBlock(i + 5, j + 3, k + 8, Blocks.air);
			setBlock(i + 5, j + 3, k + 9, Blocks.air);
			setBlock(i + 5, j + 3, k + 10, Blocks.air);
			setBlock(i + 5, j + 3, k + 11, Blocks.air);
			setBlock(i + 5, j + 3, k + 12, Blocks.air);
			setBlock(i + 5, j + 3, k + 13, Blocks.air);
			setBlock(i + 5, j + 3, k + 14, ROCBlocks.netherrack_bricks);
			setBlock(i + 5, j + 3, k + 15, Blocks.netherrack);
			setBlock(i + 5, j + 4, k + 0, Blocks.netherrack);
			setBlock(i + 5, j + 4, k + 1, ROCBlocks.netherrack_bricks);
			setBlock(i + 5, j + 4, k + 2, ROCBlocks.charwood_log);
			setBlock(i + 5, j + 4, k + 3, ROCBlocks.charwood_log);
			setBlock(i + 5, j + 4, k + 4, ROCBlocks.charwood_log);
			setBlock(i + 5, j + 4, k + 5, ROCBlocks.charwood_log);
			setBlock(i + 5, j + 4, k + 6, ROCBlocks.charwood_log);
			setBlock(i + 5, j + 4, k + 7, ROCBlocks.charwood_log);
			setBlock(i + 5, j + 4, k + 8, ROCBlocks.charwood_log);
			setBlock(i + 5, j + 4, k + 9, ROCBlocks.charwood_log);
			setBlock(i + 5, j + 4, k + 10, ROCBlocks.charwood_log);
			setBlock(i + 5, j + 4, k + 11, ROCBlocks.charwood_log);
			setBlock(i + 5, j + 4, k + 12, ROCBlocks.charwood_log);
			setBlock(i + 5, j + 4, k + 13, ROCBlocks.charwood_log);
			setBlock(i + 5, j + 4, k + 14, ROCBlocks.netherrack_bricks);
			setBlock(i + 5, j + 4, k + 15, Blocks.netherrack);
			setBlock(i + 6, j + 0, k + 0, Blocks.nether_brick);
			setBlock(i + 6, j + 0, k + 1, Blocks.nether_brick);
			setBlock(i + 6, j + 0, k + 2, Blocks.nether_brick);
			setBlock(i + 6, j + 0, k + 3, Blocks.nether_brick);
			setBlock(i + 6, j + 0, k + 4, Blocks.nether_brick);
			setBlock(i + 6, j + 0, k + 5, Blocks.nether_brick);
			setBlock(i + 6, j + 0, k + 6, Blocks.nether_brick);
			setBlock(i + 6, j + 0, k + 7, Blocks.nether_brick);
			setBlock(i + 6, j + 0, k + 8, Blocks.nether_brick);
			setBlock(i + 6, j + 0, k + 9, Blocks.nether_brick);
			setBlock(i + 6, j + 0, k + 10, Blocks.nether_brick);
			setBlock(i + 6, j + 0, k + 11, Blocks.nether_brick);
			setBlock(i + 6, j + 0, k + 12, Blocks.nether_brick);
			setBlock(i + 6, j + 0, k + 13, Blocks.nether_brick);
			setBlock(i + 6, j + 0, k + 14, Blocks.nether_brick);
			setBlock(i + 6, j + 0, k + 15, Blocks.nether_brick);
			setBlock(i + 6, j + 1, k + 0, ROCBlocks.netherrack_bricks);
			setBlock(i + 6, j + 1, k + 1, Blocks.mob_spawner);
			TileEntityMobSpawner spawner1 = (TileEntityMobSpawner)world.getTileEntity(pos.add(6, 1, 1));
			if (spawner1 != null) spawner1.getSpawnerBaseLogic().setEntityName("Blaze");
			setBlock(i + 6, j + 1, k + 2, Blocks.air);
			setBlock(i + 6, j + 1, k + 3, Blocks.air);
			setBlock(i + 6, j + 1, k + 4, Blocks.air);
			setBlock(i + 6, j + 1, k + 5, Blocks.air);
			setBlock(i + 6, j + 1, k + 6, ROCBlocks.netherrack_brick_stairs);
			setBlock(i + 6, j + 1, k + 7, ROCBlocks.netherrack_brick_stairs);
			setBlock(i + 6, j + 1, k + 8, ROCBlocks.netherrack_brick_stairs);
			setBlock(i + 6, j + 1, k + 9, ROCBlocks.netherrack_brick_stairs, 3, 2);
			setBlock(i + 6, j + 1, k + 10, Blocks.air);
			setBlock(i + 6, j + 1, k + 11, Blocks.air);
			setBlock(i + 6, j + 1, k + 12, Blocks.air);
			setBlock(i + 6, j + 1, k + 13, Blocks.air);
			setBlock(i + 6, j + 1, k + 14, Blocks.mob_spawner);
			TileEntityMobSpawner spawner2 = (TileEntityMobSpawner)world.getTileEntity(pos.add(6, 1, 14));
			if (spawner2 != null) spawner2.getSpawnerBaseLogic().setEntityName("Blaze");
			setBlock(i + 6, j + 1, k + 15, ROCBlocks.netherrack_bricks);
			setBlock(i + 6, j + 2, k + 0, ROCBlocks.netherrack_bricks);
			setBlock(i + 6, j + 2, k + 1, Blocks.air);
			setBlock(i + 6, j + 2, k + 2, Blocks.air);
			setBlock(i + 6, j + 2, k + 3, Blocks.air);
			setBlock(i + 6, j + 2, k + 4, Blocks.air);
			setBlock(i + 6, j + 2, k + 5, Blocks.air);
			setBlock(i + 6, j + 2, k + 6, Blocks.air);
			setBlock(i + 6, j + 2, k + 7, Blocks.air);
			setBlock(i + 6, j + 2, k + 8, Blocks.air);
			setBlock(i + 6, j + 2, k + 9, Blocks.air);
			setBlock(i + 6, j + 2, k + 10, Blocks.air);
			setBlock(i + 6, j + 2, k + 11, Blocks.air);
			setBlock(i + 6, j + 2, k + 12, Blocks.air);
			setBlock(i + 6, j + 2, k + 13, Blocks.air);
			setBlock(i + 6, j + 2, k + 14, Blocks.air);
			setBlock(i + 6, j + 2, k + 15, ROCBlocks.netherrack_bricks);
			setBlock(i + 6, j + 3, k + 0, ROCBlocks.netherrack_bricks);
			setBlock(i + 6, j + 3, k + 1, Blocks.air);
			setBlock(i + 6, j + 3, k + 2, Blocks.air);
			setBlock(i + 6, j + 3, k + 3, Blocks.air);
			setBlock(i + 6, j + 3, k + 4, Blocks.air);
			setBlock(i + 6, j + 3, k + 5, Blocks.air);
			setBlock(i + 6, j + 3, k + 6, Blocks.air);
			setBlock(i + 6, j + 3, k + 7, Blocks.air);
			setBlock(i + 6, j + 3, k + 8, Blocks.air);
			setBlock(i + 6, j + 3, k + 9, Blocks.air);
			setBlock(i + 6, j + 3, k + 10, Blocks.air);
			setBlock(i + 6, j + 3, k + 11, Blocks.air);
			setBlock(i + 6, j + 3, k + 12, Blocks.air);
			setBlock(i + 6, j + 3, k + 13, Blocks.air);
			setBlock(i + 6, j + 3, k + 14, Blocks.air);
			setBlock(i + 6, j + 3, k + 15, ROCBlocks.netherrack_bricks);
			setBlock(i + 6, j + 4, k + 0, ROCBlocks.netherrack_bricks);
			setBlock(i + 6, j + 4, k + 1, ROCBlocks.charwood_log);
			setBlock(i + 6, j + 4, k + 2, ROCBlocks.charwood_log);
			setBlock(i + 6, j + 4, k + 3, ROCBlocks.charwood_log);
			setBlock(i + 6, j + 4, k + 4, ROCBlocks.charwood_log);
			setBlock(i + 6, j + 4, k + 5, ROCBlocks.charwood_log);
			setBlock(i + 6, j + 4, k + 6, ROCBlocks.charwood_log);
			setBlock(i + 6, j + 4, k + 7, ROCBlocks.charwood_log);
			setBlock(i + 6, j + 4, k + 8, ROCBlocks.charwood_log);
			setBlock(i + 6, j + 4, k + 9, ROCBlocks.charwood_log);
			setBlock(i + 6, j + 4, k + 10, ROCBlocks.charwood_log);
			setBlock(i + 6, j + 4, k + 11, ROCBlocks.charwood_log);
			setBlock(i + 6, j + 4, k + 12, ROCBlocks.charwood_log);
			setBlock(i + 6, j + 4, k + 13, ROCBlocks.charwood_log);
			setBlock(i + 6, j + 4, k + 14, ROCBlocks.charwood_log);
			setBlock(i + 6, j + 4, k + 15, ROCBlocks.netherrack_bricks);
			setBlock(i + 7, j + 0, k + 0, Blocks.nether_brick);
			setBlock(i + 7, j + 0, k + 1, Blocks.nether_brick);
			setBlock(i + 7, j + 0, k + 2, Blocks.nether_brick);
			setBlock(i + 7, j + 0, k + 3, Blocks.nether_brick);
			setBlock(i + 7, j + 0, k + 4, Blocks.nether_brick);
			setBlock(i + 7, j + 0, k + 5, Blocks.nether_brick);
			setBlock(i + 7, j + 0, k + 6, Blocks.nether_brick);
			setBlock(i + 7, j + 0, k + 7, Blocks.nether_brick);
			setBlock(i + 7, j + 0, k + 8, Blocks.nether_brick);
			setBlock(i + 7, j + 0, k + 9, Blocks.nether_brick);
			setBlock(i + 7, j + 0, k + 10, Blocks.nether_brick);
			setBlock(i + 7, j + 0, k + 11, Blocks.nether_brick);
			setBlock(i + 7, j + 0, k + 12, Blocks.nether_brick);
			setBlock(i + 7, j + 0, k + 13, Blocks.nether_brick);
			setBlock(i + 7, j + 0, k + 14, Blocks.nether_brick);
			setBlock(i + 7, j + 0, k + 15, Blocks.nether_brick);
			setBlock(i + 7, j + 1, k + 0, ROCBlocks.netherrack_bricks);
			setBlock(i + 7, j + 1, k + 1, Blocks.mob_spawner);
			TileEntityMobSpawner spawner3 = (TileEntityMobSpawner)world.getTileEntity(pos.add(7, 1, 1));
			if (spawner3 != null) spawner3.getSpawnerBaseLogic().setEntityName("Blaze");
			setBlock(i + 7, j + 1, k + 2, Blocks.air);
			setBlock(i + 7, j + 1, k + 3, Blocks.air);
			setBlock(i + 7, j + 1, k + 4, Blocks.air);
			setBlock(i + 7, j + 1, k + 5, Blocks.air);
			setBlock(i + 7, j + 1, k + 6, ROCBlocks.netherrack_brick_stairs, 2, 2);
			setBlock(i + 7, j + 1, k + 9, ROCBlocks.netherrack_brick_stairs, 3, 2);
			setBlock(i + 7, j + 1, k + 10, Blocks.air);
			setBlock(i + 7, j + 1, k + 11, Blocks.air);
			setBlock(i + 7, j + 1, k + 12, Blocks.air);
			setBlock(i + 7, j + 1, k + 13, Blocks.air);
			setBlock(i + 7, j + 1, k + 14, Blocks.mob_spawner);
			TileEntityMobSpawner spawner4 = (TileEntityMobSpawner)world.getTileEntity(pos.add(6, 1, 14));
			if (spawner4 != null) spawner4.getSpawnerBaseLogic().setEntityName("Blaze");
			setBlock(i + 7, j + 1, k + 15, ROCBlocks.netherrack_bricks);
			setBlock(i + 7, j + 2, k + 0, ROCBlocks.netherrack_bricks);
			setBlock(i + 7, j + 2, k + 1, Blocks.air);
			setBlock(i + 7, j + 2, k + 2, Blocks.air);
			setBlock(i + 7, j + 2, k + 3, Blocks.air);
			setBlock(i + 7, j + 2, k + 4, Blocks.air);
			setBlock(i + 7, j + 2, k + 5, Blocks.air);
			setBlock(i + 7, j + 2, k + 6, Blocks.air);
			setBlock(i + 7, j + 2, k + 7, Blocks.air);
			setBlock(i + 7, j + 2, k + 8, Blocks.air);
			setBlock(i + 7, j + 2, k + 9, Blocks.air);
			setBlock(i + 7, j + 2, k + 10, Blocks.air);
			setBlock(i + 7, j + 2, k + 11, Blocks.air);
			setBlock(i + 7, j + 2, k + 12, Blocks.air);
			setBlock(i + 7, j + 2, k + 13, Blocks.air);
			setBlock(i + 7, j + 2, k + 14, Blocks.air);
			setBlock(i + 7, j + 2, k + 15, ROCBlocks.netherrack_bricks);
			setBlock(i + 7, j + 3, k + 0, ROCBlocks.netherrack_bricks);
			setBlock(i + 7, j + 3, k + 1, Blocks.air);
			setBlock(i + 7, j + 3, k + 2, Blocks.air);
			setBlock(i + 7, j + 3, k + 3, Blocks.air);
			setBlock(i + 7, j + 3, k + 4, Blocks.air);
			setBlock(i + 7, j + 3, k + 5, Blocks.air);
			setBlock(i + 7, j + 3, k + 6, Blocks.air);
			setBlock(i + 7, j + 3, k + 7, Blocks.air);
			setBlock(i + 7, j + 3, k + 8, Blocks.air);
			setBlock(i + 7, j + 3, k + 9, Blocks.air);
			setBlock(i + 7, j + 3, k + 10, Blocks.air);
			setBlock(i + 7, j + 3, k + 11, Blocks.air);
			setBlock(i + 7, j + 3, k + 12, Blocks.air);
			setBlock(i + 7, j + 3, k + 13, Blocks.air);
			setBlock(i + 7, j + 3, k + 14, Blocks.air);
			setBlock(i + 7, j + 3, k + 15, ROCBlocks.netherrack_bricks);
			setBlock(i + 7, j + 4, k + 0, ROCBlocks.netherrack_bricks);
			setBlock(i + 7, j + 4, k + 1, ROCBlocks.charwood_log);
			setBlock(i + 7, j + 4, k + 2, ROCBlocks.charwood_log);
			setBlock(i + 7, j + 4, k + 3, ROCBlocks.charwood_log);
			setBlock(i + 7, j + 4, k + 4, ROCBlocks.charwood_log);
			setBlock(i + 7, j + 4, k + 5, ROCBlocks.charwood_log);
			setBlock(i + 7, j + 4, k + 6, ROCBlocks.charwood_log);
			setBlock(i + 7, j + 4, k + 7, ROCBlocks.charwood_log);
			setBlock(i + 7, j + 4, k + 8, ROCBlocks.charwood_log);
			setBlock(i + 7, j + 4, k + 9, ROCBlocks.charwood_log);
			setBlock(i + 7, j + 4, k + 10, ROCBlocks.charwood_log);
			setBlock(i + 7, j + 4, k + 11, ROCBlocks.charwood_log);
			setBlock(i + 7, j + 4, k + 12, ROCBlocks.charwood_log);
			setBlock(i + 7, j + 4, k + 13, ROCBlocks.charwood_log);
			setBlock(i + 7, j + 4, k + 14, ROCBlocks.charwood_log);
			setBlock(i + 7, j + 4, k + 15, ROCBlocks.netherrack_bricks);
			setBlock(i + 8, j + 0, k + 0, Blocks.netherrack);
			setBlock(i + 8, j + 0, k + 1, Blocks.nether_brick);
			setBlock(i + 8, j + 0, k + 2, Blocks.nether_brick);
			setBlock(i + 8, j + 0, k + 3, Blocks.nether_brick);
			setBlock(i + 8, j + 0, k + 4, Blocks.nether_brick);
			setBlock(i + 8, j + 0, k + 5, Blocks.nether_brick);
			setBlock(i + 8, j + 0, k + 6, Blocks.nether_brick);
			setBlock(i + 8, j + 0, k + 7, Blocks.nether_brick);
			setBlock(i + 8, j + 0, k + 8, Blocks.nether_brick);
			setBlock(i + 8, j + 0, k + 9, Blocks.nether_brick);
			setBlock(i + 8, j + 0, k + 10, Blocks.nether_brick);
			setBlock(i + 8, j + 0, k + 11, Blocks.nether_brick);
			setBlock(i + 8, j + 0, k + 12, Blocks.nether_brick);
			setBlock(i + 8, j + 0, k + 13, Blocks.nether_brick);
			setBlock(i + 8, j + 0, k + 14, Blocks.nether_brick);
			setBlock(i + 8, j + 0, k + 15, Blocks.netherrack);
			setBlock(i + 8, j + 1, k + 0, Blocks.netherrack);
			setBlock(i + 8, j + 1, k + 1, ROCBlocks.netherrack_bricks);
			setBlock(i + 8, j + 1, k + 2, Blocks.air);
			setBlock(i + 8, j + 1, k + 3, Blocks.air);
			setBlock(i + 8, j + 1, k + 4, Blocks.air);
			setBlock(i + 8, j + 1, k + 5, Blocks.air);
			setBlock(i + 8, j + 1, k + 6, ROCBlocks.netherrack_brick_stairs, 2, 2);
			setBlock(i + 8, j + 1, k + 9, ROCBlocks.netherrack_brick_stairs, 3, 2);
			setBlock(i + 8, j + 1, k + 10, Blocks.air);
			setBlock(i + 8, j + 1, k + 11, Blocks.air);
			setBlock(i + 8, j + 1, k + 12, Blocks.air);
			setBlock(i + 8, j + 1, k + 13, Blocks.air);
			setBlock(i + 8, j + 1, k + 14, ROCBlocks.netherrack_bricks);
			setBlock(i + 8, j + 1, k + 15, Blocks.netherrack);
			setBlock(i + 8, j + 2, k + 0, Blocks.netherrack);
			setBlock(i + 8, j + 2, k + 1, ROCBlocks.netherrack_bricks);
			setBlock(i + 8, j + 2, k + 2, Blocks.air);
			setBlock(i + 8, j + 2, k + 3, Blocks.air);
			setBlock(i + 8, j + 2, k + 4, Blocks.air);
			setBlock(i + 8, j + 2, k + 5, Blocks.air);
			setBlock(i + 8, j + 2, k + 6, Blocks.air);
			setBlock(i + 8, j + 2, k + 7, Blocks.air);
			setBlock(i + 8, j + 2, k + 8, Blocks.air);
			setBlock(i + 8, j + 2, k + 9, Blocks.air);
			setBlock(i + 8, j + 2, k + 10, Blocks.air);
			setBlock(i + 8, j + 2, k + 11, Blocks.air);
			setBlock(i + 8, j + 2, k + 12, Blocks.air);
			setBlock(i + 8, j + 2, k + 13, Blocks.air);
			setBlock(i + 8, j + 2, k + 14, ROCBlocks.netherrack_bricks);
			setBlock(i + 8, j + 2, k + 15, Blocks.netherrack);
			setBlock(i + 8, j + 3, k + 0, Blocks.netherrack);
			setBlock(i + 8, j + 3, k + 1, ROCBlocks.netherrack_bricks);
			setBlock(i + 8, j + 3, k + 2, Blocks.air);
			setBlock(i + 8, j + 3, k + 3, Blocks.air);
			setBlock(i + 8, j + 3, k + 4, Blocks.air);
			setBlock(i + 8, j + 3, k + 5, Blocks.air);
			setBlock(i + 8, j + 3, k + 6, Blocks.air);
			setBlock(i + 8, j + 3, k + 7, Blocks.air);
			setBlock(i + 8, j + 3, k + 8, Blocks.air);
			setBlock(i + 8, j + 3, k + 9, Blocks.air);
			setBlock(i + 8, j + 3, k + 10, Blocks.air);
			setBlock(i + 8, j + 3, k + 11, Blocks.air);
			setBlock(i + 8, j + 3, k + 12, Blocks.air);
			setBlock(i + 8, j + 3, k + 13, Blocks.air);
			setBlock(i + 8, j + 3, k + 14, ROCBlocks.netherrack_bricks);
			setBlock(i + 8, j + 3, k + 15, Blocks.netherrack);
			setBlock(i + 8, j + 4, k + 0, Blocks.netherrack);
			setBlock(i + 8, j + 4, k + 1, ROCBlocks.netherrack_bricks);
			setBlock(i + 8, j + 4, k + 2, ROCBlocks.charwood_log);
			setBlock(i + 8, j + 4, k + 3, ROCBlocks.charwood_log);
			setBlock(i + 8, j + 4, k + 4, ROCBlocks.charwood_log);
			setBlock(i + 8, j + 4, k + 5, ROCBlocks.charwood_log);
			setBlock(i + 8, j + 4, k + 6, ROCBlocks.charwood_log);
			setBlock(i + 8, j + 4, k + 7, ROCBlocks.charwood_log);
			setBlock(i + 8, j + 4, k + 8, ROCBlocks.charwood_log);
			setBlock(i + 8, j + 4, k + 9, ROCBlocks.charwood_log);
			setBlock(i + 8, j + 4, k + 10, ROCBlocks.charwood_log);
			setBlock(i + 8, j + 4, k + 11, ROCBlocks.charwood_log);
			setBlock(i + 8, j + 4, k + 12, ROCBlocks.charwood_log);
			setBlock(i + 8, j + 4, k + 13, ROCBlocks.charwood_log);
			setBlock(i + 8, j + 4, k + 14, ROCBlocks.netherrack_bricks);
			setBlock(i + 8, j + 4, k + 15, Blocks.netherrack);
			setBlock(i + 9, j + 0, k + 0, Blocks.netherrack);
			setBlock(i + 9, j + 0, k + 1, Blocks.nether_brick);
			setBlock(i + 9, j + 0, k + 2, Blocks.nether_brick);
			setBlock(i + 9, j + 0, k + 3, Blocks.nether_brick);
			setBlock(i + 9, j + 0, k + 4, Blocks.nether_brick);
			setBlock(i + 9, j + 0, k + 5, Blocks.nether_brick);
			setBlock(i + 9, j + 0, k + 6, Blocks.nether_brick);
			setBlock(i + 9, j + 0, k + 7, Blocks.nether_brick);
			setBlock(i + 9, j + 0, k + 8, Blocks.nether_brick);
			setBlock(i + 9, j + 0, k + 9, Blocks.nether_brick);
			setBlock(i + 9, j + 0, k + 10, Blocks.nether_brick);
			setBlock(i + 9, j + 0, k + 11, Blocks.nether_brick);
			setBlock(i + 9, j + 0, k + 12, Blocks.nether_brick);
			setBlock(i + 9, j + 0, k + 13, Blocks.nether_brick);
			setBlock(i + 9, j + 0, k + 14, Blocks.nether_brick);
			setBlock(i + 9, j + 0, k + 15, Blocks.netherrack);
			setBlock(i + 9, j + 1, k + 0, Blocks.netherrack);
			setBlock(i + 9, j + 1, k + 1, ROCBlocks.netherrack_bricks);
			setBlock(i + 9, j + 1, k + 2, Blocks.air);
			setBlock(i + 9, j + 1, k + 3, Blocks.air);
			setBlock(i + 9, j + 1, k + 4, Blocks.air);
			setBlock(i + 9, j + 1, k + 5, Blocks.air);
			setBlock(i + 9, j + 1, k + 6, ROCBlocks.netherrack_brick_stairs, 1, 2);
			setBlock(i + 9, j + 1, k + 7, ROCBlocks.netherrack_brick_stairs, 1, 2);
			setBlock(i + 9, j + 1, k + 8, ROCBlocks.netherrack_brick_stairs, 1, 2);
			setBlock(i + 9, j + 1, k + 9, ROCBlocks.netherrack_brick_stairs, 3, 2);
			setBlock(i + 9, j + 1, k + 10, Blocks.air);
			setBlock(i + 9, j + 1, k + 11, Blocks.air);
			setBlock(i + 9, j + 1, k + 12, Blocks.air);
			setBlock(i + 9, j + 1, k + 13, Blocks.air);
			setBlock(i + 9, j + 1, k + 14, ROCBlocks.netherrack_bricks);
			setBlock(i + 9, j + 1, k + 15, Blocks.netherrack);
			setBlock(i + 9, j + 2, k + 0, Blocks.netherrack);
			setBlock(i + 9, j + 2, k + 1, ROCBlocks.netherrack_bricks);
			setBlock(i + 9, j + 2, k + 2, Blocks.air);
			setBlock(i + 9, j + 2, k + 3, Blocks.air);
			setBlock(i + 9, j + 2, k + 4, Blocks.air);
			setBlock(i + 9, j + 2, k + 5, Blocks.air);
			setBlock(i + 9, j + 2, k + 6, Blocks.air);
			setBlock(i + 9, j + 2, k + 7, Blocks.air);
			setBlock(i + 9, j + 2, k + 8, Blocks.air);
			setBlock(i + 9, j + 2, k + 9, Blocks.air);
			setBlock(i + 9, j + 2, k + 10, Blocks.air);
			setBlock(i + 9, j + 2, k + 11, Blocks.air);
			setBlock(i + 9, j + 2, k + 12, Blocks.air);
			setBlock(i + 9, j + 2, k + 13, Blocks.air);
			setBlock(i + 9, j + 2, k + 14, ROCBlocks.netherrack_bricks);
			setBlock(i + 9, j + 2, k + 15, Blocks.netherrack);
			setBlock(i + 9, j + 3, k + 0, Blocks.netherrack);
			setBlock(i + 9, j + 3, k + 1, ROCBlocks.netherrack_bricks);
			setBlock(i + 9, j + 3, k + 2, Blocks.air);
			setBlock(i + 9, j + 3, k + 3, Blocks.air);
			setBlock(i + 9, j + 3, k + 4, Blocks.air);
			setBlock(i + 9, j + 3, k + 5, Blocks.air);
			setBlock(i + 9, j + 3, k + 6, Blocks.air);
			setBlock(i + 9, j + 3, k + 7, Blocks.air);
			setBlock(i + 9, j + 3, k + 8, Blocks.air);
			setBlock(i + 9, j + 3, k + 9, Blocks.air);
			setBlock(i + 9, j + 3, k + 10, Blocks.air);
			setBlock(i + 9, j + 3, k + 11, Blocks.air);
			setBlock(i + 9, j + 3, k + 12, Blocks.air);
			setBlock(i + 9, j + 3, k + 13, Blocks.air);
			setBlock(i + 9, j + 3, k + 14, ROCBlocks.netherrack_bricks);
			setBlock(i + 9, j + 3, k + 15, Blocks.netherrack);
			setBlock(i + 9, j + 4, k + 0, Blocks.netherrack);
			setBlock(i + 9, j + 4, k + 1, ROCBlocks.netherrack_bricks);
			setBlock(i + 9, j + 4, k + 2, ROCBlocks.charwood_log);
			setBlock(i + 9, j + 4, k + 3, ROCBlocks.charwood_log);
			setBlock(i + 9, j + 4, k + 4, ROCBlocks.charwood_log);
			setBlock(i + 9, j + 4, k + 5, ROCBlocks.charwood_log);
			setBlock(i + 9, j + 4, k + 6, ROCBlocks.charwood_log);
			setBlock(i + 9, j + 4, k + 7, ROCBlocks.charwood_log);
			setBlock(i + 9, j + 4, k + 8, ROCBlocks.charwood_log);
			setBlock(i + 9, j + 4, k + 9, ROCBlocks.charwood_log);
			setBlock(i + 9, j + 4, k + 10, ROCBlocks.charwood_log);
			setBlock(i + 9, j + 4, k + 11, ROCBlocks.charwood_log);
			setBlock(i + 9, j + 4, k + 12, ROCBlocks.charwood_log);
			setBlock(i + 9, j + 4, k + 13, ROCBlocks.charwood_log);
			setBlock(i + 9, j + 4, k + 14, ROCBlocks.netherrack_bricks);
			setBlock(i + 9, j + 4, k + 15, Blocks.netherrack);
			setBlock(i + 10, j + 0, k + 0, Blocks.netherrack);
			setBlock(i + 10, j + 0, k + 1, Blocks.netherrack);
			setBlock(i + 10, j + 0, k + 2, Blocks.nether_brick);
			setBlock(i + 10, j + 0, k + 3, Blocks.nether_brick);
			setBlock(i + 10, j + 0, k + 4, Blocks.nether_brick);
			setBlock(i + 10, j + 0, k + 5, Blocks.nether_brick);
			setBlock(i + 10, j + 0, k + 6, Blocks.nether_brick);
			setBlock(i + 10, j + 0, k + 7, Blocks.nether_brick);
			setBlock(i + 10, j + 0, k + 8, Blocks.nether_brick);
			setBlock(i + 10, j + 0, k + 9, Blocks.nether_brick);
			setBlock(i + 10, j + 0, k + 10, Blocks.nether_brick);
			setBlock(i + 10, j + 0, k + 11, Blocks.nether_brick);
			setBlock(i + 10, j + 0, k + 12, Blocks.nether_brick);
			setBlock(i + 10, j + 0, k + 13, Blocks.nether_brick);
			setBlock(i + 10, j + 0, k + 14, Blocks.netherrack);
			setBlock(i + 10, j + 0, k + 15, Blocks.netherrack);
			setBlock(i + 10, j + 1, k + 0, Blocks.netherrack);
			setBlock(i + 10, j + 1, k + 1, Blocks.netherrack);
			setBlock(i + 10, j + 1, k + 2, ROCBlocks.netherrack_bricks);
			setBlock(i + 10, j + 1, k + 3, Blocks.air);
			setBlock(i + 10, j + 1, k + 4, Blocks.air);
			setBlock(i + 10, j + 1, k + 5, Blocks.air);
			setBlock(i + 10, j + 1, k + 6, Blocks.air);
			setBlock(i + 10, j + 1, k + 7, Blocks.air);
			setBlock(i + 10, j + 1, k + 8, Blocks.air);
			setBlock(i + 10, j + 1, k + 9, Blocks.air);
			setBlock(i + 10, j + 1, k + 10, Blocks.air);
			setBlock(i + 10, j + 1, k + 11, Blocks.air);
			setBlock(i + 10, j + 1, k + 12, Blocks.air);
			setBlock(i + 10, j + 1, k + 13, ROCBlocks.netherrack_bricks);
			setBlock(i + 10, j + 1, k + 14, Blocks.netherrack);
			setBlock(i + 10, j + 1, k + 15, Blocks.netherrack);
			setBlock(i + 10, j + 2, k + 0, Blocks.netherrack);
			setBlock(i + 10, j + 2, k + 1, Blocks.netherrack);
			setBlock(i + 10, j + 2, k + 2, ROCBlocks.netherrack_bricks);
			setBlock(i + 10, j + 2, k + 3, Blocks.air);
			setBlock(i + 10, j + 2, k + 4, Blocks.air);
			setBlock(i + 10, j + 2, k + 5, Blocks.air);
			setBlock(i + 10, j + 2, k + 6, Blocks.air);
			setBlock(i + 10, j + 2, k + 7, Blocks.air);
			setBlock(i + 10, j + 2, k + 8, Blocks.air);
			setBlock(i + 10, j + 2, k + 9, Blocks.air);
			setBlock(i + 10, j + 2, k + 10, Blocks.air);
			setBlock(i + 10, j + 2, k + 11, Blocks.air);
			setBlock(i + 10, j + 2, k + 12, Blocks.air);
			setBlock(i + 10, j + 2, k + 13, ROCBlocks.netherrack_bricks);
			setBlock(i + 10, j + 2, k + 14, Blocks.netherrack);
			setBlock(i + 10, j + 2, k + 15, Blocks.netherrack);
			setBlock(i + 10, j + 3, k + 0, Blocks.netherrack);
			setBlock(i + 10, j + 3, k + 1, Blocks.netherrack);
			setBlock(i + 10, j + 3, k + 2, ROCBlocks.netherrack_bricks);
			setBlock(i + 10, j + 3, k + 3, Blocks.air);
			setBlock(i + 10, j + 3, k + 4, Blocks.air);
			setBlock(i + 10, j + 3, k + 5, Blocks.air);
			setBlock(i + 10, j + 3, k + 6, Blocks.air);
			setBlock(i + 10, j + 3, k + 7, Blocks.air);
			setBlock(i + 10, j + 3, k + 8, Blocks.air);
			setBlock(i + 10, j + 3, k + 9, Blocks.air);
			setBlock(i + 10, j + 3, k + 10, Blocks.air);
			setBlock(i + 10, j + 3, k + 11, Blocks.air);
			setBlock(i + 10, j + 3, k + 12, Blocks.air);
			setBlock(i + 10, j + 3, k + 13, ROCBlocks.netherrack_bricks);
			setBlock(i + 10, j + 3, k + 14, Blocks.netherrack);
			setBlock(i + 10, j + 3, k + 15, Blocks.netherrack);
			setBlock(i + 10, j + 4, k + 0, Blocks.netherrack);
			setBlock(i + 10, j + 4, k + 1, Blocks.netherrack);
			setBlock(i + 10, j + 4, k + 2, ROCBlocks.netherrack_bricks);
			setBlock(i + 10, j + 4, k + 3, ROCBlocks.charwood_log);
			setBlock(i + 10, j + 4, k + 4, ROCBlocks.charwood_log);
			setBlock(i + 10, j + 4, k + 5, ROCBlocks.charwood_log);
			setBlock(i + 10, j + 4, k + 6, ROCBlocks.charwood_log);
			setBlock(i + 10, j + 4, k + 7, ROCBlocks.charwood_log);
			setBlock(i + 10, j + 4, k + 8, ROCBlocks.charwood_log);
			setBlock(i + 10, j + 4, k + 9, ROCBlocks.charwood_log);
			setBlock(i + 10, j + 4, k + 10, ROCBlocks.charwood_log);
			setBlock(i + 10, j + 4, k + 11, ROCBlocks.charwood_log);
			setBlock(i + 10, j + 4, k + 12, ROCBlocks.charwood_log);
			setBlock(i + 10, j + 4, k + 13, ROCBlocks.netherrack_bricks);
			setBlock(i + 10, j + 4, k + 14, Blocks.netherrack);
			setBlock(i + 10, j + 4, k + 15, Blocks.netherrack);
			setBlock(i + 11, j + 0, k + 0, Blocks.netherrack);
			setBlock(i + 11, j + 0, k + 1, Blocks.netherrack);
			setBlock(i + 11, j + 0, k + 2, Blocks.netherrack);
			setBlock(i + 11, j + 0, k + 3, Blocks.nether_brick);
			setBlock(i + 11, j + 0, k + 4, Blocks.nether_brick);
			setBlock(i + 11, j + 0, k + 5, Blocks.nether_brick);
			setBlock(i + 11, j + 0, k + 6, Blocks.nether_brick);
			setBlock(i + 11, j + 0, k + 7, Blocks.nether_brick);
			setBlock(i + 11, j + 0, k + 8, Blocks.nether_brick);
			setBlock(i + 11, j + 0, k + 9, Blocks.nether_brick);
			setBlock(i + 11, j + 0, k + 10, Blocks.nether_brick);
			setBlock(i + 11, j + 0, k + 11, Blocks.nether_brick);
			setBlock(i + 11, j + 0, k + 12, Blocks.nether_brick);
			setBlock(i + 11, j + 0, k + 13, Blocks.netherrack);
			setBlock(i + 11, j + 0, k + 14, Blocks.netherrack);
			setBlock(i + 11, j + 0, k + 15, Blocks.netherrack);
			setBlock(i + 11, j + 1, k + 0, Blocks.netherrack);
			setBlock(i + 11, j + 1, k + 1, Blocks.netherrack);
			setBlock(i + 11, j + 1, k + 2, Blocks.netherrack);
			setBlock(i + 11, j + 1, k + 3, ROCBlocks.netherrack_bricks);
			setBlock(i + 11, j + 1, k + 4, ROCBlocks.netherrack_bricks);
			setBlock(i + 11, j + 1, k + 5, Blocks.air);
			setBlock(i + 11, j + 1, k + 6, Blocks.air);
			setBlock(i + 11, j + 1, k + 7, Blocks.air);
			setBlock(i + 11, j + 1, k + 8, Blocks.air);
			setBlock(i + 11, j + 1, k + 9, Blocks.air);
			setBlock(i + 11, j + 1, k + 10, Blocks.air);
			setBlock(i + 11, j + 1, k + 11, ROCBlocks.netherrack_bricks);
			setBlock(i + 11, j + 1, k + 12, ROCBlocks.netherrack_bricks);
			setBlock(i + 11, j + 1, k + 13, Blocks.netherrack);
			setBlock(i + 11, j + 1, k + 14, Blocks.netherrack);
			setBlock(i + 11, j + 1, k + 15, Blocks.netherrack);
			setBlock(i + 11, j + 2, k + 0, Blocks.netherrack);
			setBlock(i + 11, j + 2, k + 1, Blocks.netherrack);
			setBlock(i + 11, j + 2, k + 2, Blocks.netherrack);
			setBlock(i + 11, j + 2, k + 3, ROCBlocks.netherrack_bricks);
			setBlock(i + 11, j + 2, k + 4, ROCBlocks.netherrack_bricks);
			setBlock(i + 11, j + 2, k + 5, Blocks.air);
			setBlock(i + 11, j + 2, k + 6, Blocks.air);
			setBlock(i + 11, j + 2, k + 7, Blocks.air);
			setBlock(i + 11, j + 2, k + 8, Blocks.air);
			setBlock(i + 11, j + 2, k + 9, Blocks.air);
			setBlock(i + 11, j + 2, k + 10, Blocks.air);
			setBlock(i + 11, j + 2, k + 11, ROCBlocks.netherrack_bricks);
			setBlock(i + 11, j + 2, k + 12, ROCBlocks.netherrack_bricks);
			setBlock(i + 11, j + 2, k + 13, Blocks.netherrack);
			setBlock(i + 11, j + 2, k + 14, Blocks.netherrack);
			setBlock(i + 11, j + 2, k + 15, Blocks.netherrack);
			setBlock(i + 11, j + 3, k + 0, Blocks.netherrack);
			setBlock(i + 11, j + 3, k + 1, Blocks.netherrack);
			setBlock(i + 11, j + 3, k + 2, Blocks.netherrack);
			setBlock(i + 11, j + 3, k + 3, ROCBlocks.netherrack_bricks);
			setBlock(i + 11, j + 3, k + 4, ROCBlocks.netherrack_bricks);
			setBlock(i + 11, j + 3, k + 5, Blocks.air);
			setBlock(i + 11, j + 3, k + 6, Blocks.air);
			setBlock(i + 11, j + 3, k + 7, Blocks.air);
			setBlock(i + 11, j + 3, k + 8, Blocks.air);
			setBlock(i + 11, j + 3, k + 9, Blocks.air);
			setBlock(i + 11, j + 3, k + 10, Blocks.air);
			setBlock(i + 11, j + 3, k + 11, ROCBlocks.netherrack_bricks);
			setBlock(i + 11, j + 3, k + 12, ROCBlocks.netherrack_bricks);
			setBlock(i + 11, j + 3, k + 13, Blocks.netherrack);
			setBlock(i + 11, j + 3, k + 14, Blocks.netherrack);
			setBlock(i + 11, j + 3, k + 15, Blocks.netherrack);
			setBlock(i + 11, j + 4, k + 0, Blocks.netherrack);
			setBlock(i + 11, j + 4, k + 1, Blocks.netherrack);
			setBlock(i + 11, j + 4, k + 2, Blocks.netherrack);
			setBlock(i + 11, j + 4, k + 3, ROCBlocks.netherrack_bricks);
			setBlock(i + 11, j + 4, k + 4, ROCBlocks.netherrack_bricks);
			setBlock(i + 11, j + 4, k + 5, ROCBlocks.charwood_log);
			setBlock(i + 11, j + 4, k + 6, ROCBlocks.charwood_log);
			setBlock(i + 11, j + 4, k + 7, ROCBlocks.charwood_log);
			setBlock(i + 11, j + 4, k + 8, ROCBlocks.charwood_log);
			setBlock(i + 11, j + 4, k + 9, ROCBlocks.charwood_log);
			setBlock(i + 11, j + 4, k + 10, ROCBlocks.charwood_log);
			setBlock(i + 11, j + 4, k + 11, ROCBlocks.netherrack_bricks);
			setBlock(i + 11, j + 4, k + 12, ROCBlocks.netherrack_bricks);
			setBlock(i + 11, j + 4, k + 13, Blocks.netherrack);
			setBlock(i + 11, j + 4, k + 14, Blocks.netherrack);
			setBlock(i + 11, j + 4, k + 15, Blocks.netherrack);
			setBlock(i + 12, j + 0, k + 0, Blocks.netherrack);
			setBlock(i + 12, j + 0, k + 1, Blocks.netherrack);
			setBlock(i + 12, j + 0, k + 2, Blocks.netherrack);
			setBlock(i + 12, j + 0, k + 3, Blocks.netherrack);
			setBlock(i + 12, j + 0, k + 4, Blocks.netherrack);
			setBlock(i + 12, j + 0, k + 5, Blocks.nether_brick);
			setBlock(i + 12, j + 0, k + 6, Blocks.nether_brick);
			setBlock(i + 12, j + 0, k + 7, Blocks.nether_brick);
			setBlock(i + 12, j + 0, k + 8, Blocks.nether_brick);
			setBlock(i + 12, j + 0, k + 9, Blocks.nether_brick);
			setBlock(i + 12, j + 0, k + 10, Blocks.nether_brick);
			setBlock(i + 12, j + 0, k + 11, Blocks.netherrack);
			setBlock(i + 12, j + 0, k + 12, Blocks.netherrack);
			setBlock(i + 12, j + 0, k + 13, Blocks.netherrack);
			setBlock(i + 12, j + 0, k + 14, Blocks.netherrack);
			setBlock(i + 12, j + 0, k + 15, Blocks.netherrack);
			setBlock(i + 12, j + 1, k + 0, Blocks.netherrack);
			setBlock(i + 12, j + 1, k + 1, Blocks.netherrack);
			setBlock(i + 12, j + 1, k + 2, Blocks.netherrack);
			setBlock(i + 12, j + 1, k + 3, Blocks.netherrack);
			setBlock(i + 12, j + 1, k + 4, Blocks.netherrack);
			setBlock(i + 12, j + 1, k + 5, ROCBlocks.netherrack_bricks);
			setBlock(i + 12, j + 1, k + 6, Blocks.air);
			setBlock(i + 12, j + 1, k + 7, Blocks.air);
			setBlock(i + 12, j + 1, k + 8, Blocks.air);
			setBlock(i + 12, j + 1, k + 9, Blocks.air);
			setBlock(i + 12, j + 1, k + 10, ROCBlocks.netherrack_bricks);
			setBlock(i + 12, j + 1, k + 11, Blocks.netherrack);
			setBlock(i + 12, j + 1, k + 12, Blocks.netherrack);
			setBlock(i + 12, j + 1, k + 13, Blocks.netherrack);
			setBlock(i + 12, j + 1, k + 14, Blocks.netherrack);
			setBlock(i + 12, j + 1, k + 15, Blocks.netherrack);
			setBlock(i + 12, j + 2, k + 0, Blocks.netherrack);
			setBlock(i + 12, j + 2, k + 1, Blocks.netherrack);
			setBlock(i + 12, j + 2, k + 2, Blocks.netherrack);
			setBlock(i + 12, j + 2, k + 3, Blocks.netherrack);
			setBlock(i + 12, j + 2, k + 4, Blocks.netherrack);
			setBlock(i + 12, j + 2, k + 5, ROCBlocks.netherrack_bricks);
			setBlock(i + 12, j + 2, k + 6, Blocks.air);
			setBlock(i + 12, j + 2, k + 7, Blocks.air);
			setBlock(i + 12, j + 2, k + 8, Blocks.air);
			setBlock(i + 12, j + 2, k + 9, Blocks.air);
			setBlock(i + 12, j + 2, k + 10, ROCBlocks.netherrack_bricks);
			setBlock(i + 12, j + 2, k + 11, Blocks.netherrack);
			setBlock(i + 12, j + 2, k + 12, Blocks.netherrack);
			setBlock(i + 12, j + 2, k + 13, Blocks.netherrack);
			setBlock(i + 12, j + 2, k + 14, Blocks.netherrack);
			setBlock(i + 12, j + 2, k + 15, Blocks.netherrack);
			setBlock(i + 12, j + 3, k + 0, Blocks.netherrack);
			setBlock(i + 12, j + 3, k + 1, Blocks.netherrack);
			setBlock(i + 12, j + 3, k + 2, Blocks.netherrack);
			setBlock(i + 12, j + 3, k + 3, Blocks.netherrack);
			setBlock(i + 12, j + 3, k + 4, Blocks.netherrack);
			setBlock(i + 12, j + 3, k + 5, ROCBlocks.netherrack_bricks);
			setBlock(i + 12, j + 3, k + 6, Blocks.air);
			setBlock(i + 12, j + 3, k + 7, Blocks.air);
			setBlock(i + 12, j + 3, k + 8, Blocks.air);
			setBlock(i + 12, j + 3, k + 9, Blocks.air);
			setBlock(i + 12, j + 3, k + 10, ROCBlocks.netherrack_bricks);
			setBlock(i + 12, j + 3, k + 11, Blocks.netherrack);
			setBlock(i + 12, j + 3, k + 12, Blocks.netherrack);
			setBlock(i + 12, j + 3, k + 13, Blocks.netherrack);
			setBlock(i + 12, j + 3, k + 14, Blocks.netherrack);
			setBlock(i + 12, j + 3, k + 15, Blocks.netherrack);
			setBlock(i + 12, j + 4, k + 0, Blocks.netherrack);
			setBlock(i + 12, j + 4, k + 1, Blocks.netherrack);
			setBlock(i + 12, j + 4, k + 2, Blocks.netherrack);
			setBlock(i + 12, j + 4, k + 3, Blocks.netherrack);
			setBlock(i + 12, j + 4, k + 4, Blocks.netherrack);
			setBlock(i + 12, j + 4, k + 5, ROCBlocks.netherrack_bricks);
			setBlock(i + 12, j + 4, k + 6, ROCBlocks.charwood_log);
			setBlock(i + 12, j + 4, k + 7, ROCBlocks.charwood_log);
			setBlock(i + 12, j + 4, k + 8, ROCBlocks.charwood_log);
			setBlock(i + 12, j + 4, k + 9, ROCBlocks.charwood_log);
			setBlock(i + 12, j + 4, k + 10, ROCBlocks.netherrack_bricks);
			setBlock(i + 12, j + 4, k + 11, Blocks.netherrack);
			setBlock(i + 12, j + 4, k + 12, Blocks.netherrack);
			setBlock(i + 12, j + 4, k + 13, Blocks.netherrack);
			setBlock(i + 12, j + 4, k + 14, Blocks.netherrack);
			setBlock(i + 12, j + 4, k + 15, Blocks.netherrack);
			setBlock(i + 13, j + 0, k + 0, Blocks.netherrack);
			setBlock(i + 13, j + 0, k + 1, Blocks.netherrack);
			setBlock(i + 13, j + 0, k + 2, Blocks.netherrack);
			setBlock(i + 13, j + 0, k + 3, Blocks.netherrack);
			setBlock(i + 13, j + 0, k + 4, Blocks.netherrack);
			setBlock(i + 13, j + 0, k + 5, Blocks.netherrack);
			setBlock(i + 13, j + 0, k + 6, Blocks.nether_brick);
			setBlock(i + 13, j + 0, k + 7, Blocks.nether_brick);
			setBlock(i + 13, j + 0, k + 8, Blocks.nether_brick);
			setBlock(i + 13, j + 0, k + 9, Blocks.nether_brick);
			setBlock(i + 13, j + 0, k + 10, Blocks.netherrack);
			setBlock(i + 13, j + 0, k + 11, Blocks.netherrack);
			setBlock(i + 13, j + 0, k + 12, Blocks.netherrack);
			setBlock(i + 13, j + 0, k + 13, Blocks.netherrack);
			setBlock(i + 13, j + 0, k + 14, Blocks.netherrack);
			setBlock(i + 13, j + 0, k + 15, Blocks.netherrack);
			setBlock(i + 13, j + 1, k + 0, Blocks.netherrack);
			setBlock(i + 13, j + 1, k + 1, Blocks.netherrack);
			setBlock(i + 13, j + 1, k + 2, Blocks.netherrack);
			setBlock(i + 13, j + 1, k + 3, Blocks.netherrack);
			setBlock(i + 13, j + 1, k + 4, Blocks.netherrack);
			setBlock(i + 13, j + 1, k + 5, Blocks.netherrack);
			setBlock(i + 13, j + 1, k + 6, ROCBlocks.netherrack_bricks);
			setBlock(i + 13, j + 1, k + 7, Blocks.air);
			setBlock(i + 13, j + 1, k + 8, Blocks.air);
			setBlock(i + 13, j + 1, k + 9, ROCBlocks.netherrack_bricks);
			setBlock(i + 13, j + 1, k + 10, Blocks.netherrack);
			setBlock(i + 13, j + 1, k + 11, Blocks.netherrack);
			setBlock(i + 13, j + 1, k + 12, Blocks.netherrack);
			setBlock(i + 13, j + 1, k + 13, Blocks.netherrack);
			setBlock(i + 13, j + 1, k + 14, Blocks.netherrack);
			setBlock(i + 13, j + 1, k + 15, Blocks.netherrack);
			setBlock(i + 13, j + 2, k + 0, Blocks.netherrack);
			setBlock(i + 13, j + 2, k + 1, Blocks.netherrack);
			setBlock(i + 13, j + 2, k + 2, Blocks.netherrack);
			setBlock(i + 13, j + 2, k + 3, Blocks.netherrack);
			setBlock(i + 13, j + 2, k + 4, Blocks.netherrack);
			setBlock(i + 13, j + 2, k + 5, Blocks.netherrack);
			setBlock(i + 13, j + 2, k + 6, ROCBlocks.netherrack_bricks);
			setBlock(i + 13, j + 2, k + 7, Blocks.air);
			setBlock(i + 13, j + 2, k + 8, Blocks.air);
			setBlock(i + 13, j + 2, k + 9, ROCBlocks.netherrack_bricks);
			setBlock(i + 13, j + 2, k + 10, Blocks.netherrack);
			setBlock(i + 13, j + 2, k + 11, Blocks.netherrack);
			setBlock(i + 13, j + 2, k + 12, Blocks.netherrack);
			setBlock(i + 13, j + 2, k + 13, Blocks.netherrack);
			setBlock(i + 13, j + 2, k + 14, Blocks.netherrack);
			setBlock(i + 13, j + 2, k + 15, Blocks.netherrack);
			setBlock(i + 13, j + 3, k + 0, Blocks.netherrack);
			setBlock(i + 13, j + 3, k + 1, Blocks.netherrack);
			setBlock(i + 13, j + 3, k + 2, Blocks.netherrack);
			setBlock(i + 13, j + 3, k + 3, Blocks.netherrack);
			setBlock(i + 13, j + 3, k + 4, Blocks.netherrack);
			setBlock(i + 13, j + 3, k + 5, Blocks.netherrack);
			setBlock(i + 13, j + 3, k + 6, ROCBlocks.netherrack_bricks);
			setBlock(i + 13, j + 3, k + 7, Blocks.air);
			setBlock(i + 13, j + 3, k + 8, Blocks.air);
			setBlock(i + 13, j + 3, k + 9, ROCBlocks.netherrack_bricks);
			setBlock(i + 13, j + 3, k + 10, Blocks.netherrack);
			setBlock(i + 13, j + 3, k + 11, Blocks.netherrack);
			setBlock(i + 13, j + 3, k + 12, Blocks.netherrack);
			setBlock(i + 13, j + 3, k + 13, Blocks.netherrack);
			setBlock(i + 13, j + 3, k + 14, Blocks.netherrack);
			setBlock(i + 13, j + 3, k + 15, Blocks.netherrack);
			setBlock(i + 13, j + 4, k + 0, Blocks.netherrack);
			setBlock(i + 13, j + 4, k + 1, Blocks.netherrack);
			setBlock(i + 13, j + 4, k + 2, Blocks.netherrack);
			setBlock(i + 13, j + 4, k + 3, Blocks.netherrack);
			setBlock(i + 13, j + 4, k + 4, Blocks.netherrack);
			setBlock(i + 13, j + 4, k + 5, Blocks.netherrack);
			setBlock(i + 13, j + 4, k + 6, ROCBlocks.netherrack_bricks);
			setBlock(i + 13, j + 4, k + 7, ROCBlocks.charwood_log);
			setBlock(i + 13, j + 4, k + 8, ROCBlocks.charwood_log);
			setBlock(i + 13, j + 4, k + 9, ROCBlocks.netherrack_bricks);
			setBlock(i + 13, j + 4, k + 10, Blocks.netherrack);
			setBlock(i + 13, j + 4, k + 11, Blocks.netherrack);
			setBlock(i + 13, j + 4, k + 12, Blocks.netherrack);
			setBlock(i + 13, j + 4, k + 13, Blocks.netherrack);
			setBlock(i + 13, j + 4, k + 14, Blocks.netherrack);
			setBlock(i + 13, j + 4, k + 15, Blocks.netherrack);
			setBlock(i + 14, j + 0, k + 0, Blocks.netherrack);
			setBlock(i + 14, j + 0, k + 1, Blocks.netherrack);
			setBlock(i + 14, j + 0, k + 2, Blocks.netherrack);
			setBlock(i + 14, j + 0, k + 3, Blocks.netherrack);
			setBlock(i + 14, j + 0, k + 4, Blocks.netherrack);
			setBlock(i + 14, j + 0, k + 5, Blocks.netherrack);
			setBlock(i + 14, j + 0, k + 6, ROCBlocks.netherrack_bricks);
			setBlock(i + 14, j + 0, k + 7, Blocks.nether_brick);
			setBlock(i + 14, j + 0, k + 8, Blocks.nether_brick);
			setBlock(i + 14, j + 0, k + 9, ROCBlocks.netherrack_bricks);
			setBlock(i + 14, j + 0, k + 10, Blocks.netherrack);
			setBlock(i + 14, j + 0, k + 11, Blocks.netherrack);
			setBlock(i + 14, j + 0, k + 12, Blocks.netherrack);
			setBlock(i + 14, j + 0, k + 13, Blocks.netherrack);
			setBlock(i + 14, j + 0, k + 14, Blocks.netherrack);
			setBlock(i + 14, j + 0, k + 15, Blocks.netherrack);
			setBlock(i + 14, j + 1, k + 0, Blocks.netherrack);
			setBlock(i + 14, j + 1, k + 1, Blocks.netherrack);
			setBlock(i + 14, j + 1, k + 2, Blocks.netherrack);
			setBlock(i + 14, j + 1, k + 3, Blocks.netherrack);
			setBlock(i + 14, j + 1, k + 4, Blocks.netherrack);
			setBlock(i + 14, j + 1, k + 5, Blocks.netherrack);
			setBlock(i + 14, j + 1, k + 6, ROCBlocks.netherrack_bricks);
			setBlock(i + 14, j + 1, k + 7, Blocks.air);
			setBlock(i + 14, j + 1, k + 8, Blocks.air);
			setBlock(i + 14, j + 1, k + 9, ROCBlocks.netherrack_bricks);
			setBlock(i + 14, j + 1, k + 10, Blocks.netherrack);
			setBlock(i + 14, j + 1, k + 11, Blocks.netherrack);
			setBlock(i + 14, j + 1, k + 12, Blocks.netherrack);
			setBlock(i + 14, j + 1, k + 13, Blocks.netherrack);
			setBlock(i + 14, j + 1, k + 14, Blocks.netherrack);
			setBlock(i + 14, j + 1, k + 15, Blocks.netherrack);
			setBlock(i + 14, j + 2, k + 0, Blocks.netherrack);
			setBlock(i + 14, j + 2, k + 1, Blocks.netherrack);
			setBlock(i + 14, j + 2, k + 2, Blocks.netherrack);
			setBlock(i + 14, j + 2, k + 3, Blocks.netherrack);
			setBlock(i + 14, j + 2, k + 4, Blocks.netherrack);
			setBlock(i + 14, j + 2, k + 5, Blocks.netherrack);
			setBlock(i + 14, j + 2, k + 6, ROCBlocks.netherrack_bricks);
			setBlock(i + 14, j + 2, k + 7, Blocks.air);
			setBlock(i + 14, j + 2, k + 8, Blocks.air);
			setBlock(i + 14, j + 2, k + 9, ROCBlocks.netherrack_bricks);
			setBlock(i + 14, j + 2, k + 10, Blocks.netherrack);
			setBlock(i + 14, j + 2, k + 11, Blocks.netherrack);
			setBlock(i + 14, j + 2, k + 12, Blocks.netherrack);
			setBlock(i + 14, j + 2, k + 13, Blocks.netherrack);
			setBlock(i + 14, j + 2, k + 14, Blocks.netherrack);
			setBlock(i + 14, j + 2, k + 15, Blocks.netherrack);
			setBlock(i + 14, j + 3, k + 0, Blocks.netherrack);
			setBlock(i + 14, j + 3, k + 1, Blocks.netherrack);
			setBlock(i + 14, j + 3, k + 2, Blocks.netherrack);
			setBlock(i + 14, j + 3, k + 3, Blocks.netherrack);
			setBlock(i + 14, j + 3, k + 4, Blocks.netherrack);
			setBlock(i + 14, j + 3, k + 5, Blocks.netherrack);
			setBlock(i + 14, j + 3, k + 6, ROCBlocks.netherrack_bricks);
			setBlock(i + 14, j + 3, k + 7, Blocks.air);
			setBlock(i + 14, j + 3, k + 8, Blocks.air);
			setBlock(i + 14, j + 3, k + 9, ROCBlocks.netherrack_bricks);
			setBlock(i + 14, j + 3, k + 10, Blocks.netherrack);
			setBlock(i + 14, j + 3, k + 11, Blocks.netherrack);
			setBlock(i + 14, j + 3, k + 12, Blocks.netherrack);
			setBlock(i + 14, j + 3, k + 13, Blocks.netherrack);
			setBlock(i + 14, j + 3, k + 14, Blocks.netherrack);
			setBlock(i + 14, j + 3, k + 15, Blocks.netherrack);
			setBlock(i + 14, j + 4, k + 0, Blocks.netherrack);
			setBlock(i + 14, j + 4, k + 1, Blocks.netherrack);
			setBlock(i + 14, j + 4, k + 2, Blocks.netherrack);
			setBlock(i + 14, j + 4, k + 3, Blocks.netherrack);
			setBlock(i + 14, j + 4, k + 4, Blocks.netherrack);
			setBlock(i + 14, j + 4, k + 5, Blocks.netherrack);
			setBlock(i + 14, j + 4, k + 6, ROCBlocks.netherrack_bricks);
			setBlock(i + 14, j + 4, k + 7, Blocks.nether_brick);
			setBlock(i + 14, j + 4, k + 8, Blocks.nether_brick);
			setBlock(i + 14, j + 4, k + 9, ROCBlocks.netherrack_bricks);
			setBlock(i + 14, j + 4, k + 10, Blocks.netherrack);
			setBlock(i + 14, j + 4, k + 11, Blocks.netherrack);
			setBlock(i + 14, j + 4, k + 12, Blocks.netherrack);
			setBlock(i + 14, j + 4, k + 13, Blocks.netherrack);
			setBlock(i + 14, j + 4, k + 14, Blocks.netherrack);
			setBlock(i + 14, j + 4, k + 15, Blocks.netherrack);
			setBlock(i + 15, j + 0, k + 0, Blocks.netherrack);
			setBlock(i + 15, j + 0, k + 1, Blocks.netherrack);
			setBlock(i + 15, j + 0, k + 2, Blocks.netherrack);
			setBlock(i + 15, j + 0, k + 3, Blocks.netherrack);
			setBlock(i + 15, j + 0, k + 4, Blocks.netherrack);
			setBlock(i + 15, j + 0, k + 5, Blocks.netherrack);
			setBlock(i + 15, j + 0, k + 6, ROCBlocks.netherrack_bricks);
			setBlock(i + 15, j + 0, k + 7, Blocks.nether_brick);
			setBlock(i + 15, j + 0, k + 8, Blocks.nether_brick);
			setBlock(i + 15, j + 0, k + 9, ROCBlocks.netherrack_bricks);
			setBlock(i + 15, j + 0, k + 10, Blocks.netherrack);
			setBlock(i + 15, j + 0, k + 11, Blocks.netherrack);
			setBlock(i + 15, j + 0, k + 12, Blocks.netherrack);
			setBlock(i + 15, j + 0, k + 13, Blocks.netherrack);
			setBlock(i + 15, j + 0, k + 14, Blocks.netherrack);
			setBlock(i + 15, j + 0, k + 15, Blocks.netherrack);
			setBlock(i + 15, j + 1, k + 0, Blocks.netherrack);
			setBlock(i + 15, j + 1, k + 1, Blocks.netherrack);
			setBlock(i + 15, j + 1, k + 2, Blocks.netherrack);
			setBlock(i + 15, j + 1, k + 3, Blocks.netherrack);
			setBlock(i + 15, j + 1, k + 4, Blocks.netherrack);
			setBlock(i + 15, j + 1, k + 5, Blocks.netherrack);
			setBlock(i + 15, j + 1, k + 6, ROCBlocks.netherrack_bricks);
			setBlock(i + 15, j + 1, k + 7, Blocks.air);
			setBlock(i + 15, j + 1, k + 8, Blocks.air);
			setBlock(i + 15, j + 1, k + 9, ROCBlocks.netherrack_bricks);
			setBlock(i + 15, j + 1, k + 10, Blocks.netherrack);
			setBlock(i + 15, j + 1, k + 11, Blocks.netherrack);
			setBlock(i + 15, j + 1, k + 12, Blocks.netherrack);
			setBlock(i + 15, j + 1, k + 13, Blocks.netherrack);
			setBlock(i + 15, j + 1, k + 14, Blocks.netherrack);
			setBlock(i + 15, j + 1, k + 15, Blocks.netherrack);
			setBlock(i + 15, j + 2, k + 0, Blocks.netherrack);
			setBlock(i + 15, j + 2, k + 1, Blocks.netherrack);
			setBlock(i + 15, j + 2, k + 2, Blocks.netherrack);
			setBlock(i + 15, j + 2, k + 3, Blocks.netherrack);
			setBlock(i + 15, j + 2, k + 4, Blocks.netherrack);
			setBlock(i + 15, j + 2, k + 5, Blocks.netherrack);
			setBlock(i + 15, j + 2, k + 6, ROCBlocks.netherrack_bricks);
			setBlock(i + 15, j + 2, k + 7, Blocks.air);
			setBlock(i + 15, j + 2, k + 8, Blocks.air);
			setBlock(i + 15, j + 2, k + 9, ROCBlocks.netherrack_bricks);
			setBlock(i + 15, j + 2, k + 10, Blocks.netherrack);
			setBlock(i + 15, j + 2, k + 11, Blocks.netherrack);
			setBlock(i + 15, j + 2, k + 12, Blocks.netherrack);
			setBlock(i + 15, j + 2, k + 13, Blocks.netherrack);
			setBlock(i + 15, j + 2, k + 14, Blocks.netherrack);
			setBlock(i + 15, j + 2, k + 15, Blocks.netherrack);
			setBlock(i + 15, j + 3, k + 0, Blocks.netherrack);
			setBlock(i + 15, j + 3, k + 1, Blocks.netherrack);
			setBlock(i + 15, j + 3, k + 2, Blocks.netherrack);
			setBlock(i + 15, j + 3, k + 3, Blocks.netherrack);
			setBlock(i + 15, j + 3, k + 4, Blocks.netherrack);
			setBlock(i + 15, j + 3, k + 5, Blocks.netherrack);
			setBlock(i + 15, j + 3, k + 6, ROCBlocks.netherrack_bricks);
			setBlock(i + 15, j + 3, k + 7, Blocks.air);
			setBlock(i + 15, j + 3, k + 8, Blocks.air);
			setBlock(i + 15, j + 3, k + 9, ROCBlocks.netherrack_bricks);
			setBlock(i + 15, j + 3, k + 10, Blocks.netherrack);
			setBlock(i + 15, j + 3, k + 11, Blocks.netherrack);
			setBlock(i + 15, j + 3, k + 12, Blocks.netherrack);
			setBlock(i + 15, j + 3, k + 13, Blocks.netherrack);
			setBlock(i + 15, j + 3, k + 14, Blocks.netherrack);
			setBlock(i + 15, j + 3, k + 15, Blocks.netherrack);
			setBlock(i + 15, j + 4, k + 0, Blocks.netherrack);
			setBlock(i + 15, j + 4, k + 1, Blocks.netherrack);
			setBlock(i + 15, j + 4, k + 2, Blocks.netherrack);
			setBlock(i + 15, j + 4, k + 3, Blocks.netherrack);
			setBlock(i + 15, j + 4, k + 4, Blocks.netherrack);
			setBlock(i + 15, j + 4, k + 5, Blocks.netherrack);
			setBlock(i + 15, j + 4, k + 6, ROCBlocks.netherrack_bricks);
			setBlock(i + 15, j + 4, k + 7, Blocks.nether_brick);
			setBlock(i + 15, j + 4, k + 8, Blocks.nether_brick);
			setBlock(i + 15, j + 4, k + 9, ROCBlocks.netherrack_bricks);
			setBlock(i + 15, j + 4, k + 10, Blocks.netherrack);
			setBlock(i + 15, j + 4, k + 11, Blocks.netherrack);
			setBlock(i + 15, j + 4, k + 12, Blocks.netherrack);
			setBlock(i + 15, j + 4, k + 13, Blocks.netherrack);
			setBlock(i + 15, j + 4, k + 14, Blocks.netherrack);
			setBlock(i + 15, j + 4, k + 15, Blocks.netherrack);
			setBlock(i + 16, j + 0, k + 0, Blocks.netherrack);
			setBlock(i + 16, j + 0, k + 1, Blocks.netherrack);
			setBlock(i + 16, j + 0, k + 2, Blocks.netherrack);
			setBlock(i + 16, j + 0, k + 3, Blocks.netherrack);
			setBlock(i + 16, j + 0, k + 4, Blocks.netherrack);
			setBlock(i + 16, j + 0, k + 5, Blocks.netherrack);
			setBlock(i + 16, j + 0, k + 6, ROCBlocks.netherrack_bricks);
			setBlock(i + 16, j + 0, k + 7, Blocks.nether_brick);
			setBlock(i + 16, j + 0, k + 8, Blocks.nether_brick);
			setBlock(i + 16, j + 0, k + 9, ROCBlocks.netherrack_bricks);
			setBlock(i + 16, j + 0, k + 10, Blocks.netherrack);
			setBlock(i + 16, j + 0, k + 11, Blocks.netherrack);
			setBlock(i + 16, j + 0, k + 12, Blocks.netherrack);
			setBlock(i + 16, j + 0, k + 13, Blocks.netherrack);
			setBlock(i + 16, j + 0, k + 14, Blocks.netherrack);
			setBlock(i + 16, j + 0, k + 15, Blocks.netherrack);
			setBlock(i + 16, j + 1, k + 0, Blocks.netherrack);
			setBlock(i + 16, j + 1, k + 1, Blocks.netherrack);
			setBlock(i + 16, j + 1, k + 2, Blocks.netherrack);
			setBlock(i + 16, j + 1, k + 3, Blocks.netherrack);
			setBlock(i + 16, j + 1, k + 4, Blocks.netherrack);
			setBlock(i + 16, j + 1, k + 5, Blocks.netherrack);
			setBlock(i + 16, j + 1, k + 6, ROCBlocks.netherrack_bricks);
			setBlock(i + 16, j + 1, k + 7, Blocks.air);
			setBlock(i + 16, j + 1, k + 8, Blocks.air);
			setBlock(i + 16, j + 1, k + 9, ROCBlocks.netherrack_bricks);
			setBlock(i + 16, j + 1, k + 10, Blocks.netherrack);
			setBlock(i + 16, j + 1, k + 11, Blocks.netherrack);
			setBlock(i + 16, j + 1, k + 12, Blocks.netherrack);
			setBlock(i + 16, j + 1, k + 13, Blocks.netherrack);
			setBlock(i + 16, j + 1, k + 14, Blocks.netherrack);
			setBlock(i + 16, j + 1, k + 15, Blocks.netherrack);
			setBlock(i + 16, j + 2, k + 0, Blocks.netherrack);
			setBlock(i + 16, j + 2, k + 1, Blocks.netherrack);
			setBlock(i + 16, j + 2, k + 2, Blocks.netherrack);
			setBlock(i + 16, j + 2, k + 3, Blocks.netherrack);
			setBlock(i + 16, j + 2, k + 4, Blocks.netherrack);
			setBlock(i + 16, j + 2, k + 5, Blocks.netherrack);
			setBlock(i + 16, j + 2, k + 6, ROCBlocks.netherrack_bricks);
			setBlock(i + 16, j + 2, k + 7, Blocks.air);
			setBlock(i + 16, j + 2, k + 8, Blocks.air);
			setBlock(i + 16, j + 2, k + 9, ROCBlocks.netherrack_bricks);
			setBlock(i + 16, j + 2, k + 10, Blocks.netherrack);
			setBlock(i + 16, j + 2, k + 11, Blocks.netherrack);
			setBlock(i + 16, j + 2, k + 12, Blocks.netherrack);
			setBlock(i + 16, j + 2, k + 13, Blocks.netherrack);
			setBlock(i + 16, j + 2, k + 14, Blocks.netherrack);
			setBlock(i + 16, j + 2, k + 15, Blocks.netherrack);
			setBlock(i + 16, j + 3, k + 0, Blocks.netherrack);
			setBlock(i + 16, j + 3, k + 1, Blocks.netherrack);
			setBlock(i + 16, j + 3, k + 2, Blocks.netherrack);
			setBlock(i + 16, j + 3, k + 3, Blocks.netherrack);
			setBlock(i + 16, j + 3, k + 4, Blocks.netherrack);
			setBlock(i + 16, j + 3, k + 5, Blocks.netherrack);
			setBlock(i + 16, j + 3, k + 6, ROCBlocks.netherrack_bricks);
			setBlock(i + 16, j + 3, k + 7, Blocks.air);
			setBlock(i + 16, j + 3, k + 8, Blocks.air);
			setBlock(i + 16, j + 3, k + 9, ROCBlocks.netherrack_bricks);
			setBlock(i + 16, j + 3, k + 10, Blocks.netherrack);
			setBlock(i + 16, j + 3, k + 11, Blocks.netherrack);
			setBlock(i + 16, j + 3, k + 12, Blocks.netherrack);
			setBlock(i + 16, j + 3, k + 13, Blocks.netherrack);
			setBlock(i + 16, j + 3, k + 14, Blocks.netherrack);
			setBlock(i + 16, j + 3, k + 15, Blocks.netherrack);
			setBlock(i + 16, j + 4, k + 0, Blocks.netherrack);
			setBlock(i + 16, j + 4, k + 1, Blocks.netherrack);
			setBlock(i + 16, j + 4, k + 2, Blocks.netherrack);
			setBlock(i + 16, j + 4, k + 3, Blocks.netherrack);
			setBlock(i + 16, j + 4, k + 4, Blocks.netherrack);
			setBlock(i + 16, j + 4, k + 5, Blocks.netherrack);
			setBlock(i + 16, j + 4, k + 6, ROCBlocks.netherrack_bricks);
			setBlock(i + 16, j + 4, k + 7, Blocks.nether_brick);
			setBlock(i + 16, j + 4, k + 8, Blocks.nether_brick);
			setBlock(i + 16, j + 4, k + 9, ROCBlocks.netherrack_bricks);
			setBlock(i + 16, j + 4, k + 10, Blocks.netherrack);
			setBlock(i + 16, j + 4, k + 11, Blocks.netherrack);
			setBlock(i + 16, j + 4, k + 12, Blocks.netherrack);
			setBlock(i + 16, j + 4, k + 13, Blocks.netherrack);
			setBlock(i + 16, j + 4, k + 14, Blocks.netherrack);
			setBlock(i + 16, j + 4, k + 15, Blocks.netherrack);
			setBlock(i + 17, j + 0, k + 0, Blocks.netherrack);
			setBlock(i + 17, j + 0, k + 1, Blocks.netherrack);
			setBlock(i + 17, j + 0, k + 2, Blocks.netherrack);
			setBlock(i + 17, j + 0, k + 3, Blocks.netherrack);
			setBlock(i + 17, j + 0, k + 4, Blocks.netherrack);
			setBlock(i + 17, j + 0, k + 5, Blocks.netherrack);
			setBlock(i + 17, j + 0, k + 6, ROCBlocks.netherrack_bricks);
			setBlock(i + 17, j + 0, k + 7, Blocks.nether_brick);
			setBlock(i + 17, j + 0, k + 8, Blocks.nether_brick);
			setBlock(i + 17, j + 0, k + 9, ROCBlocks.netherrack_bricks);
			setBlock(i + 17, j + 0, k + 10, Blocks.netherrack);
			setBlock(i + 17, j + 0, k + 11, Blocks.netherrack);
			setBlock(i + 17, j + 0, k + 12, Blocks.netherrack);
			setBlock(i + 17, j + 0, k + 13, Blocks.netherrack);
			setBlock(i + 17, j + 0, k + 14, Blocks.netherrack);
			setBlock(i + 17, j + 0, k + 15, Blocks.netherrack);
			setBlock(i + 17, j + 1, k + 0, Blocks.netherrack);
			setBlock(i + 17, j + 1, k + 1, Blocks.netherrack);
			setBlock(i + 17, j + 1, k + 2, Blocks.netherrack);
			setBlock(i + 17, j + 1, k + 3, Blocks.netherrack);
			setBlock(i + 17, j + 1, k + 4, Blocks.netherrack);
			setBlock(i + 17, j + 1, k + 5, Blocks.netherrack);
			setBlock(i + 17, j + 1, k + 6, ROCBlocks.netherrack_bricks);
			setBlock(i + 17, j + 1, k + 7, Blocks.air);
			setBlock(i + 17, j + 1, k + 8, Blocks.air);
			setBlock(i + 17, j + 1, k + 9, ROCBlocks.netherrack_bricks);
			setBlock(i + 17, j + 1, k + 10, Blocks.netherrack);
			setBlock(i + 17, j + 1, k + 11, Blocks.netherrack);
			setBlock(i + 17, j + 1, k + 12, Blocks.netherrack);
			setBlock(i + 17, j + 1, k + 13, Blocks.netherrack);
			setBlock(i + 17, j + 1, k + 14, Blocks.netherrack);
			setBlock(i + 17, j + 1, k + 15, Blocks.netherrack);
			setBlock(i + 17, j + 2, k + 0, Blocks.netherrack);
			setBlock(i + 17, j + 2, k + 1, Blocks.netherrack);
			setBlock(i + 17, j + 2, k + 2, Blocks.netherrack);
			setBlock(i + 17, j + 2, k + 3, Blocks.netherrack);
			setBlock(i + 17, j + 2, k + 4, Blocks.netherrack);
			setBlock(i + 17, j + 2, k + 5, Blocks.netherrack);
			setBlock(i + 17, j + 2, k + 6, ROCBlocks.netherrack_bricks);
			setBlock(i + 17, j + 2, k + 7, Blocks.air);
			setBlock(i + 17, j + 2, k + 8, Blocks.air);
			setBlock(i + 17, j + 2, k + 9, ROCBlocks.netherrack_bricks);
			setBlock(i + 17, j + 2, k + 10, Blocks.netherrack);
			setBlock(i + 17, j + 2, k + 11, Blocks.netherrack);
			setBlock(i + 17, j + 2, k + 12, Blocks.netherrack);
			setBlock(i + 17, j + 2, k + 13, Blocks.netherrack);
			setBlock(i + 17, j + 2, k + 14, Blocks.netherrack);
			setBlock(i + 17, j + 2, k + 15, Blocks.netherrack);
			setBlock(i + 17, j + 3, k + 0, Blocks.netherrack);
			setBlock(i + 17, j + 3, k + 1, Blocks.netherrack);
			setBlock(i + 17, j + 3, k + 2, Blocks.netherrack);
			setBlock(i + 17, j + 3, k + 3, Blocks.netherrack);
			setBlock(i + 17, j + 3, k + 4, Blocks.netherrack);
			setBlock(i + 17, j + 3, k + 5, Blocks.netherrack);
			setBlock(i + 17, j + 3, k + 6, ROCBlocks.netherrack_bricks);
			setBlock(i + 17, j + 3, k + 7, Blocks.air);
			setBlock(i + 17, j + 3, k + 8, Blocks.air);
			setBlock(i + 17, j + 3, k + 9, ROCBlocks.netherrack_bricks);
			setBlock(i + 17, j + 3, k + 10, Blocks.netherrack);
			setBlock(i + 17, j + 3, k + 11, Blocks.netherrack);
			setBlock(i + 17, j + 3, k + 12, Blocks.netherrack);
			setBlock(i + 17, j + 3, k + 13, Blocks.netherrack);
			setBlock(i + 17, j + 3, k + 14, Blocks.netherrack);
			setBlock(i + 17, j + 3, k + 15, Blocks.netherrack);
			setBlock(i + 17, j + 4, k + 0, Blocks.netherrack);
			setBlock(i + 17, j + 4, k + 1, Blocks.netherrack);
			setBlock(i + 17, j + 4, k + 2, Blocks.netherrack);
			setBlock(i + 17, j + 4, k + 3, Blocks.netherrack);
			setBlock(i + 17, j + 4, k + 4, Blocks.netherrack);
			setBlock(i + 17, j + 4, k + 5, Blocks.netherrack);
			setBlock(i + 17, j + 4, k + 6, ROCBlocks.netherrack_bricks);
			setBlock(i + 17, j + 4, k + 7, Blocks.nether_brick);
			setBlock(i + 17, j + 4, k + 8, Blocks.nether_brick);
			setBlock(i + 17, j + 4, k + 9, ROCBlocks.netherrack_bricks);
			setBlock(i + 17, j + 4, k + 10, Blocks.netherrack);
			setBlock(i + 17, j + 4, k + 11, Blocks.netherrack);
			setBlock(i + 17, j + 4, k + 12, Blocks.netherrack);
			setBlock(i + 17, j + 4, k + 13, Blocks.netherrack);
			setBlock(i + 17, j + 4, k + 14, Blocks.netherrack);
			setBlock(i + 17, j + 4, k + 15, Blocks.netherrack);
			setBlock(i + 18, j + 0, k + 0, Blocks.netherrack);
			setBlock(i + 18, j + 0, k + 1, Blocks.netherrack);
			setBlock(i + 18, j + 0, k + 2, Blocks.netherrack);
			setBlock(i + 18, j + 0, k + 3, Blocks.netherrack);
			setBlock(i + 18, j + 0, k + 4, Blocks.netherrack);
			setBlock(i + 18, j + 0, k + 5, Blocks.netherrack);
			setBlock(i + 18, j + 0, k + 6, ROCBlocks.netherrack_bricks);
			setBlock(i + 18, j + 0, k + 7, Blocks.nether_brick);
			setBlock(i + 18, j + 0, k + 8, Blocks.nether_brick);
			setBlock(i + 18, j + 0, k + 9, ROCBlocks.netherrack_bricks);
			setBlock(i + 18, j + 0, k + 10, Blocks.netherrack);
			setBlock(i + 18, j + 0, k + 11, Blocks.netherrack);
			setBlock(i + 18, j + 0, k + 12, Blocks.netherrack);
			setBlock(i + 18, j + 0, k + 13, Blocks.netherrack);
			setBlock(i + 18, j + 0, k + 14, Blocks.netherrack);
			setBlock(i + 18, j + 0, k + 15, Blocks.netherrack);
			setBlock(i + 18, j + 1, k + 0, Blocks.netherrack);
			setBlock(i + 18, j + 1, k + 1, Blocks.netherrack);
			setBlock(i + 18, j + 1, k + 2, Blocks.netherrack);
			setBlock(i + 18, j + 1, k + 3, Blocks.netherrack);
			setBlock(i + 18, j + 1, k + 4, Blocks.netherrack);
			setBlock(i + 18, j + 1, k + 5, Blocks.netherrack);
			setBlock(i + 18, j + 1, k + 6, ROCBlocks.netherrack_bricks);
			setBlock(i + 18, j + 1, k + 7, Blocks.air);
			setBlock(i + 18, j + 1, k + 8, Blocks.air);
			setBlock(i + 18, j + 1, k + 9, ROCBlocks.netherrack_bricks);
			setBlock(i + 18, j + 1, k + 10, Blocks.netherrack);
			setBlock(i + 18, j + 1, k + 11, Blocks.netherrack);
			setBlock(i + 18, j + 1, k + 12, Blocks.netherrack);
			setBlock(i + 18, j + 1, k + 13, Blocks.netherrack);
			setBlock(i + 18, j + 1, k + 14, Blocks.netherrack);
			setBlock(i + 18, j + 1, k + 15, Blocks.netherrack);
			setBlock(i + 18, j + 2, k + 0, Blocks.netherrack);
			setBlock(i + 18, j + 2, k + 1, Blocks.netherrack);
			setBlock(i + 18, j + 2, k + 2, Blocks.netherrack);
			setBlock(i + 18, j + 2, k + 3, Blocks.netherrack);
			setBlock(i + 18, j + 2, k + 4, Blocks.netherrack);
			setBlock(i + 18, j + 2, k + 5, Blocks.netherrack);
			setBlock(i + 18, j + 2, k + 6, ROCBlocks.netherrack_bricks);
			setBlock(i + 18, j + 2, k + 7, Blocks.air);
			setBlock(i + 18, j + 2, k + 8, Blocks.air);
			setBlock(i + 18, j + 2, k + 9, ROCBlocks.netherrack_bricks);
			setBlock(i + 18, j + 2, k + 10, Blocks.netherrack);
			setBlock(i + 18, j + 2, k + 11, Blocks.netherrack);
			setBlock(i + 18, j + 2, k + 12, Blocks.netherrack);
			setBlock(i + 18, j + 2, k + 13, Blocks.netherrack);
			setBlock(i + 18, j + 2, k + 14, Blocks.netherrack);
			setBlock(i + 18, j + 2, k + 15, Blocks.netherrack);
			setBlock(i + 18, j + 3, k + 0, Blocks.netherrack);
			setBlock(i + 18, j + 3, k + 1, Blocks.netherrack);
			setBlock(i + 18, j + 3, k + 2, Blocks.netherrack);
			setBlock(i + 18, j + 3, k + 3, Blocks.netherrack);
			setBlock(i + 18, j + 3, k + 4, Blocks.netherrack);
			setBlock(i + 18, j + 3, k + 5, Blocks.netherrack);
			setBlock(i + 18, j + 3, k + 6, ROCBlocks.netherrack_bricks);
			setBlock(i + 18, j + 3, k + 7, Blocks.air);
			setBlock(i + 18, j + 3, k + 8, Blocks.air);
			setBlock(i + 18, j + 3, k + 9, ROCBlocks.netherrack_bricks);
			setBlock(i + 18, j + 3, k + 10, Blocks.netherrack);
			setBlock(i + 18, j + 3, k + 11, Blocks.netherrack);
			setBlock(i + 18, j + 3, k + 12, Blocks.netherrack);
			setBlock(i + 18, j + 3, k + 13, Blocks.netherrack);
			setBlock(i + 18, j + 3, k + 14, Blocks.netherrack);
			setBlock(i + 18, j + 3, k + 15, Blocks.netherrack);
			setBlock(i + 18, j + 4, k + 0, Blocks.netherrack);
			setBlock(i + 18, j + 4, k + 1, Blocks.netherrack);
			setBlock(i + 18, j + 4, k + 2, Blocks.netherrack);
			setBlock(i + 18, j + 4, k + 3, Blocks.netherrack);
			setBlock(i + 18, j + 4, k + 4, Blocks.netherrack);
			setBlock(i + 18, j + 4, k + 5, Blocks.netherrack);
			setBlock(i + 18, j + 4, k + 6, ROCBlocks.netherrack_bricks);
			setBlock(i + 18, j + 4, k + 7, Blocks.nether_brick);
			setBlock(i + 18, j + 4, k + 8, Blocks.nether_brick);
			setBlock(i + 18, j + 4, k + 9, ROCBlocks.netherrack_bricks);
			setBlock(i + 18, j + 4, k + 10, Blocks.netherrack);
			setBlock(i + 18, j + 4, k + 11, Blocks.netherrack);
			setBlock(i + 18, j + 4, k + 12, Blocks.netherrack);
			setBlock(i + 18, j + 4, k + 13, Blocks.netherrack);
			setBlock(i + 18, j + 4, k + 14, Blocks.netherrack);
			setBlock(i + 18, j + 4, k + 15, Blocks.netherrack);
			setBlock(i + 19, j + 0, k + 0, Blocks.netherrack);
			setBlock(i + 19, j + 0, k + 1, Blocks.netherrack);
			setBlock(i + 19, j + 0, k + 2, Blocks.netherrack);
			setBlock(i + 19, j + 0, k + 3, Blocks.netherrack);
			setBlock(i + 19, j + 0, k + 4, Blocks.netherrack);
			setBlock(i + 19, j + 0, k + 5, Blocks.netherrack);
			setBlock(i + 19, j + 0, k + 6, ROCBlocks.netherrack_bricks);
			setBlock(i + 19, j + 0, k + 7, Blocks.nether_brick);
			setBlock(i + 19, j + 0, k + 8, Blocks.nether_brick);
			setBlock(i + 19, j + 0, k + 9, ROCBlocks.netherrack_bricks);
			setBlock(i + 19, j + 0, k + 10, Blocks.netherrack);
			setBlock(i + 19, j + 0, k + 11, Blocks.netherrack);
			setBlock(i + 19, j + 0, k + 12, Blocks.netherrack);
			setBlock(i + 19, j + 0, k + 13, Blocks.netherrack);
			setBlock(i + 19, j + 0, k + 14, Blocks.netherrack);
			setBlock(i + 19, j + 0, k + 15, Blocks.netherrack);
			setBlock(i + 19, j + 1, k + 0, Blocks.netherrack);
			setBlock(i + 19, j + 1, k + 1, Blocks.netherrack);
			setBlock(i + 19, j + 1, k + 2, Blocks.netherrack);
			setBlock(i + 19, j + 1, k + 3, Blocks.netherrack);
			setBlock(i + 19, j + 1, k + 4, Blocks.netherrack);
			setBlock(i + 19, j + 1, k + 5, Blocks.netherrack);
			setBlock(i + 19, j + 1, k + 6, ROCBlocks.netherrack_bricks);
			setBlock(i + 19, j + 1, k + 7, Blocks.air);
			setBlock(i + 19, j + 1, k + 8, Blocks.air);
			setBlock(i + 19, j + 1, k + 9, ROCBlocks.netherrack_bricks);
			setBlock(i + 19, j + 1, k + 10, Blocks.netherrack);
			setBlock(i + 19, j + 1, k + 11, Blocks.netherrack);
			setBlock(i + 19, j + 1, k + 12, Blocks.netherrack);
			setBlock(i + 19, j + 1, k + 13, Blocks.netherrack);
			setBlock(i + 19, j + 1, k + 14, Blocks.netherrack);
			setBlock(i + 19, j + 1, k + 15, Blocks.netherrack);
			setBlock(i + 19, j + 2, k + 0, Blocks.netherrack);
			setBlock(i + 19, j + 2, k + 1, Blocks.netherrack);
			setBlock(i + 19, j + 2, k + 2, Blocks.netherrack);
			setBlock(i + 19, j + 2, k + 3, Blocks.netherrack);
			setBlock(i + 19, j + 2, k + 4, Blocks.netherrack);
			setBlock(i + 19, j + 2, k + 5, Blocks.netherrack);
			setBlock(i + 19, j + 2, k + 6, ROCBlocks.netherrack_bricks);
			setBlock(i + 19, j + 2, k + 7, Blocks.air);
			setBlock(i + 19, j + 2, k + 8, Blocks.air);
			setBlock(i + 19, j + 2, k + 9, ROCBlocks.netherrack_bricks);
			setBlock(i + 19, j + 2, k + 10, Blocks.netherrack);
			setBlock(i + 19, j + 2, k + 11, Blocks.netherrack);
			setBlock(i + 19, j + 2, k + 12, Blocks.netherrack);
			setBlock(i + 19, j + 2, k + 13, Blocks.netherrack);
			setBlock(i + 19, j + 2, k + 14, Blocks.netherrack);
			setBlock(i + 19, j + 2, k + 15, Blocks.netherrack);
			setBlock(i + 19, j + 3, k + 0, Blocks.netherrack);
			setBlock(i + 19, j + 3, k + 1, Blocks.netherrack);
			setBlock(i + 19, j + 3, k + 2, Blocks.netherrack);
			setBlock(i + 19, j + 3, k + 3, Blocks.netherrack);
			setBlock(i + 19, j + 3, k + 4, Blocks.netherrack);
			setBlock(i + 19, j + 3, k + 5, Blocks.netherrack);
			setBlock(i + 19, j + 3, k + 6, ROCBlocks.netherrack_bricks);
			setBlock(i + 19, j + 3, k + 7, Blocks.air);
			setBlock(i + 19, j + 3, k + 8, Blocks.air);
			setBlock(i + 19, j + 3, k + 9, ROCBlocks.netherrack_bricks);
			setBlock(i + 19, j + 3, k + 10, Blocks.netherrack);
			setBlock(i + 19, j + 3, k + 11, Blocks.netherrack);
			setBlock(i + 19, j + 3, k + 12, Blocks.netherrack);
			setBlock(i + 19, j + 3, k + 13, Blocks.netherrack);
			setBlock(i + 19, j + 3, k + 14, Blocks.netherrack);
			setBlock(i + 19, j + 3, k + 15, Blocks.netherrack);
			setBlock(i + 19, j + 4, k + 0, Blocks.netherrack);
			setBlock(i + 19, j + 4, k + 1, Blocks.netherrack);
			setBlock(i + 19, j + 4, k + 2, Blocks.netherrack);
			setBlock(i + 19, j + 4, k + 3, Blocks.netherrack);
			setBlock(i + 19, j + 4, k + 4, Blocks.netherrack);
			setBlock(i + 19, j + 4, k + 5, Blocks.netherrack);
			setBlock(i + 19, j + 4, k + 6, ROCBlocks.netherrack_bricks);
			setBlock(i + 19, j + 4, k + 7, Blocks.nether_brick);
			setBlock(i + 19, j + 4, k + 8, Blocks.nether_brick);
			setBlock(i + 19, j + 4, k + 9, ROCBlocks.netherrack_bricks);
			setBlock(i + 19, j + 4, k + 10, Blocks.netherrack);
			setBlock(i + 19, j + 4, k + 11, Blocks.netherrack);
			setBlock(i + 19, j + 4, k + 12, Blocks.netherrack);
			setBlock(i + 19, j + 4, k + 13, Blocks.netherrack);
			setBlock(i + 19, j + 4, k + 14, Blocks.netherrack);
			setBlock(i + 19, j + 4, k + 15, Blocks.netherrack);
			setBlock(i + 20, j + 0, k + 0, Blocks.netherrack);
			setBlock(i + 20, j + 0, k + 1, Blocks.netherrack);
			setBlock(i + 20, j + 0, k + 2, Blocks.netherrack);
			setBlock(i + 20, j + 0, k + 3, Blocks.netherrack);
			setBlock(i + 20, j + 0, k + 4, Blocks.netherrack);
			setBlock(i + 20, j + 0, k + 5, Blocks.netherrack);
			setBlock(i + 20, j + 0, k + 6, ROCBlocks.netherrack_bricks);
			setBlock(i + 20, j + 0, k + 7, Blocks.nether_brick);
			setBlock(i + 20, j + 0, k + 8, Blocks.nether_brick);
			setBlock(i + 20, j + 0, k + 9, ROCBlocks.netherrack_bricks);
			setBlock(i + 20, j + 0, k + 10, Blocks.netherrack);
			setBlock(i + 20, j + 0, k + 11, Blocks.netherrack);
			setBlock(i + 20, j + 0, k + 12, Blocks.netherrack);
			setBlock(i + 20, j + 0, k + 13, Blocks.netherrack);
			setBlock(i + 20, j + 0, k + 14, Blocks.netherrack);
			setBlock(i + 20, j + 0, k + 15, Blocks.netherrack);
			setBlock(i + 20, j + 1, k + 0, Blocks.netherrack);
			setBlock(i + 20, j + 1, k + 1, Blocks.netherrack);
			setBlock(i + 20, j + 1, k + 2, Blocks.netherrack);
			setBlock(i + 20, j + 1, k + 3, Blocks.netherrack);
			setBlock(i + 20, j + 1, k + 4, Blocks.netherrack);
			setBlock(i + 20, j + 1, k + 5, Blocks.netherrack);
			setBlock(i + 20, j + 1, k + 6, ROCBlocks.netherrack_bricks);
			setBlock(i + 20, j + 1, k + 9, ROCBlocks.netherrack_bricks);
			setBlock(i + 20, j + 1, k + 10, Blocks.netherrack);
			setBlock(i + 20, j + 1, k + 11, Blocks.netherrack);
			setBlock(i + 20, j + 1, k + 12, Blocks.netherrack);
			setBlock(i + 20, j + 1, k + 13, Blocks.netherrack);
			setBlock(i + 20, j + 1, k + 14, Blocks.netherrack);
			setBlock(i + 20, j + 1, k + 15, Blocks.netherrack);
			setBlock(i + 20, j + 2, k + 0, Blocks.netherrack);
			setBlock(i + 20, j + 2, k + 1, Blocks.netherrack);
			setBlock(i + 20, j + 2, k + 2, Blocks.netherrack);
			setBlock(i + 20, j + 2, k + 3, Blocks.netherrack);
			setBlock(i + 20, j + 2, k + 4, Blocks.netherrack);
			setBlock(i + 20, j + 2, k + 5, Blocks.netherrack);
			setBlock(i + 20, j + 2, k + 6, ROCBlocks.netherrack_bricks);
			setBlock(i + 20, j + 2, k + 9, ROCBlocks.netherrack_bricks);
			setBlock(i + 20, j + 2, k + 10, Blocks.netherrack);
			setBlock(i + 20, j + 2, k + 11, Blocks.netherrack);
			setBlock(i + 20, j + 2, k + 12, Blocks.netherrack);
			setBlock(i + 20, j + 2, k + 13, Blocks.netherrack);
			setBlock(i + 20, j + 2, k + 14, Blocks.netherrack);
			setBlock(i + 20, j + 2, k + 15, Blocks.netherrack);
			setBlock(i + 20, j + 3, k + 0, Blocks.netherrack);
			setBlock(i + 20, j + 3, k + 1, Blocks.netherrack);
			setBlock(i + 20, j + 3, k + 2, Blocks.netherrack);
			setBlock(i + 20, j + 3, k + 3, Blocks.netherrack);
			setBlock(i + 20, j + 3, k + 4, Blocks.netherrack);
			setBlock(i + 20, j + 3, k + 5, Blocks.netherrack);
			setBlock(i + 20, j + 3, k + 6, ROCBlocks.netherrack_bricks);
			setBlock(i + 20, j + 3, k + 7, ROCBlocks.netherrack_bricks);
			setBlock(i + 20, j + 3, k + 8, ROCBlocks.netherrack_bricks);
			setBlock(i + 20, j + 3, k + 9, ROCBlocks.netherrack_bricks);
			setBlock(i + 20, j + 3, k + 10, Blocks.netherrack);
			setBlock(i + 20, j + 3, k + 11, Blocks.netherrack);
			setBlock(i + 20, j + 3, k + 12, Blocks.netherrack);
			setBlock(i + 20, j + 3, k + 13, Blocks.netherrack);
			setBlock(i + 20, j + 3, k + 14, Blocks.netherrack);
			setBlock(i + 20, j + 3, k + 15, Blocks.netherrack);
			setBlock(i + 20, j + 4, k + 0, Blocks.netherrack);
			setBlock(i + 20, j + 4, k + 1, Blocks.netherrack);
			setBlock(i + 20, j + 4, k + 2, Blocks.netherrack);
			setBlock(i + 20, j + 4, k + 3, Blocks.netherrack);
			setBlock(i + 20, j + 4, k + 4, Blocks.netherrack);
			setBlock(i + 20, j + 4, k + 5, Blocks.netherrack);
			setBlock(i + 20, j + 4, k + 6, ROCBlocks.netherrack_bricks);
			setBlock(i + 20, j + 4, k + 7, Blocks.nether_brick);
			setBlock(i + 20, j + 4, k + 8, Blocks.nether_brick);
			setBlock(i + 20, j + 4, k + 9, ROCBlocks.netherrack_bricks);
			setBlock(i + 20, j + 4, k + 10, Blocks.netherrack);
			setBlock(i + 20, j + 4, k + 11, Blocks.netherrack);
			setBlock(i + 20, j + 4, k + 12, Blocks.netherrack);
			setBlock(i + 20, j + 4, k + 13, Blocks.netherrack);
			setBlock(i + 20, j + 4, k + 14, Blocks.netherrack);
			setBlock(i + 20, j + 4, k + 15, Blocks.netherrack);
			setBlock(i + 7, j + 1, k + 7, Blocks.lava);
			setBlock(i + 7, j + 1, k + 8, Blocks.lava);
			setBlock(i + 8, j + 1, k + 7, Blocks.lava);
			setBlock(i + 8, j + 1, k + 8, Blocks.lava);
			setBlock(i + 20, j + 1, k + 7, Blocks.iron_door, 2, 2);
			setBlock(i + 20, j + 1, k + 8, Blocks.iron_door, 2, 2);
			setBlock(i + 20, j + 2, k + 7, Blocks.iron_door, 9, 2);
			setBlock(i + 20, j + 2, k + 8, Blocks.iron_door, 8, 2);

		return true;
		}
		return false;
		}
    
    private void setBlock(int i, int j, int k, Block block){
    	this.helperWorld.setBlockState(this.helperPos.add(i, j, k), block.getDefaultState());
    }
    
    private void setBlock(int i, int j, int k, Block block, int meta, int flag){
    	this.helperWorld.setBlockState(this.helperPos.add(i, j, k), block.getStateFromMeta(meta), flag);
    }
}