package com.eternaldoom.realmsofchaos.gen;

import java.util.Random;

import net.minecraft.init.Blocks;
import net.minecraft.init.Items;
import net.minecraft.item.Item;
import net.minecraft.tileentity.TileEntityMobSpawner;
import net.minecraft.util.WeightedRandomChestContent;
import net.minecraft.world.World;
import net.minecraft.world.gen.feature.WorldGenerator;

import com.eternaldoom.realmsofchaos.blocks.ROCBlocks;
import com.eternaldoom.realmsofchaos.blocks.TileEntityNetherChest;
import com.eternaldoom.realmsofchaos.items.ROCItems;

public class WorldGenNetherDungeon extends WorldGenerator {
    public static final WeightedRandomChestContent[] cheststuff = new WeightedRandomChestContent[] {new WeightedRandomChestContent(Items.diamond, 0, 1, 3, 3), new WeightedRandomChestContent(ROCItems.xylite_ingot, 0, 1, 2, 1), new WeightedRandomChestContent(Item.getItemFromBlock(Blocks.gold_block), 0, 1, 2, 2), new WeightedRandomChestContent(Items.golden_horse_armor, 0, 1, 1, 2), new WeightedRandomChestContent(Items.diamond_horse_armor, 0, 1, 1, 1), new WeightedRandomChestContent(Items.saddle, 0, 1, 1, 2), new WeightedRandomChestContent(ROCItems.scorpion_stone, 0, 1, 1, 1)};
	public boolean generate(World world, Random rand, int i, int j, int k) {

		if(world.getBlock(i+20, j, k) == Blocks.netherrack && world.getBlock(i+20, j+6, k) == Blocks.netherrack && world.getBlock(i+20, j, k+20) == Blocks.netherrack && world.getBlock(i+20, j+6, k+20) == Blocks.netherrack && world.getBlock(i, j, k+20) == Blocks.netherrack && world.getBlock(i, j+6, k+20) == Blocks.netherrack){
		
			world.setBlock(i + 0, j + 0, k + 0, Blocks.netherrack);
			world.setBlock(i + 0, j + 0, k + 1, Blocks.netherrack);
			world.setBlock(i + 0, j + 0, k + 2, Blocks.netherrack);
			world.setBlock(i + 0, j + 0, k + 3, Blocks.netherrack);
			world.setBlock(i + 0, j + 0, k + 4, Blocks.netherrack);
			world.setBlock(i + 0, j + 0, k + 5, Blocks.netherrack);
			world.setBlock(i + 0, j + 0, k + 6, Blocks.netherrack);
			world.setBlock(i + 0, j + 0, k + 7, Blocks.nether_brick);
			world.setBlock(i + 0, j + 0, k + 8, Blocks.nether_brick);
			world.setBlock(i + 0, j + 0, k + 9, Blocks.netherrack);
			world.setBlock(i + 0, j + 0, k + 10, Blocks.netherrack);
			world.setBlock(i + 0, j + 0, k + 11, Blocks.netherrack);
			world.setBlock(i + 0, j + 0, k + 12, Blocks.netherrack);
			world.setBlock(i + 0, j + 0, k + 13, Blocks.netherrack);
			world.setBlock(i + 0, j + 0, k + 14, Blocks.netherrack);
			world.setBlock(i + 0, j + 0, k + 15, Blocks.netherrack);
			world.setBlock(i + 0, j + 1, k + 0, Blocks.netherrack);
			world.setBlock(i + 0, j + 1, k + 1, Blocks.netherrack);
			world.setBlock(i + 0, j + 1, k + 2, Blocks.netherrack);
			world.setBlock(i + 0, j + 1, k + 3, Blocks.netherrack);
			world.setBlock(i + 0, j + 1, k + 4, Blocks.netherrack);
			world.setBlock(i + 0, j + 1, k + 5, Blocks.netherrack);
			world.setBlock(i + 0, j + 1, k + 6, Blocks.netherrack);
			world.setBlock(i + 0, j + 1, k + 7, ROCBlocks.netherrack_bricks);
			world.setBlock(i + 0, j + 1, k + 8, ROCBlocks.netherrack_bricks);
			world.setBlock(i + 0, j + 1, k + 9, Blocks.netherrack);
			world.setBlock(i + 0, j + 1, k + 10, Blocks.netherrack);
			world.setBlock(i + 0, j + 1, k + 11, Blocks.netherrack);
			world.setBlock(i + 0, j + 1, k + 12, Blocks.netherrack);
			world.setBlock(i + 0, j + 1, k + 13, Blocks.netherrack);
			world.setBlock(i + 0, j + 1, k + 14, Blocks.netherrack);
			world.setBlock(i + 0, j + 1, k + 15, Blocks.netherrack);
			world.setBlock(i + 0, j + 2, k + 0, Blocks.netherrack);
			world.setBlock(i + 0, j + 2, k + 1, Blocks.netherrack);
			world.setBlock(i + 0, j + 2, k + 2, Blocks.netherrack);
			world.setBlock(i + 0, j + 2, k + 3, Blocks.netherrack);
			world.setBlock(i + 0, j + 2, k + 4, Blocks.netherrack);
			world.setBlock(i + 0, j + 2, k + 5, Blocks.netherrack);
			world.setBlock(i + 0, j + 2, k + 6, Blocks.netherrack);
			world.setBlock(i + 0, j + 2, k + 7, ROCBlocks.netherrack_bricks);
			world.setBlock(i + 0, j + 2, k + 8, ROCBlocks.netherrack_bricks);
			world.setBlock(i + 0, j + 2, k + 9, Blocks.netherrack);
			world.setBlock(i + 0, j + 2, k + 10, Blocks.netherrack);
			world.setBlock(i + 0, j + 2, k + 11, Blocks.netherrack);
			world.setBlock(i + 0, j + 2, k + 12, Blocks.netherrack);
			world.setBlock(i + 0, j + 2, k + 13, Blocks.netherrack);
			world.setBlock(i + 0, j + 2, k + 14, Blocks.netherrack);
			world.setBlock(i + 0, j + 2, k + 15, Blocks.netherrack);
			world.setBlock(i + 0, j + 3, k + 0, Blocks.netherrack);
			world.setBlock(i + 0, j + 3, k + 1, Blocks.netherrack);
			world.setBlock(i + 0, j + 3, k + 2, Blocks.netherrack);
			world.setBlock(i + 0, j + 3, k + 3, Blocks.netherrack);
			world.setBlock(i + 0, j + 3, k + 4, Blocks.netherrack);
			world.setBlock(i + 0, j + 3, k + 5, Blocks.netherrack);
			world.setBlock(i + 0, j + 3, k + 6, Blocks.netherrack);
			world.setBlock(i + 0, j + 3, k + 7, ROCBlocks.netherrack_bricks);
			world.setBlock(i + 0, j + 3, k + 8, ROCBlocks.netherrack_bricks);
			world.setBlock(i + 0, j + 3, k + 9, Blocks.netherrack);
			world.setBlock(i + 0, j + 3, k + 10, Blocks.netherrack);
			world.setBlock(i + 0, j + 3, k + 11, Blocks.netherrack);
			world.setBlock(i + 0, j + 3, k + 12, Blocks.netherrack);
			world.setBlock(i + 0, j + 3, k + 13, Blocks.netherrack);
			world.setBlock(i + 0, j + 3, k + 14, Blocks.netherrack);
			world.setBlock(i + 0, j + 3, k + 15, Blocks.netherrack);
			world.setBlock(i + 0, j + 4, k + 0, Blocks.netherrack);
			world.setBlock(i + 0, j + 4, k + 1, Blocks.netherrack);
			world.setBlock(i + 0, j + 4, k + 2, Blocks.netherrack);
			world.setBlock(i + 0, j + 4, k + 3, Blocks.netherrack);
			world.setBlock(i + 0, j + 4, k + 4, Blocks.netherrack);
			world.setBlock(i + 0, j + 4, k + 5, Blocks.netherrack);
			world.setBlock(i + 0, j + 4, k + 6, Blocks.netherrack);
			world.setBlock(i + 0, j + 4, k + 7, ROCBlocks.netherrack_bricks);
			world.setBlock(i + 0, j + 4, k + 8, ROCBlocks.netherrack_bricks);
			world.setBlock(i + 0, j + 4, k + 9, Blocks.netherrack);
			world.setBlock(i + 0, j + 4, k + 10, Blocks.netherrack);
			world.setBlock(i + 0, j + 4, k + 11, Blocks.netherrack);
			world.setBlock(i + 0, j + 4, k + 12, Blocks.netherrack);
			world.setBlock(i + 0, j + 4, k + 13, Blocks.netherrack);
			world.setBlock(i + 0, j + 4, k + 14, Blocks.netherrack);
			world.setBlock(i + 0, j + 4, k + 15, Blocks.netherrack);
			world.setBlock(i + 1, j + 0, k + 0, Blocks.netherrack);
			world.setBlock(i + 1, j + 0, k + 1, Blocks.netherrack);
			world.setBlock(i + 1, j + 0, k + 2, Blocks.netherrack);
			world.setBlock(i + 1, j + 0, k + 3, Blocks.netherrack);
			world.setBlock(i + 1, j + 0, k + 4, Blocks.netherrack);
			world.setBlock(i + 1, j + 0, k + 5, Blocks.nether_brick);
			world.setBlock(i + 1, j + 0, k + 6, Blocks.nether_brick);
			world.setBlock(i + 1, j + 0, k + 7, Blocks.nether_brick);
			world.setBlock(i + 1, j + 0, k + 8, Blocks.nether_brick);
			world.setBlock(i + 1, j + 0, k + 9, Blocks.nether_brick);
			world.setBlock(i + 1, j + 0, k + 10, Blocks.nether_brick);
			world.setBlock(i + 1, j + 0, k + 11, Blocks.netherrack);
			world.setBlock(i + 1, j + 0, k + 12, Blocks.netherrack);
			world.setBlock(i + 1, j + 0, k + 13, Blocks.netherrack);
			world.setBlock(i + 1, j + 0, k + 14, Blocks.netherrack);
			world.setBlock(i + 1, j + 0, k + 15, Blocks.netherrack);
			world.setBlock(i + 1, j + 1, k + 0, Blocks.netherrack);
			world.setBlock(i + 1, j + 1, k + 1, Blocks.netherrack);
			world.setBlock(i + 1, j + 1, k + 2, Blocks.netherrack);
			world.setBlock(i + 1, j + 1, k + 3, Blocks.netherrack);
			world.setBlock(i + 1, j + 1, k + 4, Blocks.netherrack);
			world.setBlock(i + 1, j + 1, k + 5, ROCBlocks.netherrack_bricks);
			world.setBlock(i + 1, j + 1, k + 6, ROCBlocks.netherrack_bricks);
			world.setBlock(i + 1, j + 1, k + 7, ROCBlocks.nether_chest, 5, 2);
			world.setBlock(i + 1, j + 1, k + 8, ROCBlocks.nether_chest, 5, 2);
			TileEntityNetherChest chest = (TileEntityNetherChest)world.getTileEntity(i+1, j+1, k+8);
			if (chest != null) WeightedRandomChestContent.generateChestContents(rand, cheststuff, chest, 10);
			world.setBlock(i + 1, j + 1, k + 9, ROCBlocks.netherrack_bricks);
			world.setBlock(i + 1, j + 1, k + 10, ROCBlocks.netherrack_bricks);
			world.setBlock(i + 1, j + 1, k + 11, Blocks.netherrack);
			world.setBlock(i + 1, j + 1, k + 12, Blocks.netherrack);
			world.setBlock(i + 1, j + 1, k + 13, Blocks.netherrack);
			world.setBlock(i + 1, j + 1, k + 14, Blocks.netherrack);
			world.setBlock(i + 1, j + 1, k + 15, Blocks.netherrack);
			world.setBlock(i + 1, j + 2, k + 0, Blocks.netherrack);
			world.setBlock(i + 1, j + 2, k + 1, Blocks.netherrack);
			world.setBlock(i + 1, j + 2, k + 2, Blocks.netherrack);
			world.setBlock(i + 1, j + 2, k + 3, Blocks.netherrack);
			world.setBlock(i + 1, j + 2, k + 4, Blocks.netherrack);
			world.setBlock(i + 1, j + 2, k + 5, ROCBlocks.netherrack_bricks);
			world.setBlock(i + 1, j + 2, k + 6, ROCBlocks.netherrack_bricks);
			world.setBlock(i + 1, j + 2, k + 7, Blocks.air);
			world.setBlock(i + 1, j + 2, k + 8, Blocks.air);
			world.setBlock(i + 1, j + 2, k + 9, ROCBlocks.netherrack_bricks);
			world.setBlock(i + 1, j + 2, k + 10, ROCBlocks.netherrack_bricks);
			world.setBlock(i + 1, j + 2, k + 11, Blocks.netherrack);
			world.setBlock(i + 1, j + 2, k + 12, Blocks.netherrack);
			world.setBlock(i + 1, j + 2, k + 13, Blocks.netherrack);
			world.setBlock(i + 1, j + 2, k + 14, Blocks.netherrack);
			world.setBlock(i + 1, j + 2, k + 15, Blocks.netherrack);
			world.setBlock(i + 1, j + 3, k + 0, Blocks.netherrack);
			world.setBlock(i + 1, j + 3, k + 1, Blocks.netherrack);
			world.setBlock(i + 1, j + 3, k + 2, Blocks.netherrack);
			world.setBlock(i + 1, j + 3, k + 3, Blocks.netherrack);
			world.setBlock(i + 1, j + 3, k + 4, Blocks.netherrack);
			world.setBlock(i + 1, j + 3, k + 5, ROCBlocks.netherrack_bricks);
			world.setBlock(i + 1, j + 3, k + 6, ROCBlocks.netherrack_bricks);
			world.setBlock(i + 1, j + 3, k + 7, Blocks.air);
			world.setBlock(i + 1, j + 3, k + 8, Blocks.air);
			world.setBlock(i + 1, j + 3, k + 9, ROCBlocks.netherrack_bricks);
			world.setBlock(i + 1, j + 3, k + 10, ROCBlocks.netherrack_bricks);
			world.setBlock(i + 1, j + 3, k + 11, Blocks.netherrack);
			world.setBlock(i + 1, j + 3, k + 12, Blocks.netherrack);
			world.setBlock(i + 1, j + 3, k + 13, Blocks.netherrack);
			world.setBlock(i + 1, j + 3, k + 14, Blocks.netherrack);
			world.setBlock(i + 1, j + 3, k + 15, Blocks.netherrack);
			world.setBlock(i + 1, j + 4, k + 0, Blocks.netherrack);
			world.setBlock(i + 1, j + 4, k + 1, Blocks.netherrack);
			world.setBlock(i + 1, j + 4, k + 2, Blocks.netherrack);
			world.setBlock(i + 1, j + 4, k + 3, Blocks.netherrack);
			world.setBlock(i + 1, j + 4, k + 4, Blocks.netherrack);
			world.setBlock(i + 1, j + 4, k + 5, ROCBlocks.netherrack_bricks);
			world.setBlock(i + 1, j + 4, k + 6, ROCBlocks.netherrack_bricks);
			world.setBlock(i + 1, j + 4, k + 7, ROCBlocks.charwood_log);
			world.setBlock(i + 1, j + 4, k + 8, ROCBlocks.charwood_log);
			world.setBlock(i + 1, j + 4, k + 9, ROCBlocks.netherrack_bricks);
			world.setBlock(i + 1, j + 4, k + 10, ROCBlocks.netherrack_bricks);
			world.setBlock(i + 1, j + 4, k + 11, Blocks.netherrack);
			world.setBlock(i + 1, j + 4, k + 12, Blocks.netherrack);
			world.setBlock(i + 1, j + 4, k + 13, Blocks.netherrack);
			world.setBlock(i + 1, j + 4, k + 14, Blocks.netherrack);
			world.setBlock(i + 1, j + 4, k + 15, Blocks.netherrack);
			world.setBlock(i + 2, j + 0, k + 0, Blocks.netherrack);
			world.setBlock(i + 2, j + 0, k + 1, Blocks.netherrack);
			world.setBlock(i + 2, j + 0, k + 2, Blocks.netherrack);
			world.setBlock(i + 2, j + 0, k + 3, Blocks.nether_brick);
			world.setBlock(i + 2, j + 0, k + 4, Blocks.nether_brick);
			world.setBlock(i + 2, j + 0, k + 5, Blocks.nether_brick);
			world.setBlock(i + 2, j + 0, k + 6, Blocks.nether_brick);
			world.setBlock(i + 2, j + 0, k + 7, Blocks.nether_brick);
			world.setBlock(i + 2, j + 0, k + 8, Blocks.nether_brick);
			world.setBlock(i + 2, j + 0, k + 9, Blocks.nether_brick);
			world.setBlock(i + 2, j + 0, k + 10, Blocks.nether_brick);
			world.setBlock(i + 2, j + 0, k + 11, Blocks.nether_brick);
			world.setBlock(i + 2, j + 0, k + 12, Blocks.nether_brick);
			world.setBlock(i + 2, j + 0, k + 13, Blocks.netherrack);
			world.setBlock(i + 2, j + 0, k + 14, Blocks.netherrack);
			world.setBlock(i + 2, j + 0, k + 15, Blocks.netherrack);
			world.setBlock(i + 2, j + 1, k + 0, Blocks.netherrack);
			world.setBlock(i + 2, j + 1, k + 1, Blocks.netherrack);
			world.setBlock(i + 2, j + 1, k + 2, Blocks.netherrack);
			world.setBlock(i + 2, j + 1, k + 3, ROCBlocks.netherrack_bricks);
			world.setBlock(i + 2, j + 1, k + 4, ROCBlocks.netherrack_bricks);
			world.setBlock(i + 2, j + 1, k + 5, Blocks.air);
			world.setBlock(i + 2, j + 1, k + 6, Blocks.air);
			world.setBlock(i + 2, j + 1, k + 7, Blocks.air);
			world.setBlock(i + 2, j + 1, k + 8, Blocks.air);
			world.setBlock(i + 2, j + 1, k + 9, Blocks.air);
			world.setBlock(i + 2, j + 1, k + 10, Blocks.air);
			world.setBlock(i + 2, j + 1, k + 11, ROCBlocks.netherrack_bricks);
			world.setBlock(i + 2, j + 1, k + 12, ROCBlocks.netherrack_bricks);
			world.setBlock(i + 2, j + 1, k + 13, Blocks.netherrack);
			world.setBlock(i + 2, j + 1, k + 14, Blocks.netherrack);
			world.setBlock(i + 2, j + 1, k + 15, Blocks.netherrack);
			world.setBlock(i + 2, j + 2, k + 0, Blocks.netherrack);
			world.setBlock(i + 2, j + 2, k + 1, Blocks.netherrack);
			world.setBlock(i + 2, j + 2, k + 2, Blocks.netherrack);
			world.setBlock(i + 2, j + 2, k + 3, ROCBlocks.netherrack_bricks);
			world.setBlock(i + 2, j + 2, k + 4, ROCBlocks.netherrack_bricks);
			world.setBlock(i + 2, j + 2, k + 5, Blocks.air);
			world.setBlock(i + 2, j + 2, k + 6, Blocks.air);
			world.setBlock(i + 2, j + 2, k + 7, Blocks.air);
			world.setBlock(i + 2, j + 2, k + 8, Blocks.air);
			world.setBlock(i + 2, j + 2, k + 9, Blocks.air);
			world.setBlock(i + 2, j + 2, k + 10, Blocks.air);
			world.setBlock(i + 2, j + 2, k + 11, ROCBlocks.netherrack_bricks);
			world.setBlock(i + 2, j + 2, k + 12, ROCBlocks.netherrack_bricks);
			world.setBlock(i + 2, j + 2, k + 13, Blocks.netherrack);
			world.setBlock(i + 2, j + 2, k + 14, Blocks.netherrack);
			world.setBlock(i + 2, j + 2, k + 15, Blocks.netherrack);
			world.setBlock(i + 2, j + 3, k + 0, Blocks.netherrack);
			world.setBlock(i + 2, j + 3, k + 1, Blocks.netherrack);
			world.setBlock(i + 2, j + 3, k + 2, Blocks.netherrack);
			world.setBlock(i + 2, j + 3, k + 3, ROCBlocks.netherrack_bricks);
			world.setBlock(i + 2, j + 3, k + 4, ROCBlocks.netherrack_bricks);
			world.setBlock(i + 2, j + 3, k + 5, Blocks.air);
			world.setBlock(i + 2, j + 3, k + 6, Blocks.air);
			world.setBlock(i + 2, j + 3, k + 7, Blocks.air);
			world.setBlock(i + 2, j + 3, k + 8, Blocks.air);
			world.setBlock(i + 2, j + 3, k + 9, Blocks.air);
			world.setBlock(i + 2, j + 3, k + 10, Blocks.air);
			world.setBlock(i + 2, j + 3, k + 11, ROCBlocks.netherrack_bricks);
			world.setBlock(i + 2, j + 3, k + 12, ROCBlocks.netherrack_bricks);
			world.setBlock(i + 2, j + 3, k + 13, Blocks.netherrack);
			world.setBlock(i + 2, j + 3, k + 14, Blocks.netherrack);
			world.setBlock(i + 2, j + 3, k + 15, Blocks.netherrack);
			world.setBlock(i + 2, j + 4, k + 0, Blocks.netherrack);
			world.setBlock(i + 2, j + 4, k + 1, Blocks.netherrack);
			world.setBlock(i + 2, j + 4, k + 2, Blocks.netherrack);
			world.setBlock(i + 2, j + 4, k + 3, ROCBlocks.netherrack_bricks);
			world.setBlock(i + 2, j + 4, k + 4, ROCBlocks.netherrack_bricks);
			world.setBlock(i + 2, j + 4, k + 5, ROCBlocks.charwood_log);
			world.setBlock(i + 2, j + 4, k + 6, ROCBlocks.charwood_log);
			world.setBlock(i + 2, j + 4, k + 7, ROCBlocks.charwood_log);
			world.setBlock(i + 2, j + 4, k + 8, ROCBlocks.charwood_log);
			world.setBlock(i + 2, j + 4, k + 9, ROCBlocks.charwood_log);
			world.setBlock(i + 2, j + 4, k + 10, ROCBlocks.charwood_log);
			world.setBlock(i + 2, j + 4, k + 11, ROCBlocks.netherrack_bricks);
			world.setBlock(i + 2, j + 4, k + 12, ROCBlocks.netherrack_bricks);
			world.setBlock(i + 2, j + 4, k + 13, Blocks.netherrack);
			world.setBlock(i + 2, j + 4, k + 14, Blocks.netherrack);
			world.setBlock(i + 2, j + 4, k + 15, Blocks.netherrack);
			world.setBlock(i + 3, j + 0, k + 0, Blocks.netherrack);
			world.setBlock(i + 3, j + 0, k + 1, Blocks.netherrack);
			world.setBlock(i + 3, j + 0, k + 2, Blocks.nether_brick);
			world.setBlock(i + 3, j + 0, k + 3, Blocks.nether_brick);
			world.setBlock(i + 3, j + 0, k + 4, Blocks.nether_brick);
			world.setBlock(i + 3, j + 0, k + 5, Blocks.nether_brick);
			world.setBlock(i + 3, j + 0, k + 6, Blocks.nether_brick);
			world.setBlock(i + 3, j + 0, k + 7, Blocks.nether_brick);
			world.setBlock(i + 3, j + 0, k + 8, Blocks.nether_brick);
			world.setBlock(i + 3, j + 0, k + 9, Blocks.nether_brick);
			world.setBlock(i + 3, j + 0, k + 10, Blocks.nether_brick);
			world.setBlock(i + 3, j + 0, k + 11, Blocks.nether_brick);
			world.setBlock(i + 3, j + 0, k + 12, Blocks.nether_brick);
			world.setBlock(i + 3, j + 0, k + 13, Blocks.nether_brick);
			world.setBlock(i + 3, j + 0, k + 14, Blocks.netherrack);
			world.setBlock(i + 3, j + 0, k + 15, Blocks.netherrack);
			world.setBlock(i + 3, j + 1, k + 0, Blocks.netherrack);
			world.setBlock(i + 3, j + 1, k + 1, Blocks.netherrack);
			world.setBlock(i + 3, j + 1, k + 2, ROCBlocks.netherrack_bricks);
			world.setBlock(i + 3, j + 1, k + 3, Blocks.air);
			world.setBlock(i + 3, j + 1, k + 4, Blocks.air);
			world.setBlock(i + 3, j + 1, k + 5, Blocks.air);
			world.setBlock(i + 3, j + 1, k + 6, Blocks.air);
			world.setBlock(i + 3, j + 1, k + 7, Blocks.air);
			world.setBlock(i + 3, j + 1, k + 8, Blocks.air);
			world.setBlock(i + 3, j + 1, k + 9, Blocks.air);
			world.setBlock(i + 3, j + 1, k + 10, Blocks.air);
			world.setBlock(i + 3, j + 1, k + 11, Blocks.air);
			world.setBlock(i + 3, j + 1, k + 12, Blocks.air);
			world.setBlock(i + 3, j + 1, k + 13, ROCBlocks.netherrack_bricks);
			world.setBlock(i + 3, j + 1, k + 14, Blocks.netherrack);
			world.setBlock(i + 3, j + 1, k + 15, Blocks.netherrack);
			world.setBlock(i + 3, j + 2, k + 0, Blocks.netherrack);
			world.setBlock(i + 3, j + 2, k + 1, Blocks.netherrack);
			world.setBlock(i + 3, j + 2, k + 2, ROCBlocks.netherrack_bricks);
			world.setBlock(i + 3, j + 2, k + 3, Blocks.air);
			world.setBlock(i + 3, j + 2, k + 4, Blocks.air);
			world.setBlock(i + 3, j + 2, k + 5, Blocks.air);
			world.setBlock(i + 3, j + 2, k + 6, Blocks.air);
			world.setBlock(i + 3, j + 2, k + 7, Blocks.air);
			world.setBlock(i + 3, j + 2, k + 8, Blocks.air);
			world.setBlock(i + 3, j + 2, k + 9, Blocks.air);
			world.setBlock(i + 3, j + 2, k + 10, Blocks.air);
			world.setBlock(i + 3, j + 2, k + 11, Blocks.air);
			world.setBlock(i + 3, j + 2, k + 12, Blocks.air);
			world.setBlock(i + 3, j + 2, k + 13, ROCBlocks.netherrack_bricks);
			world.setBlock(i + 3, j + 2, k + 14, Blocks.netherrack);
			world.setBlock(i + 3, j + 2, k + 15, Blocks.netherrack);
			world.setBlock(i + 3, j + 3, k + 0, Blocks.netherrack);
			world.setBlock(i + 3, j + 3, k + 1, Blocks.netherrack);
			world.setBlock(i + 3, j + 3, k + 2, ROCBlocks.netherrack_bricks);
			world.setBlock(i + 3, j + 3, k + 3, Blocks.air);
			world.setBlock(i + 3, j + 3, k + 4, Blocks.air);
			world.setBlock(i + 3, j + 3, k + 5, Blocks.air);
			world.setBlock(i + 3, j + 3, k + 6, Blocks.air);
			world.setBlock(i + 3, j + 3, k + 7, Blocks.air);
			world.setBlock(i + 3, j + 3, k + 8, Blocks.air);
			world.setBlock(i + 3, j + 3, k + 9, Blocks.air);
			world.setBlock(i + 3, j + 3, k + 10, Blocks.air);
			world.setBlock(i + 3, j + 3, k + 11, Blocks.air);
			world.setBlock(i + 3, j + 3, k + 12, Blocks.air);
			world.setBlock(i + 3, j + 3, k + 13, ROCBlocks.netherrack_bricks);
			world.setBlock(i + 3, j + 3, k + 14, Blocks.netherrack);
			world.setBlock(i + 3, j + 3, k + 15, Blocks.netherrack);
			world.setBlock(i + 3, j + 4, k + 0, Blocks.netherrack);
			world.setBlock(i + 3, j + 4, k + 1, Blocks.netherrack);
			world.setBlock(i + 3, j + 4, k + 2, ROCBlocks.netherrack_bricks);
			world.setBlock(i + 3, j + 4, k + 3, ROCBlocks.charwood_log);
			world.setBlock(i + 3, j + 4, k + 4, ROCBlocks.charwood_log);
			world.setBlock(i + 3, j + 4, k + 5, ROCBlocks.charwood_log);
			world.setBlock(i + 3, j + 4, k + 6, ROCBlocks.charwood_log);
			world.setBlock(i + 3, j + 4, k + 7, ROCBlocks.charwood_log);
			world.setBlock(i + 3, j + 4, k + 8, ROCBlocks.charwood_log);
			world.setBlock(i + 3, j + 4, k + 9, ROCBlocks.charwood_log);
			world.setBlock(i + 3, j + 4, k + 10, ROCBlocks.charwood_log);
			world.setBlock(i + 3, j + 4, k + 11, ROCBlocks.charwood_log);
			world.setBlock(i + 3, j + 4, k + 12, ROCBlocks.charwood_log);
			world.setBlock(i + 3, j + 4, k + 13, ROCBlocks.netherrack_bricks);
			world.setBlock(i + 3, j + 4, k + 14, Blocks.netherrack);
			world.setBlock(i + 3, j + 4, k + 15, Blocks.netherrack);
			world.setBlock(i + 4, j + 0, k + 0, Blocks.netherrack);
			world.setBlock(i + 4, j + 0, k + 1, Blocks.nether_brick);
			world.setBlock(i + 4, j + 0, k + 2, Blocks.nether_brick);
			world.setBlock(i + 4, j + 0, k + 3, Blocks.nether_brick);
			world.setBlock(i + 4, j + 0, k + 4, Blocks.nether_brick);
			world.setBlock(i + 4, j + 0, k + 5, Blocks.nether_brick);
			world.setBlock(i + 4, j + 0, k + 6, Blocks.nether_brick);
			world.setBlock(i + 4, j + 0, k + 7, Blocks.nether_brick);
			world.setBlock(i + 4, j + 0, k + 8, Blocks.nether_brick);
			world.setBlock(i + 4, j + 0, k + 9, Blocks.nether_brick);
			world.setBlock(i + 4, j + 0, k + 10, Blocks.nether_brick);
			world.setBlock(i + 4, j + 0, k + 11, Blocks.nether_brick);
			world.setBlock(i + 4, j + 0, k + 12, Blocks.nether_brick);
			world.setBlock(i + 4, j + 0, k + 13, Blocks.nether_brick);
			world.setBlock(i + 4, j + 0, k + 14, Blocks.nether_brick);
			world.setBlock(i + 4, j + 0, k + 15, Blocks.netherrack);
			world.setBlock(i + 4, j + 1, k + 0, Blocks.netherrack);
			world.setBlock(i + 4, j + 1, k + 1, ROCBlocks.netherrack_bricks);
			world.setBlock(i + 4, j + 1, k + 2, Blocks.air);
			world.setBlock(i + 4, j + 1, k + 3, Blocks.air);
			world.setBlock(i + 4, j + 1, k + 4, Blocks.air);
			world.setBlock(i + 4, j + 1, k + 5, Blocks.air);
			world.setBlock(i + 4, j + 1, k + 6, Blocks.air);
			world.setBlock(i + 4, j + 1, k + 7, Blocks.air);
			world.setBlock(i + 4, j + 1, k + 8, Blocks.air);
			world.setBlock(i + 4, j + 1, k + 9, Blocks.air);
			world.setBlock(i + 4, j + 1, k + 10, Blocks.air);
			world.setBlock(i + 4, j + 1, k + 11, Blocks.air);
			world.setBlock(i + 4, j + 1, k + 12, Blocks.air);
			world.setBlock(i + 4, j + 1, k + 13, Blocks.air);
			world.setBlock(i + 4, j + 1, k + 14, ROCBlocks.netherrack_bricks);
			world.setBlock(i + 4, j + 1, k + 15, Blocks.netherrack);
			world.setBlock(i + 4, j + 2, k + 0, Blocks.netherrack);
			world.setBlock(i + 4, j + 2, k + 1, ROCBlocks.netherrack_bricks);
			world.setBlock(i + 4, j + 2, k + 2, Blocks.air);
			world.setBlock(i + 4, j + 2, k + 3, Blocks.air);
			world.setBlock(i + 4, j + 2, k + 4, Blocks.air);
			world.setBlock(i + 4, j + 2, k + 5, Blocks.air);
			world.setBlock(i + 4, j + 2, k + 6, Blocks.air);
			world.setBlock(i + 4, j + 2, k + 7, Blocks.air);
			world.setBlock(i + 4, j + 2, k + 8, Blocks.air);
			world.setBlock(i + 4, j + 2, k + 9, Blocks.air);
			world.setBlock(i + 4, j + 2, k + 10, Blocks.air);
			world.setBlock(i + 4, j + 2, k + 11, Blocks.air);
			world.setBlock(i + 4, j + 2, k + 12, Blocks.air);
			world.setBlock(i + 4, j + 2, k + 13, Blocks.air);
			world.setBlock(i + 4, j + 2, k + 14, ROCBlocks.netherrack_bricks);
			world.setBlock(i + 4, j + 2, k + 15, Blocks.netherrack);
			world.setBlock(i + 4, j + 3, k + 0, Blocks.netherrack);
			world.setBlock(i + 4, j + 3, k + 1, ROCBlocks.netherrack_bricks);
			world.setBlock(i + 4, j + 3, k + 2, Blocks.air);
			world.setBlock(i + 4, j + 3, k + 3, Blocks.air);
			world.setBlock(i + 4, j + 3, k + 4, Blocks.air);
			world.setBlock(i + 4, j + 3, k + 5, Blocks.air);
			world.setBlock(i + 4, j + 3, k + 6, Blocks.air);
			world.setBlock(i + 4, j + 3, k + 7, Blocks.air);
			world.setBlock(i + 4, j + 3, k + 8, Blocks.air);
			world.setBlock(i + 4, j + 3, k + 9, Blocks.air);
			world.setBlock(i + 4, j + 3, k + 10, Blocks.air);
			world.setBlock(i + 4, j + 3, k + 11, Blocks.air);
			world.setBlock(i + 4, j + 3, k + 12, Blocks.air);
			world.setBlock(i + 4, j + 3, k + 13, Blocks.air);
			world.setBlock(i + 4, j + 3, k + 14, ROCBlocks.netherrack_bricks);
			world.setBlock(i + 4, j + 3, k + 15, Blocks.netherrack);
			world.setBlock(i + 4, j + 4, k + 0, Blocks.netherrack);
			world.setBlock(i + 4, j + 4, k + 1, ROCBlocks.netherrack_bricks);
			world.setBlock(i + 4, j + 4, k + 2, ROCBlocks.charwood_log);
			world.setBlock(i + 4, j + 4, k + 3, ROCBlocks.charwood_log);
			world.setBlock(i + 4, j + 4, k + 4, ROCBlocks.charwood_log);
			world.setBlock(i + 4, j + 4, k + 5, ROCBlocks.charwood_log);
			world.setBlock(i + 4, j + 4, k + 6, ROCBlocks.charwood_log);
			world.setBlock(i + 4, j + 4, k + 7, ROCBlocks.charwood_log);
			world.setBlock(i + 4, j + 4, k + 8, ROCBlocks.charwood_log);
			world.setBlock(i + 4, j + 4, k + 9, ROCBlocks.charwood_log);
			world.setBlock(i + 4, j + 4, k + 10, ROCBlocks.charwood_log);
			world.setBlock(i + 4, j + 4, k + 11, ROCBlocks.charwood_log);
			world.setBlock(i + 4, j + 4, k + 12, ROCBlocks.charwood_log);
			world.setBlock(i + 4, j + 4, k + 13, ROCBlocks.charwood_log);
			world.setBlock(i + 4, j + 4, k + 14, ROCBlocks.netherrack_bricks);
			world.setBlock(i + 4, j + 4, k + 15, Blocks.netherrack);
			world.setBlock(i + 5, j + 0, k + 0, Blocks.netherrack);
			world.setBlock(i + 5, j + 0, k + 1, Blocks.nether_brick);
			world.setBlock(i + 5, j + 0, k + 2, Blocks.nether_brick);
			world.setBlock(i + 5, j + 0, k + 3, Blocks.nether_brick);
			world.setBlock(i + 5, j + 0, k + 4, Blocks.nether_brick);
			world.setBlock(i + 5, j + 0, k + 5, Blocks.nether_brick);
			world.setBlock(i + 5, j + 0, k + 6, Blocks.nether_brick);
			world.setBlock(i + 5, j + 0, k + 7, Blocks.nether_brick);
			world.setBlock(i + 5, j + 0, k + 8, Blocks.nether_brick);
			world.setBlock(i + 5, j + 0, k + 9, Blocks.nether_brick);
			world.setBlock(i + 5, j + 0, k + 10, Blocks.nether_brick);
			world.setBlock(i + 5, j + 0, k + 11, Blocks.nether_brick);
			world.setBlock(i + 5, j + 0, k + 12, Blocks.nether_brick);
			world.setBlock(i + 5, j + 0, k + 13, Blocks.nether_brick);
			world.setBlock(i + 5, j + 0, k + 14, Blocks.nether_brick);
			world.setBlock(i + 5, j + 0, k + 15, Blocks.netherrack);
			world.setBlock(i + 5, j + 1, k + 0, Blocks.netherrack);
			world.setBlock(i + 5, j + 1, k + 1, ROCBlocks.netherrack_bricks);
			world.setBlock(i + 5, j + 1, k + 2, Blocks.air);
			world.setBlock(i + 5, j + 1, k + 3, Blocks.air);
			world.setBlock(i + 5, j + 1, k + 4, Blocks.air);
			world.setBlock(i + 5, j + 1, k + 5, Blocks.air);
			world.setBlock(i + 5, j + 1, k + 6, Blocks.air);
			world.setBlock(i + 5, j + 1, k + 7, Blocks.air);
			world.setBlock(i + 5, j + 1, k + 8, Blocks.air);
			world.setBlock(i + 5, j + 1, k + 9, Blocks.air);
			world.setBlock(i + 5, j + 1, k + 10, Blocks.air);
			world.setBlock(i + 5, j + 1, k + 11, Blocks.air);
			world.setBlock(i + 5, j + 1, k + 12, Blocks.air);
			world.setBlock(i + 5, j + 1, k + 13, Blocks.air);
			world.setBlock(i + 5, j + 1, k + 14, ROCBlocks.netherrack_bricks);
			world.setBlock(i + 5, j + 1, k + 15, Blocks.netherrack);
			world.setBlock(i + 5, j + 2, k + 0, Blocks.netherrack);
			world.setBlock(i + 5, j + 2, k + 1, ROCBlocks.netherrack_bricks);
			world.setBlock(i + 5, j + 2, k + 2, Blocks.air);
			world.setBlock(i + 5, j + 2, k + 3, Blocks.air);
			world.setBlock(i + 5, j + 2, k + 4, Blocks.air);
			world.setBlock(i + 5, j + 2, k + 5, Blocks.air);
			world.setBlock(i + 5, j + 2, k + 6, Blocks.air);
			world.setBlock(i + 5, j + 2, k + 7, Blocks.air);
			world.setBlock(i + 5, j + 2, k + 8, Blocks.air);
			world.setBlock(i + 5, j + 2, k + 9, Blocks.air);
			world.setBlock(i + 5, j + 2, k + 10, Blocks.air);
			world.setBlock(i + 5, j + 2, k + 11, Blocks.air);
			world.setBlock(i + 5, j + 2, k + 12, Blocks.air);
			world.setBlock(i + 5, j + 2, k + 13, Blocks.air);
			world.setBlock(i + 5, j + 2, k + 14, ROCBlocks.netherrack_bricks);
			world.setBlock(i + 5, j + 2, k + 15, Blocks.netherrack);
			world.setBlock(i + 5, j + 3, k + 0, Blocks.netherrack);
			world.setBlock(i + 5, j + 3, k + 1, ROCBlocks.netherrack_bricks);
			world.setBlock(i + 5, j + 3, k + 2, Blocks.air);
			world.setBlock(i + 5, j + 3, k + 3, Blocks.air);
			world.setBlock(i + 5, j + 3, k + 4, Blocks.air);
			world.setBlock(i + 5, j + 3, k + 5, Blocks.air);
			world.setBlock(i + 5, j + 3, k + 6, Blocks.air);
			world.setBlock(i + 5, j + 3, k + 7, Blocks.air);
			world.setBlock(i + 5, j + 3, k + 8, Blocks.air);
			world.setBlock(i + 5, j + 3, k + 9, Blocks.air);
			world.setBlock(i + 5, j + 3, k + 10, Blocks.air);
			world.setBlock(i + 5, j + 3, k + 11, Blocks.air);
			world.setBlock(i + 5, j + 3, k + 12, Blocks.air);
			world.setBlock(i + 5, j + 3, k + 13, Blocks.air);
			world.setBlock(i + 5, j + 3, k + 14, ROCBlocks.netherrack_bricks);
			world.setBlock(i + 5, j + 3, k + 15, Blocks.netherrack);
			world.setBlock(i + 5, j + 4, k + 0, Blocks.netherrack);
			world.setBlock(i + 5, j + 4, k + 1, ROCBlocks.netherrack_bricks);
			world.setBlock(i + 5, j + 4, k + 2, ROCBlocks.charwood_log);
			world.setBlock(i + 5, j + 4, k + 3, ROCBlocks.charwood_log);
			world.setBlock(i + 5, j + 4, k + 4, ROCBlocks.charwood_log);
			world.setBlock(i + 5, j + 4, k + 5, ROCBlocks.charwood_log);
			world.setBlock(i + 5, j + 4, k + 6, ROCBlocks.charwood_log);
			world.setBlock(i + 5, j + 4, k + 7, ROCBlocks.charwood_log);
			world.setBlock(i + 5, j + 4, k + 8, ROCBlocks.charwood_log);
			world.setBlock(i + 5, j + 4, k + 9, ROCBlocks.charwood_log);
			world.setBlock(i + 5, j + 4, k + 10, ROCBlocks.charwood_log);
			world.setBlock(i + 5, j + 4, k + 11, ROCBlocks.charwood_log);
			world.setBlock(i + 5, j + 4, k + 12, ROCBlocks.charwood_log);
			world.setBlock(i + 5, j + 4, k + 13, ROCBlocks.charwood_log);
			world.setBlock(i + 5, j + 4, k + 14, ROCBlocks.netherrack_bricks);
			world.setBlock(i + 5, j + 4, k + 15, Blocks.netherrack);
			world.setBlock(i + 6, j + 0, k + 0, Blocks.nether_brick);
			world.setBlock(i + 6, j + 0, k + 1, Blocks.nether_brick);
			world.setBlock(i + 6, j + 0, k + 2, Blocks.nether_brick);
			world.setBlock(i + 6, j + 0, k + 3, Blocks.nether_brick);
			world.setBlock(i + 6, j + 0, k + 4, Blocks.nether_brick);
			world.setBlock(i + 6, j + 0, k + 5, Blocks.nether_brick);
			world.setBlock(i + 6, j + 0, k + 6, Blocks.nether_brick);
			world.setBlock(i + 6, j + 0, k + 7, Blocks.nether_brick);
			world.setBlock(i + 6, j + 0, k + 8, Blocks.nether_brick);
			world.setBlock(i + 6, j + 0, k + 9, Blocks.nether_brick);
			world.setBlock(i + 6, j + 0, k + 10, Blocks.nether_brick);
			world.setBlock(i + 6, j + 0, k + 11, Blocks.nether_brick);
			world.setBlock(i + 6, j + 0, k + 12, Blocks.nether_brick);
			world.setBlock(i + 6, j + 0, k + 13, Blocks.nether_brick);
			world.setBlock(i + 6, j + 0, k + 14, Blocks.nether_brick);
			world.setBlock(i + 6, j + 0, k + 15, Blocks.nether_brick);
			world.setBlock(i + 6, j + 1, k + 0, ROCBlocks.netherrack_bricks);
			world.setBlock(i + 6, j + 1, k + 1, Blocks.mob_spawner);
			TileEntityMobSpawner spawner1 = (TileEntityMobSpawner)world.getTileEntity(i+6, j+1, k+1);
			if (spawner1 != null) spawner1.func_145881_a().setEntityName("Blaze");
			world.setBlock(i + 6, j + 1, k + 2, Blocks.air);
			world.setBlock(i + 6, j + 1, k + 3, Blocks.air);
			world.setBlock(i + 6, j + 1, k + 4, Blocks.air);
			world.setBlock(i + 6, j + 1, k + 5, Blocks.air);
			world.setBlock(i + 6, j + 1, k + 6, ROCBlocks.netherrack_brick_stairs);
			world.setBlock(i + 6, j + 1, k + 7, ROCBlocks.netherrack_brick_stairs);
			world.setBlock(i + 6, j + 1, k + 8, ROCBlocks.netherrack_brick_stairs);
			world.setBlock(i + 6, j + 1, k + 9, ROCBlocks.netherrack_brick_stairs, 3, 2);
			world.setBlock(i + 6, j + 1, k + 10, Blocks.air);
			world.setBlock(i + 6, j + 1, k + 11, Blocks.air);
			world.setBlock(i + 6, j + 1, k + 12, Blocks.air);
			world.setBlock(i + 6, j + 1, k + 13, Blocks.air);
			world.setBlock(i + 6, j + 1, k + 14, Blocks.mob_spawner);
			TileEntityMobSpawner spawner2 = (TileEntityMobSpawner)world.getTileEntity(i+6, j+1, k+14);
			if (spawner2 != null) spawner2.func_145881_a().setEntityName("Blaze");
			world.setBlock(i + 6, j + 1, k + 15, ROCBlocks.netherrack_bricks);
			world.setBlock(i + 6, j + 2, k + 0, ROCBlocks.netherrack_bricks);
			world.setBlock(i + 6, j + 2, k + 1, Blocks.air);
			world.setBlock(i + 6, j + 2, k + 2, Blocks.air);
			world.setBlock(i + 6, j + 2, k + 3, Blocks.air);
			world.setBlock(i + 6, j + 2, k + 4, Blocks.air);
			world.setBlock(i + 6, j + 2, k + 5, Blocks.air);
			world.setBlock(i + 6, j + 2, k + 6, Blocks.air);
			world.setBlock(i + 6, j + 2, k + 7, Blocks.air);
			world.setBlock(i + 6, j + 2, k + 8, Blocks.air);
			world.setBlock(i + 6, j + 2, k + 9, Blocks.air);
			world.setBlock(i + 6, j + 2, k + 10, Blocks.air);
			world.setBlock(i + 6, j + 2, k + 11, Blocks.air);
			world.setBlock(i + 6, j + 2, k + 12, Blocks.air);
			world.setBlock(i + 6, j + 2, k + 13, Blocks.air);
			world.setBlock(i + 6, j + 2, k + 14, Blocks.air);
			world.setBlock(i + 6, j + 2, k + 15, ROCBlocks.netherrack_bricks);
			world.setBlock(i + 6, j + 3, k + 0, ROCBlocks.netherrack_bricks);
			world.setBlock(i + 6, j + 3, k + 1, Blocks.air);
			world.setBlock(i + 6, j + 3, k + 2, Blocks.air);
			world.setBlock(i + 6, j + 3, k + 3, Blocks.air);
			world.setBlock(i + 6, j + 3, k + 4, Blocks.air);
			world.setBlock(i + 6, j + 3, k + 5, Blocks.air);
			world.setBlock(i + 6, j + 3, k + 6, Blocks.air);
			world.setBlock(i + 6, j + 3, k + 7, Blocks.air);
			world.setBlock(i + 6, j + 3, k + 8, Blocks.air);
			world.setBlock(i + 6, j + 3, k + 9, Blocks.air);
			world.setBlock(i + 6, j + 3, k + 10, Blocks.air);
			world.setBlock(i + 6, j + 3, k + 11, Blocks.air);
			world.setBlock(i + 6, j + 3, k + 12, Blocks.air);
			world.setBlock(i + 6, j + 3, k + 13, Blocks.air);
			world.setBlock(i + 6, j + 3, k + 14, Blocks.air);
			world.setBlock(i + 6, j + 3, k + 15, ROCBlocks.netherrack_bricks);
			world.setBlock(i + 6, j + 4, k + 0, ROCBlocks.netherrack_bricks);
			world.setBlock(i + 6, j + 4, k + 1, ROCBlocks.charwood_log);
			world.setBlock(i + 6, j + 4, k + 2, ROCBlocks.charwood_log);
			world.setBlock(i + 6, j + 4, k + 3, ROCBlocks.charwood_log);
			world.setBlock(i + 6, j + 4, k + 4, ROCBlocks.charwood_log);
			world.setBlock(i + 6, j + 4, k + 5, ROCBlocks.charwood_log);
			world.setBlock(i + 6, j + 4, k + 6, ROCBlocks.charwood_log);
			world.setBlock(i + 6, j + 4, k + 7, ROCBlocks.charwood_log);
			world.setBlock(i + 6, j + 4, k + 8, ROCBlocks.charwood_log);
			world.setBlock(i + 6, j + 4, k + 9, ROCBlocks.charwood_log);
			world.setBlock(i + 6, j + 4, k + 10, ROCBlocks.charwood_log);
			world.setBlock(i + 6, j + 4, k + 11, ROCBlocks.charwood_log);
			world.setBlock(i + 6, j + 4, k + 12, ROCBlocks.charwood_log);
			world.setBlock(i + 6, j + 4, k + 13, ROCBlocks.charwood_log);
			world.setBlock(i + 6, j + 4, k + 14, ROCBlocks.charwood_log);
			world.setBlock(i + 6, j + 4, k + 15, ROCBlocks.netherrack_bricks);
			world.setBlock(i + 7, j + 0, k + 0, Blocks.nether_brick);
			world.setBlock(i + 7, j + 0, k + 1, Blocks.nether_brick);
			world.setBlock(i + 7, j + 0, k + 2, Blocks.nether_brick);
			world.setBlock(i + 7, j + 0, k + 3, Blocks.nether_brick);
			world.setBlock(i + 7, j + 0, k + 4, Blocks.nether_brick);
			world.setBlock(i + 7, j + 0, k + 5, Blocks.nether_brick);
			world.setBlock(i + 7, j + 0, k + 6, Blocks.nether_brick);
			world.setBlock(i + 7, j + 0, k + 7, Blocks.nether_brick);
			world.setBlock(i + 7, j + 0, k + 8, Blocks.nether_brick);
			world.setBlock(i + 7, j + 0, k + 9, Blocks.nether_brick);
			world.setBlock(i + 7, j + 0, k + 10, Blocks.nether_brick);
			world.setBlock(i + 7, j + 0, k + 11, Blocks.nether_brick);
			world.setBlock(i + 7, j + 0, k + 12, Blocks.nether_brick);
			world.setBlock(i + 7, j + 0, k + 13, Blocks.nether_brick);
			world.setBlock(i + 7, j + 0, k + 14, Blocks.nether_brick);
			world.setBlock(i + 7, j + 0, k + 15, Blocks.nether_brick);
			world.setBlock(i + 7, j + 1, k + 0, ROCBlocks.netherrack_bricks);
			world.setBlock(i + 7, j + 1, k + 1, Blocks.mob_spawner);
			TileEntityMobSpawner spawner3 = (TileEntityMobSpawner)world.getTileEntity(i+7, j+1, k+1);
			if (spawner3 != null) spawner3.func_145881_a().setEntityName("Blaze");
			world.setBlock(i + 7, j + 1, k + 2, Blocks.air);
			world.setBlock(i + 7, j + 1, k + 3, Blocks.air);
			world.setBlock(i + 7, j + 1, k + 4, Blocks.air);
			world.setBlock(i + 7, j + 1, k + 5, Blocks.air);
			world.setBlock(i + 7, j + 1, k + 6, ROCBlocks.netherrack_brick_stairs, 2, 2);
			world.setBlock(i + 7, j + 1, k + 9, ROCBlocks.netherrack_brick_stairs, 3, 2);
			world.setBlock(i + 7, j + 1, k + 10, Blocks.air);
			world.setBlock(i + 7, j + 1, k + 11, Blocks.air);
			world.setBlock(i + 7, j + 1, k + 12, Blocks.air);
			world.setBlock(i + 7, j + 1, k + 13, Blocks.air);
			world.setBlock(i + 7, j + 1, k + 14, Blocks.mob_spawner);
			TileEntityMobSpawner spawner4 = (TileEntityMobSpawner)world.getTileEntity(i+6, j+1, k+14);
			if (spawner4 != null) spawner4.func_145881_a().setEntityName("Blaze");
			world.setBlock(i + 7, j + 1, k + 15, ROCBlocks.netherrack_bricks);
			world.setBlock(i + 7, j + 2, k + 0, ROCBlocks.netherrack_bricks);
			world.setBlock(i + 7, j + 2, k + 1, Blocks.air);
			world.setBlock(i + 7, j + 2, k + 2, Blocks.air);
			world.setBlock(i + 7, j + 2, k + 3, Blocks.air);
			world.setBlock(i + 7, j + 2, k + 4, Blocks.air);
			world.setBlock(i + 7, j + 2, k + 5, Blocks.air);
			world.setBlock(i + 7, j + 2, k + 6, Blocks.air);
			world.setBlock(i + 7, j + 2, k + 7, Blocks.air);
			world.setBlock(i + 7, j + 2, k + 8, Blocks.air);
			world.setBlock(i + 7, j + 2, k + 9, Blocks.air);
			world.setBlock(i + 7, j + 2, k + 10, Blocks.air);
			world.setBlock(i + 7, j + 2, k + 11, Blocks.air);
			world.setBlock(i + 7, j + 2, k + 12, Blocks.air);
			world.setBlock(i + 7, j + 2, k + 13, Blocks.air);
			world.setBlock(i + 7, j + 2, k + 14, Blocks.air);
			world.setBlock(i + 7, j + 2, k + 15, ROCBlocks.netherrack_bricks);
			world.setBlock(i + 7, j + 3, k + 0, ROCBlocks.netherrack_bricks);
			world.setBlock(i + 7, j + 3, k + 1, Blocks.air);
			world.setBlock(i + 7, j + 3, k + 2, Blocks.air);
			world.setBlock(i + 7, j + 3, k + 3, Blocks.air);
			world.setBlock(i + 7, j + 3, k + 4, Blocks.air);
			world.setBlock(i + 7, j + 3, k + 5, Blocks.air);
			world.setBlock(i + 7, j + 3, k + 6, Blocks.air);
			world.setBlock(i + 7, j + 3, k + 7, Blocks.air);
			world.setBlock(i + 7, j + 3, k + 8, Blocks.air);
			world.setBlock(i + 7, j + 3, k + 9, Blocks.air);
			world.setBlock(i + 7, j + 3, k + 10, Blocks.air);
			world.setBlock(i + 7, j + 3, k + 11, Blocks.air);
			world.setBlock(i + 7, j + 3, k + 12, Blocks.air);
			world.setBlock(i + 7, j + 3, k + 13, Blocks.air);
			world.setBlock(i + 7, j + 3, k + 14, Blocks.air);
			world.setBlock(i + 7, j + 3, k + 15, ROCBlocks.netherrack_bricks);
			world.setBlock(i + 7, j + 4, k + 0, ROCBlocks.netherrack_bricks);
			world.setBlock(i + 7, j + 4, k + 1, ROCBlocks.charwood_log);
			world.setBlock(i + 7, j + 4, k + 2, ROCBlocks.charwood_log);
			world.setBlock(i + 7, j + 4, k + 3, ROCBlocks.charwood_log);
			world.setBlock(i + 7, j + 4, k + 4, ROCBlocks.charwood_log);
			world.setBlock(i + 7, j + 4, k + 5, ROCBlocks.charwood_log);
			world.setBlock(i + 7, j + 4, k + 6, ROCBlocks.charwood_log);
			world.setBlock(i + 7, j + 4, k + 7, ROCBlocks.charwood_log);
			world.setBlock(i + 7, j + 4, k + 8, ROCBlocks.charwood_log);
			world.setBlock(i + 7, j + 4, k + 9, ROCBlocks.charwood_log);
			world.setBlock(i + 7, j + 4, k + 10, ROCBlocks.charwood_log);
			world.setBlock(i + 7, j + 4, k + 11, ROCBlocks.charwood_log);
			world.setBlock(i + 7, j + 4, k + 12, ROCBlocks.charwood_log);
			world.setBlock(i + 7, j + 4, k + 13, ROCBlocks.charwood_log);
			world.setBlock(i + 7, j + 4, k + 14, ROCBlocks.charwood_log);
			world.setBlock(i + 7, j + 4, k + 15, ROCBlocks.netherrack_bricks);
			world.setBlock(i + 8, j + 0, k + 0, Blocks.netherrack);
			world.setBlock(i + 8, j + 0, k + 1, Blocks.nether_brick);
			world.setBlock(i + 8, j + 0, k + 2, Blocks.nether_brick);
			world.setBlock(i + 8, j + 0, k + 3, Blocks.nether_brick);
			world.setBlock(i + 8, j + 0, k + 4, Blocks.nether_brick);
			world.setBlock(i + 8, j + 0, k + 5, Blocks.nether_brick);
			world.setBlock(i + 8, j + 0, k + 6, Blocks.nether_brick);
			world.setBlock(i + 8, j + 0, k + 7, Blocks.nether_brick);
			world.setBlock(i + 8, j + 0, k + 8, Blocks.nether_brick);
			world.setBlock(i + 8, j + 0, k + 9, Blocks.nether_brick);
			world.setBlock(i + 8, j + 0, k + 10, Blocks.nether_brick);
			world.setBlock(i + 8, j + 0, k + 11, Blocks.nether_brick);
			world.setBlock(i + 8, j + 0, k + 12, Blocks.nether_brick);
			world.setBlock(i + 8, j + 0, k + 13, Blocks.nether_brick);
			world.setBlock(i + 8, j + 0, k + 14, Blocks.nether_brick);
			world.setBlock(i + 8, j + 0, k + 15, Blocks.netherrack);
			world.setBlock(i + 8, j + 1, k + 0, Blocks.netherrack);
			world.setBlock(i + 8, j + 1, k + 1, ROCBlocks.netherrack_bricks);
			world.setBlock(i + 8, j + 1, k + 2, Blocks.air);
			world.setBlock(i + 8, j + 1, k + 3, Blocks.air);
			world.setBlock(i + 8, j + 1, k + 4, Blocks.air);
			world.setBlock(i + 8, j + 1, k + 5, Blocks.air);
			world.setBlock(i + 8, j + 1, k + 6, ROCBlocks.netherrack_brick_stairs, 2, 2);
			world.setBlock(i + 8, j + 1, k + 9, ROCBlocks.netherrack_brick_stairs, 3, 2);
			world.setBlock(i + 8, j + 1, k + 10, Blocks.air);
			world.setBlock(i + 8, j + 1, k + 11, Blocks.air);
			world.setBlock(i + 8, j + 1, k + 12, Blocks.air);
			world.setBlock(i + 8, j + 1, k + 13, Blocks.air);
			world.setBlock(i + 8, j + 1, k + 14, ROCBlocks.netherrack_bricks);
			world.setBlock(i + 8, j + 1, k + 15, Blocks.netherrack);
			world.setBlock(i + 8, j + 2, k + 0, Blocks.netherrack);
			world.setBlock(i + 8, j + 2, k + 1, ROCBlocks.netherrack_bricks);
			world.setBlock(i + 8, j + 2, k + 2, Blocks.air);
			world.setBlock(i + 8, j + 2, k + 3, Blocks.air);
			world.setBlock(i + 8, j + 2, k + 4, Blocks.air);
			world.setBlock(i + 8, j + 2, k + 5, Blocks.air);
			world.setBlock(i + 8, j + 2, k + 6, Blocks.air);
			world.setBlock(i + 8, j + 2, k + 7, Blocks.air);
			world.setBlock(i + 8, j + 2, k + 8, Blocks.air);
			world.setBlock(i + 8, j + 2, k + 9, Blocks.air);
			world.setBlock(i + 8, j + 2, k + 10, Blocks.air);
			world.setBlock(i + 8, j + 2, k + 11, Blocks.air);
			world.setBlock(i + 8, j + 2, k + 12, Blocks.air);
			world.setBlock(i + 8, j + 2, k + 13, Blocks.air);
			world.setBlock(i + 8, j + 2, k + 14, ROCBlocks.netherrack_bricks);
			world.setBlock(i + 8, j + 2, k + 15, Blocks.netherrack);
			world.setBlock(i + 8, j + 3, k + 0, Blocks.netherrack);
			world.setBlock(i + 8, j + 3, k + 1, ROCBlocks.netherrack_bricks);
			world.setBlock(i + 8, j + 3, k + 2, Blocks.air);
			world.setBlock(i + 8, j + 3, k + 3, Blocks.air);
			world.setBlock(i + 8, j + 3, k + 4, Blocks.air);
			world.setBlock(i + 8, j + 3, k + 5, Blocks.air);
			world.setBlock(i + 8, j + 3, k + 6, Blocks.air);
			world.setBlock(i + 8, j + 3, k + 7, Blocks.air);
			world.setBlock(i + 8, j + 3, k + 8, Blocks.air);
			world.setBlock(i + 8, j + 3, k + 9, Blocks.air);
			world.setBlock(i + 8, j + 3, k + 10, Blocks.air);
			world.setBlock(i + 8, j + 3, k + 11, Blocks.air);
			world.setBlock(i + 8, j + 3, k + 12, Blocks.air);
			world.setBlock(i + 8, j + 3, k + 13, Blocks.air);
			world.setBlock(i + 8, j + 3, k + 14, ROCBlocks.netherrack_bricks);
			world.setBlock(i + 8, j + 3, k + 15, Blocks.netherrack);
			world.setBlock(i + 8, j + 4, k + 0, Blocks.netherrack);
			world.setBlock(i + 8, j + 4, k + 1, ROCBlocks.netherrack_bricks);
			world.setBlock(i + 8, j + 4, k + 2, ROCBlocks.charwood_log);
			world.setBlock(i + 8, j + 4, k + 3, ROCBlocks.charwood_log);
			world.setBlock(i + 8, j + 4, k + 4, ROCBlocks.charwood_log);
			world.setBlock(i + 8, j + 4, k + 5, ROCBlocks.charwood_log);
			world.setBlock(i + 8, j + 4, k + 6, ROCBlocks.charwood_log);
			world.setBlock(i + 8, j + 4, k + 7, ROCBlocks.charwood_log);
			world.setBlock(i + 8, j + 4, k + 8, ROCBlocks.charwood_log);
			world.setBlock(i + 8, j + 4, k + 9, ROCBlocks.charwood_log);
			world.setBlock(i + 8, j + 4, k + 10, ROCBlocks.charwood_log);
			world.setBlock(i + 8, j + 4, k + 11, ROCBlocks.charwood_log);
			world.setBlock(i + 8, j + 4, k + 12, ROCBlocks.charwood_log);
			world.setBlock(i + 8, j + 4, k + 13, ROCBlocks.charwood_log);
			world.setBlock(i + 8, j + 4, k + 14, ROCBlocks.netherrack_bricks);
			world.setBlock(i + 8, j + 4, k + 15, Blocks.netherrack);
			world.setBlock(i + 9, j + 0, k + 0, Blocks.netherrack);
			world.setBlock(i + 9, j + 0, k + 1, Blocks.nether_brick);
			world.setBlock(i + 9, j + 0, k + 2, Blocks.nether_brick);
			world.setBlock(i + 9, j + 0, k + 3, Blocks.nether_brick);
			world.setBlock(i + 9, j + 0, k + 4, Blocks.nether_brick);
			world.setBlock(i + 9, j + 0, k + 5, Blocks.nether_brick);
			world.setBlock(i + 9, j + 0, k + 6, Blocks.nether_brick);
			world.setBlock(i + 9, j + 0, k + 7, Blocks.nether_brick);
			world.setBlock(i + 9, j + 0, k + 8, Blocks.nether_brick);
			world.setBlock(i + 9, j + 0, k + 9, Blocks.nether_brick);
			world.setBlock(i + 9, j + 0, k + 10, Blocks.nether_brick);
			world.setBlock(i + 9, j + 0, k + 11, Blocks.nether_brick);
			world.setBlock(i + 9, j + 0, k + 12, Blocks.nether_brick);
			world.setBlock(i + 9, j + 0, k + 13, Blocks.nether_brick);
			world.setBlock(i + 9, j + 0, k + 14, Blocks.nether_brick);
			world.setBlock(i + 9, j + 0, k + 15, Blocks.netherrack);
			world.setBlock(i + 9, j + 1, k + 0, Blocks.netherrack);
			world.setBlock(i + 9, j + 1, k + 1, ROCBlocks.netherrack_bricks);
			world.setBlock(i + 9, j + 1, k + 2, Blocks.air);
			world.setBlock(i + 9, j + 1, k + 3, Blocks.air);
			world.setBlock(i + 9, j + 1, k + 4, Blocks.air);
			world.setBlock(i + 9, j + 1, k + 5, Blocks.air);
			world.setBlock(i + 9, j + 1, k + 6, ROCBlocks.netherrack_brick_stairs, 1, 2);
			world.setBlock(i + 9, j + 1, k + 7, ROCBlocks.netherrack_brick_stairs, 1, 2);
			world.setBlock(i + 9, j + 1, k + 8, ROCBlocks.netherrack_brick_stairs, 1, 2);
			world.setBlock(i + 9, j + 1, k + 9, ROCBlocks.netherrack_brick_stairs, 3, 2);
			world.setBlock(i + 9, j + 1, k + 10, Blocks.air);
			world.setBlock(i + 9, j + 1, k + 11, Blocks.air);
			world.setBlock(i + 9, j + 1, k + 12, Blocks.air);
			world.setBlock(i + 9, j + 1, k + 13, Blocks.air);
			world.setBlock(i + 9, j + 1, k + 14, ROCBlocks.netherrack_bricks);
			world.setBlock(i + 9, j + 1, k + 15, Blocks.netherrack);
			world.setBlock(i + 9, j + 2, k + 0, Blocks.netherrack);
			world.setBlock(i + 9, j + 2, k + 1, ROCBlocks.netherrack_bricks);
			world.setBlock(i + 9, j + 2, k + 2, Blocks.air);
			world.setBlock(i + 9, j + 2, k + 3, Blocks.air);
			world.setBlock(i + 9, j + 2, k + 4, Blocks.air);
			world.setBlock(i + 9, j + 2, k + 5, Blocks.air);
			world.setBlock(i + 9, j + 2, k + 6, Blocks.air);
			world.setBlock(i + 9, j + 2, k + 7, Blocks.air);
			world.setBlock(i + 9, j + 2, k + 8, Blocks.air);
			world.setBlock(i + 9, j + 2, k + 9, Blocks.air);
			world.setBlock(i + 9, j + 2, k + 10, Blocks.air);
			world.setBlock(i + 9, j + 2, k + 11, Blocks.air);
			world.setBlock(i + 9, j + 2, k + 12, Blocks.air);
			world.setBlock(i + 9, j + 2, k + 13, Blocks.air);
			world.setBlock(i + 9, j + 2, k + 14, ROCBlocks.netherrack_bricks);
			world.setBlock(i + 9, j + 2, k + 15, Blocks.netherrack);
			world.setBlock(i + 9, j + 3, k + 0, Blocks.netherrack);
			world.setBlock(i + 9, j + 3, k + 1, ROCBlocks.netherrack_bricks);
			world.setBlock(i + 9, j + 3, k + 2, Blocks.air);
			world.setBlock(i + 9, j + 3, k + 3, Blocks.air);
			world.setBlock(i + 9, j + 3, k + 4, Blocks.air);
			world.setBlock(i + 9, j + 3, k + 5, Blocks.air);
			world.setBlock(i + 9, j + 3, k + 6, Blocks.air);
			world.setBlock(i + 9, j + 3, k + 7, Blocks.air);
			world.setBlock(i + 9, j + 3, k + 8, Blocks.air);
			world.setBlock(i + 9, j + 3, k + 9, Blocks.air);
			world.setBlock(i + 9, j + 3, k + 10, Blocks.air);
			world.setBlock(i + 9, j + 3, k + 11, Blocks.air);
			world.setBlock(i + 9, j + 3, k + 12, Blocks.air);
			world.setBlock(i + 9, j + 3, k + 13, Blocks.air);
			world.setBlock(i + 9, j + 3, k + 14, ROCBlocks.netherrack_bricks);
			world.setBlock(i + 9, j + 3, k + 15, Blocks.netherrack);
			world.setBlock(i + 9, j + 4, k + 0, Blocks.netherrack);
			world.setBlock(i + 9, j + 4, k + 1, ROCBlocks.netherrack_bricks);
			world.setBlock(i + 9, j + 4, k + 2, ROCBlocks.charwood_log);
			world.setBlock(i + 9, j + 4, k + 3, ROCBlocks.charwood_log);
			world.setBlock(i + 9, j + 4, k + 4, ROCBlocks.charwood_log);
			world.setBlock(i + 9, j + 4, k + 5, ROCBlocks.charwood_log);
			world.setBlock(i + 9, j + 4, k + 6, ROCBlocks.charwood_log);
			world.setBlock(i + 9, j + 4, k + 7, ROCBlocks.charwood_log);
			world.setBlock(i + 9, j + 4, k + 8, ROCBlocks.charwood_log);
			world.setBlock(i + 9, j + 4, k + 9, ROCBlocks.charwood_log);
			world.setBlock(i + 9, j + 4, k + 10, ROCBlocks.charwood_log);
			world.setBlock(i + 9, j + 4, k + 11, ROCBlocks.charwood_log);
			world.setBlock(i + 9, j + 4, k + 12, ROCBlocks.charwood_log);
			world.setBlock(i + 9, j + 4, k + 13, ROCBlocks.charwood_log);
			world.setBlock(i + 9, j + 4, k + 14, ROCBlocks.netherrack_bricks);
			world.setBlock(i + 9, j + 4, k + 15, Blocks.netherrack);
			world.setBlock(i + 10, j + 0, k + 0, Blocks.netherrack);
			world.setBlock(i + 10, j + 0, k + 1, Blocks.netherrack);
			world.setBlock(i + 10, j + 0, k + 2, Blocks.nether_brick);
			world.setBlock(i + 10, j + 0, k + 3, Blocks.nether_brick);
			world.setBlock(i + 10, j + 0, k + 4, Blocks.nether_brick);
			world.setBlock(i + 10, j + 0, k + 5, Blocks.nether_brick);
			world.setBlock(i + 10, j + 0, k + 6, Blocks.nether_brick);
			world.setBlock(i + 10, j + 0, k + 7, Blocks.nether_brick);
			world.setBlock(i + 10, j + 0, k + 8, Blocks.nether_brick);
			world.setBlock(i + 10, j + 0, k + 9, Blocks.nether_brick);
			world.setBlock(i + 10, j + 0, k + 10, Blocks.nether_brick);
			world.setBlock(i + 10, j + 0, k + 11, Blocks.nether_brick);
			world.setBlock(i + 10, j + 0, k + 12, Blocks.nether_brick);
			world.setBlock(i + 10, j + 0, k + 13, Blocks.nether_brick);
			world.setBlock(i + 10, j + 0, k + 14, Blocks.netherrack);
			world.setBlock(i + 10, j + 0, k + 15, Blocks.netherrack);
			world.setBlock(i + 10, j + 1, k + 0, Blocks.netherrack);
			world.setBlock(i + 10, j + 1, k + 1, Blocks.netherrack);
			world.setBlock(i + 10, j + 1, k + 2, ROCBlocks.netherrack_bricks);
			world.setBlock(i + 10, j + 1, k + 3, Blocks.air);
			world.setBlock(i + 10, j + 1, k + 4, Blocks.air);
			world.setBlock(i + 10, j + 1, k + 5, Blocks.air);
			world.setBlock(i + 10, j + 1, k + 6, Blocks.air);
			world.setBlock(i + 10, j + 1, k + 7, Blocks.air);
			world.setBlock(i + 10, j + 1, k + 8, Blocks.air);
			world.setBlock(i + 10, j + 1, k + 9, Blocks.air);
			world.setBlock(i + 10, j + 1, k + 10, Blocks.air);
			world.setBlock(i + 10, j + 1, k + 11, Blocks.air);
			world.setBlock(i + 10, j + 1, k + 12, Blocks.air);
			world.setBlock(i + 10, j + 1, k + 13, ROCBlocks.netherrack_bricks);
			world.setBlock(i + 10, j + 1, k + 14, Blocks.netherrack);
			world.setBlock(i + 10, j + 1, k + 15, Blocks.netherrack);
			world.setBlock(i + 10, j + 2, k + 0, Blocks.netherrack);
			world.setBlock(i + 10, j + 2, k + 1, Blocks.netherrack);
			world.setBlock(i + 10, j + 2, k + 2, ROCBlocks.netherrack_bricks);
			world.setBlock(i + 10, j + 2, k + 3, Blocks.air);
			world.setBlock(i + 10, j + 2, k + 4, Blocks.air);
			world.setBlock(i + 10, j + 2, k + 5, Blocks.air);
			world.setBlock(i + 10, j + 2, k + 6, Blocks.air);
			world.setBlock(i + 10, j + 2, k + 7, Blocks.air);
			world.setBlock(i + 10, j + 2, k + 8, Blocks.air);
			world.setBlock(i + 10, j + 2, k + 9, Blocks.air);
			world.setBlock(i + 10, j + 2, k + 10, Blocks.air);
			world.setBlock(i + 10, j + 2, k + 11, Blocks.air);
			world.setBlock(i + 10, j + 2, k + 12, Blocks.air);
			world.setBlock(i + 10, j + 2, k + 13, ROCBlocks.netherrack_bricks);
			world.setBlock(i + 10, j + 2, k + 14, Blocks.netherrack);
			world.setBlock(i + 10, j + 2, k + 15, Blocks.netherrack);
			world.setBlock(i + 10, j + 3, k + 0, Blocks.netherrack);
			world.setBlock(i + 10, j + 3, k + 1, Blocks.netherrack);
			world.setBlock(i + 10, j + 3, k + 2, ROCBlocks.netherrack_bricks);
			world.setBlock(i + 10, j + 3, k + 3, Blocks.air);
			world.setBlock(i + 10, j + 3, k + 4, Blocks.air);
			world.setBlock(i + 10, j + 3, k + 5, Blocks.air);
			world.setBlock(i + 10, j + 3, k + 6, Blocks.air);
			world.setBlock(i + 10, j + 3, k + 7, Blocks.air);
			world.setBlock(i + 10, j + 3, k + 8, Blocks.air);
			world.setBlock(i + 10, j + 3, k + 9, Blocks.air);
			world.setBlock(i + 10, j + 3, k + 10, Blocks.air);
			world.setBlock(i + 10, j + 3, k + 11, Blocks.air);
			world.setBlock(i + 10, j + 3, k + 12, Blocks.air);
			world.setBlock(i + 10, j + 3, k + 13, ROCBlocks.netherrack_bricks);
			world.setBlock(i + 10, j + 3, k + 14, Blocks.netherrack);
			world.setBlock(i + 10, j + 3, k + 15, Blocks.netherrack);
			world.setBlock(i + 10, j + 4, k + 0, Blocks.netherrack);
			world.setBlock(i + 10, j + 4, k + 1, Blocks.netherrack);
			world.setBlock(i + 10, j + 4, k + 2, ROCBlocks.netherrack_bricks);
			world.setBlock(i + 10, j + 4, k + 3, ROCBlocks.charwood_log);
			world.setBlock(i + 10, j + 4, k + 4, ROCBlocks.charwood_log);
			world.setBlock(i + 10, j + 4, k + 5, ROCBlocks.charwood_log);
			world.setBlock(i + 10, j + 4, k + 6, ROCBlocks.charwood_log);
			world.setBlock(i + 10, j + 4, k + 7, ROCBlocks.charwood_log);
			world.setBlock(i + 10, j + 4, k + 8, ROCBlocks.charwood_log);
			world.setBlock(i + 10, j + 4, k + 9, ROCBlocks.charwood_log);
			world.setBlock(i + 10, j + 4, k + 10, ROCBlocks.charwood_log);
			world.setBlock(i + 10, j + 4, k + 11, ROCBlocks.charwood_log);
			world.setBlock(i + 10, j + 4, k + 12, ROCBlocks.charwood_log);
			world.setBlock(i + 10, j + 4, k + 13, ROCBlocks.netherrack_bricks);
			world.setBlock(i + 10, j + 4, k + 14, Blocks.netherrack);
			world.setBlock(i + 10, j + 4, k + 15, Blocks.netherrack);
			world.setBlock(i + 11, j + 0, k + 0, Blocks.netherrack);
			world.setBlock(i + 11, j + 0, k + 1, Blocks.netherrack);
			world.setBlock(i + 11, j + 0, k + 2, Blocks.netherrack);
			world.setBlock(i + 11, j + 0, k + 3, Blocks.nether_brick);
			world.setBlock(i + 11, j + 0, k + 4, Blocks.nether_brick);
			world.setBlock(i + 11, j + 0, k + 5, Blocks.nether_brick);
			world.setBlock(i + 11, j + 0, k + 6, Blocks.nether_brick);
			world.setBlock(i + 11, j + 0, k + 7, Blocks.nether_brick);
			world.setBlock(i + 11, j + 0, k + 8, Blocks.nether_brick);
			world.setBlock(i + 11, j + 0, k + 9, Blocks.nether_brick);
			world.setBlock(i + 11, j + 0, k + 10, Blocks.nether_brick);
			world.setBlock(i + 11, j + 0, k + 11, Blocks.nether_brick);
			world.setBlock(i + 11, j + 0, k + 12, Blocks.nether_brick);
			world.setBlock(i + 11, j + 0, k + 13, Blocks.netherrack);
			world.setBlock(i + 11, j + 0, k + 14, Blocks.netherrack);
			world.setBlock(i + 11, j + 0, k + 15, Blocks.netherrack);
			world.setBlock(i + 11, j + 1, k + 0, Blocks.netherrack);
			world.setBlock(i + 11, j + 1, k + 1, Blocks.netherrack);
			world.setBlock(i + 11, j + 1, k + 2, Blocks.netherrack);
			world.setBlock(i + 11, j + 1, k + 3, ROCBlocks.netherrack_bricks);
			world.setBlock(i + 11, j + 1, k + 4, ROCBlocks.netherrack_bricks);
			world.setBlock(i + 11, j + 1, k + 5, Blocks.air);
			world.setBlock(i + 11, j + 1, k + 6, Blocks.air);
			world.setBlock(i + 11, j + 1, k + 7, Blocks.air);
			world.setBlock(i + 11, j + 1, k + 8, Blocks.air);
			world.setBlock(i + 11, j + 1, k + 9, Blocks.air);
			world.setBlock(i + 11, j + 1, k + 10, Blocks.air);
			world.setBlock(i + 11, j + 1, k + 11, ROCBlocks.netherrack_bricks);
			world.setBlock(i + 11, j + 1, k + 12, ROCBlocks.netherrack_bricks);
			world.setBlock(i + 11, j + 1, k + 13, Blocks.netherrack);
			world.setBlock(i + 11, j + 1, k + 14, Blocks.netherrack);
			world.setBlock(i + 11, j + 1, k + 15, Blocks.netherrack);
			world.setBlock(i + 11, j + 2, k + 0, Blocks.netherrack);
			world.setBlock(i + 11, j + 2, k + 1, Blocks.netherrack);
			world.setBlock(i + 11, j + 2, k + 2, Blocks.netherrack);
			world.setBlock(i + 11, j + 2, k + 3, ROCBlocks.netherrack_bricks);
			world.setBlock(i + 11, j + 2, k + 4, ROCBlocks.netherrack_bricks);
			world.setBlock(i + 11, j + 2, k + 5, Blocks.air);
			world.setBlock(i + 11, j + 2, k + 6, Blocks.air);
			world.setBlock(i + 11, j + 2, k + 7, Blocks.air);
			world.setBlock(i + 11, j + 2, k + 8, Blocks.air);
			world.setBlock(i + 11, j + 2, k + 9, Blocks.air);
			world.setBlock(i + 11, j + 2, k + 10, Blocks.air);
			world.setBlock(i + 11, j + 2, k + 11, ROCBlocks.netherrack_bricks);
			world.setBlock(i + 11, j + 2, k + 12, ROCBlocks.netherrack_bricks);
			world.setBlock(i + 11, j + 2, k + 13, Blocks.netherrack);
			world.setBlock(i + 11, j + 2, k + 14, Blocks.netherrack);
			world.setBlock(i + 11, j + 2, k + 15, Blocks.netherrack);
			world.setBlock(i + 11, j + 3, k + 0, Blocks.netherrack);
			world.setBlock(i + 11, j + 3, k + 1, Blocks.netherrack);
			world.setBlock(i + 11, j + 3, k + 2, Blocks.netherrack);
			world.setBlock(i + 11, j + 3, k + 3, ROCBlocks.netherrack_bricks);
			world.setBlock(i + 11, j + 3, k + 4, ROCBlocks.netherrack_bricks);
			world.setBlock(i + 11, j + 3, k + 5, Blocks.air);
			world.setBlock(i + 11, j + 3, k + 6, Blocks.air);
			world.setBlock(i + 11, j + 3, k + 7, Blocks.air);
			world.setBlock(i + 11, j + 3, k + 8, Blocks.air);
			world.setBlock(i + 11, j + 3, k + 9, Blocks.air);
			world.setBlock(i + 11, j + 3, k + 10, Blocks.air);
			world.setBlock(i + 11, j + 3, k + 11, ROCBlocks.netherrack_bricks);
			world.setBlock(i + 11, j + 3, k + 12, ROCBlocks.netherrack_bricks);
			world.setBlock(i + 11, j + 3, k + 13, Blocks.netherrack);
			world.setBlock(i + 11, j + 3, k + 14, Blocks.netherrack);
			world.setBlock(i + 11, j + 3, k + 15, Blocks.netherrack);
			world.setBlock(i + 11, j + 4, k + 0, Blocks.netherrack);
			world.setBlock(i + 11, j + 4, k + 1, Blocks.netherrack);
			world.setBlock(i + 11, j + 4, k + 2, Blocks.netherrack);
			world.setBlock(i + 11, j + 4, k + 3, ROCBlocks.netherrack_bricks);
			world.setBlock(i + 11, j + 4, k + 4, ROCBlocks.netherrack_bricks);
			world.setBlock(i + 11, j + 4, k + 5, ROCBlocks.charwood_log);
			world.setBlock(i + 11, j + 4, k + 6, ROCBlocks.charwood_log);
			world.setBlock(i + 11, j + 4, k + 7, ROCBlocks.charwood_log);
			world.setBlock(i + 11, j + 4, k + 8, ROCBlocks.charwood_log);
			world.setBlock(i + 11, j + 4, k + 9, ROCBlocks.charwood_log);
			world.setBlock(i + 11, j + 4, k + 10, ROCBlocks.charwood_log);
			world.setBlock(i + 11, j + 4, k + 11, ROCBlocks.netherrack_bricks);
			world.setBlock(i + 11, j + 4, k + 12, ROCBlocks.netherrack_bricks);
			world.setBlock(i + 11, j + 4, k + 13, Blocks.netherrack);
			world.setBlock(i + 11, j + 4, k + 14, Blocks.netherrack);
			world.setBlock(i + 11, j + 4, k + 15, Blocks.netherrack);
			world.setBlock(i + 12, j + 0, k + 0, Blocks.netherrack);
			world.setBlock(i + 12, j + 0, k + 1, Blocks.netherrack);
			world.setBlock(i + 12, j + 0, k + 2, Blocks.netherrack);
			world.setBlock(i + 12, j + 0, k + 3, Blocks.netherrack);
			world.setBlock(i + 12, j + 0, k + 4, Blocks.netherrack);
			world.setBlock(i + 12, j + 0, k + 5, Blocks.nether_brick);
			world.setBlock(i + 12, j + 0, k + 6, Blocks.nether_brick);
			world.setBlock(i + 12, j + 0, k + 7, Blocks.nether_brick);
			world.setBlock(i + 12, j + 0, k + 8, Blocks.nether_brick);
			world.setBlock(i + 12, j + 0, k + 9, Blocks.nether_brick);
			world.setBlock(i + 12, j + 0, k + 10, Blocks.nether_brick);
			world.setBlock(i + 12, j + 0, k + 11, Blocks.netherrack);
			world.setBlock(i + 12, j + 0, k + 12, Blocks.netherrack);
			world.setBlock(i + 12, j + 0, k + 13, Blocks.netherrack);
			world.setBlock(i + 12, j + 0, k + 14, Blocks.netherrack);
			world.setBlock(i + 12, j + 0, k + 15, Blocks.netherrack);
			world.setBlock(i + 12, j + 1, k + 0, Blocks.netherrack);
			world.setBlock(i + 12, j + 1, k + 1, Blocks.netherrack);
			world.setBlock(i + 12, j + 1, k + 2, Blocks.netherrack);
			world.setBlock(i + 12, j + 1, k + 3, Blocks.netherrack);
			world.setBlock(i + 12, j + 1, k + 4, Blocks.netherrack);
			world.setBlock(i + 12, j + 1, k + 5, ROCBlocks.netherrack_bricks);
			world.setBlock(i + 12, j + 1, k + 6, Blocks.air);
			world.setBlock(i + 12, j + 1, k + 7, Blocks.air);
			world.setBlock(i + 12, j + 1, k + 8, Blocks.air);
			world.setBlock(i + 12, j + 1, k + 9, Blocks.air);
			world.setBlock(i + 12, j + 1, k + 10, ROCBlocks.netherrack_bricks);
			world.setBlock(i + 12, j + 1, k + 11, Blocks.netherrack);
			world.setBlock(i + 12, j + 1, k + 12, Blocks.netherrack);
			world.setBlock(i + 12, j + 1, k + 13, Blocks.netherrack);
			world.setBlock(i + 12, j + 1, k + 14, Blocks.netherrack);
			world.setBlock(i + 12, j + 1, k + 15, Blocks.netherrack);
			world.setBlock(i + 12, j + 2, k + 0, Blocks.netherrack);
			world.setBlock(i + 12, j + 2, k + 1, Blocks.netherrack);
			world.setBlock(i + 12, j + 2, k + 2, Blocks.netherrack);
			world.setBlock(i + 12, j + 2, k + 3, Blocks.netherrack);
			world.setBlock(i + 12, j + 2, k + 4, Blocks.netherrack);
			world.setBlock(i + 12, j + 2, k + 5, ROCBlocks.netherrack_bricks);
			world.setBlock(i + 12, j + 2, k + 6, Blocks.air);
			world.setBlock(i + 12, j + 2, k + 7, Blocks.air);
			world.setBlock(i + 12, j + 2, k + 8, Blocks.air);
			world.setBlock(i + 12, j + 2, k + 9, Blocks.air);
			world.setBlock(i + 12, j + 2, k + 10, ROCBlocks.netherrack_bricks);
			world.setBlock(i + 12, j + 2, k + 11, Blocks.netherrack);
			world.setBlock(i + 12, j + 2, k + 12, Blocks.netherrack);
			world.setBlock(i + 12, j + 2, k + 13, Blocks.netherrack);
			world.setBlock(i + 12, j + 2, k + 14, Blocks.netherrack);
			world.setBlock(i + 12, j + 2, k + 15, Blocks.netherrack);
			world.setBlock(i + 12, j + 3, k + 0, Blocks.netherrack);
			world.setBlock(i + 12, j + 3, k + 1, Blocks.netherrack);
			world.setBlock(i + 12, j + 3, k + 2, Blocks.netherrack);
			world.setBlock(i + 12, j + 3, k + 3, Blocks.netherrack);
			world.setBlock(i + 12, j + 3, k + 4, Blocks.netherrack);
			world.setBlock(i + 12, j + 3, k + 5, ROCBlocks.netherrack_bricks);
			world.setBlock(i + 12, j + 3, k + 6, Blocks.air);
			world.setBlock(i + 12, j + 3, k + 7, Blocks.air);
			world.setBlock(i + 12, j + 3, k + 8, Blocks.air);
			world.setBlock(i + 12, j + 3, k + 9, Blocks.air);
			world.setBlock(i + 12, j + 3, k + 10, ROCBlocks.netherrack_bricks);
			world.setBlock(i + 12, j + 3, k + 11, Blocks.netherrack);
			world.setBlock(i + 12, j + 3, k + 12, Blocks.netherrack);
			world.setBlock(i + 12, j + 3, k + 13, Blocks.netherrack);
			world.setBlock(i + 12, j + 3, k + 14, Blocks.netherrack);
			world.setBlock(i + 12, j + 3, k + 15, Blocks.netherrack);
			world.setBlock(i + 12, j + 4, k + 0, Blocks.netherrack);
			world.setBlock(i + 12, j + 4, k + 1, Blocks.netherrack);
			world.setBlock(i + 12, j + 4, k + 2, Blocks.netherrack);
			world.setBlock(i + 12, j + 4, k + 3, Blocks.netherrack);
			world.setBlock(i + 12, j + 4, k + 4, Blocks.netherrack);
			world.setBlock(i + 12, j + 4, k + 5, ROCBlocks.netherrack_bricks);
			world.setBlock(i + 12, j + 4, k + 6, ROCBlocks.charwood_log);
			world.setBlock(i + 12, j + 4, k + 7, ROCBlocks.charwood_log);
			world.setBlock(i + 12, j + 4, k + 8, ROCBlocks.charwood_log);
			world.setBlock(i + 12, j + 4, k + 9, ROCBlocks.charwood_log);
			world.setBlock(i + 12, j + 4, k + 10, ROCBlocks.netherrack_bricks);
			world.setBlock(i + 12, j + 4, k + 11, Blocks.netherrack);
			world.setBlock(i + 12, j + 4, k + 12, Blocks.netherrack);
			world.setBlock(i + 12, j + 4, k + 13, Blocks.netherrack);
			world.setBlock(i + 12, j + 4, k + 14, Blocks.netherrack);
			world.setBlock(i + 12, j + 4, k + 15, Blocks.netherrack);
			world.setBlock(i + 13, j + 0, k + 0, Blocks.netherrack);
			world.setBlock(i + 13, j + 0, k + 1, Blocks.netherrack);
			world.setBlock(i + 13, j + 0, k + 2, Blocks.netherrack);
			world.setBlock(i + 13, j + 0, k + 3, Blocks.netherrack);
			world.setBlock(i + 13, j + 0, k + 4, Blocks.netherrack);
			world.setBlock(i + 13, j + 0, k + 5, Blocks.netherrack);
			world.setBlock(i + 13, j + 0, k + 6, Blocks.nether_brick);
			world.setBlock(i + 13, j + 0, k + 7, Blocks.nether_brick);
			world.setBlock(i + 13, j + 0, k + 8, Blocks.nether_brick);
			world.setBlock(i + 13, j + 0, k + 9, Blocks.nether_brick);
			world.setBlock(i + 13, j + 0, k + 10, Blocks.netherrack);
			world.setBlock(i + 13, j + 0, k + 11, Blocks.netherrack);
			world.setBlock(i + 13, j + 0, k + 12, Blocks.netherrack);
			world.setBlock(i + 13, j + 0, k + 13, Blocks.netherrack);
			world.setBlock(i + 13, j + 0, k + 14, Blocks.netherrack);
			world.setBlock(i + 13, j + 0, k + 15, Blocks.netherrack);
			world.setBlock(i + 13, j + 1, k + 0, Blocks.netherrack);
			world.setBlock(i + 13, j + 1, k + 1, Blocks.netherrack);
			world.setBlock(i + 13, j + 1, k + 2, Blocks.netherrack);
			world.setBlock(i + 13, j + 1, k + 3, Blocks.netherrack);
			world.setBlock(i + 13, j + 1, k + 4, Blocks.netherrack);
			world.setBlock(i + 13, j + 1, k + 5, Blocks.netherrack);
			world.setBlock(i + 13, j + 1, k + 6, ROCBlocks.netherrack_bricks);
			world.setBlock(i + 13, j + 1, k + 7, Blocks.air);
			world.setBlock(i + 13, j + 1, k + 8, Blocks.air);
			world.setBlock(i + 13, j + 1, k + 9, ROCBlocks.netherrack_bricks);
			world.setBlock(i + 13, j + 1, k + 10, Blocks.netherrack);
			world.setBlock(i + 13, j + 1, k + 11, Blocks.netherrack);
			world.setBlock(i + 13, j + 1, k + 12, Blocks.netherrack);
			world.setBlock(i + 13, j + 1, k + 13, Blocks.netherrack);
			world.setBlock(i + 13, j + 1, k + 14, Blocks.netherrack);
			world.setBlock(i + 13, j + 1, k + 15, Blocks.netherrack);
			world.setBlock(i + 13, j + 2, k + 0, Blocks.netherrack);
			world.setBlock(i + 13, j + 2, k + 1, Blocks.netherrack);
			world.setBlock(i + 13, j + 2, k + 2, Blocks.netherrack);
			world.setBlock(i + 13, j + 2, k + 3, Blocks.netherrack);
			world.setBlock(i + 13, j + 2, k + 4, Blocks.netherrack);
			world.setBlock(i + 13, j + 2, k + 5, Blocks.netherrack);
			world.setBlock(i + 13, j + 2, k + 6, ROCBlocks.netherrack_bricks);
			world.setBlock(i + 13, j + 2, k + 7, Blocks.air);
			world.setBlock(i + 13, j + 2, k + 8, Blocks.air);
			world.setBlock(i + 13, j + 2, k + 9, ROCBlocks.netherrack_bricks);
			world.setBlock(i + 13, j + 2, k + 10, Blocks.netherrack);
			world.setBlock(i + 13, j + 2, k + 11, Blocks.netherrack);
			world.setBlock(i + 13, j + 2, k + 12, Blocks.netherrack);
			world.setBlock(i + 13, j + 2, k + 13, Blocks.netherrack);
			world.setBlock(i + 13, j + 2, k + 14, Blocks.netherrack);
			world.setBlock(i + 13, j + 2, k + 15, Blocks.netherrack);
			world.setBlock(i + 13, j + 3, k + 0, Blocks.netherrack);
			world.setBlock(i + 13, j + 3, k + 1, Blocks.netherrack);
			world.setBlock(i + 13, j + 3, k + 2, Blocks.netherrack);
			world.setBlock(i + 13, j + 3, k + 3, Blocks.netherrack);
			world.setBlock(i + 13, j + 3, k + 4, Blocks.netherrack);
			world.setBlock(i + 13, j + 3, k + 5, Blocks.netherrack);
			world.setBlock(i + 13, j + 3, k + 6, ROCBlocks.netherrack_bricks);
			world.setBlock(i + 13, j + 3, k + 7, Blocks.air);
			world.setBlock(i + 13, j + 3, k + 8, Blocks.air);
			world.setBlock(i + 13, j + 3, k + 9, ROCBlocks.netherrack_bricks);
			world.setBlock(i + 13, j + 3, k + 10, Blocks.netherrack);
			world.setBlock(i + 13, j + 3, k + 11, Blocks.netherrack);
			world.setBlock(i + 13, j + 3, k + 12, Blocks.netherrack);
			world.setBlock(i + 13, j + 3, k + 13, Blocks.netherrack);
			world.setBlock(i + 13, j + 3, k + 14, Blocks.netherrack);
			world.setBlock(i + 13, j + 3, k + 15, Blocks.netherrack);
			world.setBlock(i + 13, j + 4, k + 0, Blocks.netherrack);
			world.setBlock(i + 13, j + 4, k + 1, Blocks.netherrack);
			world.setBlock(i + 13, j + 4, k + 2, Blocks.netherrack);
			world.setBlock(i + 13, j + 4, k + 3, Blocks.netherrack);
			world.setBlock(i + 13, j + 4, k + 4, Blocks.netherrack);
			world.setBlock(i + 13, j + 4, k + 5, Blocks.netherrack);
			world.setBlock(i + 13, j + 4, k + 6, ROCBlocks.netherrack_bricks);
			world.setBlock(i + 13, j + 4, k + 7, ROCBlocks.charwood_log);
			world.setBlock(i + 13, j + 4, k + 8, ROCBlocks.charwood_log);
			world.setBlock(i + 13, j + 4, k + 9, ROCBlocks.netherrack_bricks);
			world.setBlock(i + 13, j + 4, k + 10, Blocks.netherrack);
			world.setBlock(i + 13, j + 4, k + 11, Blocks.netherrack);
			world.setBlock(i + 13, j + 4, k + 12, Blocks.netherrack);
			world.setBlock(i + 13, j + 4, k + 13, Blocks.netherrack);
			world.setBlock(i + 13, j + 4, k + 14, Blocks.netherrack);
			world.setBlock(i + 13, j + 4, k + 15, Blocks.netherrack);
			world.setBlock(i + 14, j + 0, k + 0, Blocks.netherrack);
			world.setBlock(i + 14, j + 0, k + 1, Blocks.netherrack);
			world.setBlock(i + 14, j + 0, k + 2, Blocks.netherrack);
			world.setBlock(i + 14, j + 0, k + 3, Blocks.netherrack);
			world.setBlock(i + 14, j + 0, k + 4, Blocks.netherrack);
			world.setBlock(i + 14, j + 0, k + 5, Blocks.netherrack);
			world.setBlock(i + 14, j + 0, k + 6, ROCBlocks.netherrack_bricks);
			world.setBlock(i + 14, j + 0, k + 7, Blocks.nether_brick);
			world.setBlock(i + 14, j + 0, k + 8, Blocks.nether_brick);
			world.setBlock(i + 14, j + 0, k + 9, ROCBlocks.netherrack_bricks);
			world.setBlock(i + 14, j + 0, k + 10, Blocks.netherrack);
			world.setBlock(i + 14, j + 0, k + 11, Blocks.netherrack);
			world.setBlock(i + 14, j + 0, k + 12, Blocks.netherrack);
			world.setBlock(i + 14, j + 0, k + 13, Blocks.netherrack);
			world.setBlock(i + 14, j + 0, k + 14, Blocks.netherrack);
			world.setBlock(i + 14, j + 0, k + 15, Blocks.netherrack);
			world.setBlock(i + 14, j + 1, k + 0, Blocks.netherrack);
			world.setBlock(i + 14, j + 1, k + 1, Blocks.netherrack);
			world.setBlock(i + 14, j + 1, k + 2, Blocks.netherrack);
			world.setBlock(i + 14, j + 1, k + 3, Blocks.netherrack);
			world.setBlock(i + 14, j + 1, k + 4, Blocks.netherrack);
			world.setBlock(i + 14, j + 1, k + 5, Blocks.netherrack);
			world.setBlock(i + 14, j + 1, k + 6, ROCBlocks.netherrack_bricks);
			world.setBlock(i + 14, j + 1, k + 7, Blocks.air);
			world.setBlock(i + 14, j + 1, k + 8, Blocks.air);
			world.setBlock(i + 14, j + 1, k + 9, ROCBlocks.netherrack_bricks);
			world.setBlock(i + 14, j + 1, k + 10, Blocks.netherrack);
			world.setBlock(i + 14, j + 1, k + 11, Blocks.netherrack);
			world.setBlock(i + 14, j + 1, k + 12, Blocks.netherrack);
			world.setBlock(i + 14, j + 1, k + 13, Blocks.netherrack);
			world.setBlock(i + 14, j + 1, k + 14, Blocks.netherrack);
			world.setBlock(i + 14, j + 1, k + 15, Blocks.netherrack);
			world.setBlock(i + 14, j + 2, k + 0, Blocks.netherrack);
			world.setBlock(i + 14, j + 2, k + 1, Blocks.netherrack);
			world.setBlock(i + 14, j + 2, k + 2, Blocks.netherrack);
			world.setBlock(i + 14, j + 2, k + 3, Blocks.netherrack);
			world.setBlock(i + 14, j + 2, k + 4, Blocks.netherrack);
			world.setBlock(i + 14, j + 2, k + 5, Blocks.netherrack);
			world.setBlock(i + 14, j + 2, k + 6, ROCBlocks.netherrack_bricks);
			world.setBlock(i + 14, j + 2, k + 7, Blocks.air);
			world.setBlock(i + 14, j + 2, k + 8, Blocks.air);
			world.setBlock(i + 14, j + 2, k + 9, ROCBlocks.netherrack_bricks);
			world.setBlock(i + 14, j + 2, k + 10, Blocks.netherrack);
			world.setBlock(i + 14, j + 2, k + 11, Blocks.netherrack);
			world.setBlock(i + 14, j + 2, k + 12, Blocks.netherrack);
			world.setBlock(i + 14, j + 2, k + 13, Blocks.netherrack);
			world.setBlock(i + 14, j + 2, k + 14, Blocks.netherrack);
			world.setBlock(i + 14, j + 2, k + 15, Blocks.netherrack);
			world.setBlock(i + 14, j + 3, k + 0, Blocks.netherrack);
			world.setBlock(i + 14, j + 3, k + 1, Blocks.netherrack);
			world.setBlock(i + 14, j + 3, k + 2, Blocks.netherrack);
			world.setBlock(i + 14, j + 3, k + 3, Blocks.netherrack);
			world.setBlock(i + 14, j + 3, k + 4, Blocks.netherrack);
			world.setBlock(i + 14, j + 3, k + 5, Blocks.netherrack);
			world.setBlock(i + 14, j + 3, k + 6, ROCBlocks.netherrack_bricks);
			world.setBlock(i + 14, j + 3, k + 7, Blocks.air);
			world.setBlock(i + 14, j + 3, k + 8, Blocks.air);
			world.setBlock(i + 14, j + 3, k + 9, ROCBlocks.netherrack_bricks);
			world.setBlock(i + 14, j + 3, k + 10, Blocks.netherrack);
			world.setBlock(i + 14, j + 3, k + 11, Blocks.netherrack);
			world.setBlock(i + 14, j + 3, k + 12, Blocks.netherrack);
			world.setBlock(i + 14, j + 3, k + 13, Blocks.netherrack);
			world.setBlock(i + 14, j + 3, k + 14, Blocks.netherrack);
			world.setBlock(i + 14, j + 3, k + 15, Blocks.netherrack);
			world.setBlock(i + 14, j + 4, k + 0, Blocks.netherrack);
			world.setBlock(i + 14, j + 4, k + 1, Blocks.netherrack);
			world.setBlock(i + 14, j + 4, k + 2, Blocks.netherrack);
			world.setBlock(i + 14, j + 4, k + 3, Blocks.netherrack);
			world.setBlock(i + 14, j + 4, k + 4, Blocks.netherrack);
			world.setBlock(i + 14, j + 4, k + 5, Blocks.netherrack);
			world.setBlock(i + 14, j + 4, k + 6, ROCBlocks.netherrack_bricks);
			world.setBlock(i + 14, j + 4, k + 7, Blocks.nether_brick);
			world.setBlock(i + 14, j + 4, k + 8, Blocks.nether_brick);
			world.setBlock(i + 14, j + 4, k + 9, ROCBlocks.netherrack_bricks);
			world.setBlock(i + 14, j + 4, k + 10, Blocks.netherrack);
			world.setBlock(i + 14, j + 4, k + 11, Blocks.netherrack);
			world.setBlock(i + 14, j + 4, k + 12, Blocks.netherrack);
			world.setBlock(i + 14, j + 4, k + 13, Blocks.netherrack);
			world.setBlock(i + 14, j + 4, k + 14, Blocks.netherrack);
			world.setBlock(i + 14, j + 4, k + 15, Blocks.netherrack);
			world.setBlock(i + 15, j + 0, k + 0, Blocks.netherrack);
			world.setBlock(i + 15, j + 0, k + 1, Blocks.netherrack);
			world.setBlock(i + 15, j + 0, k + 2, Blocks.netherrack);
			world.setBlock(i + 15, j + 0, k + 3, Blocks.netherrack);
			world.setBlock(i + 15, j + 0, k + 4, Blocks.netherrack);
			world.setBlock(i + 15, j + 0, k + 5, Blocks.netherrack);
			world.setBlock(i + 15, j + 0, k + 6, ROCBlocks.netherrack_bricks);
			world.setBlock(i + 15, j + 0, k + 7, Blocks.nether_brick);
			world.setBlock(i + 15, j + 0, k + 8, Blocks.nether_brick);
			world.setBlock(i + 15, j + 0, k + 9, ROCBlocks.netherrack_bricks);
			world.setBlock(i + 15, j + 0, k + 10, Blocks.netherrack);
			world.setBlock(i + 15, j + 0, k + 11, Blocks.netherrack);
			world.setBlock(i + 15, j + 0, k + 12, Blocks.netherrack);
			world.setBlock(i + 15, j + 0, k + 13, Blocks.netherrack);
			world.setBlock(i + 15, j + 0, k + 14, Blocks.netherrack);
			world.setBlock(i + 15, j + 0, k + 15, Blocks.netherrack);
			world.setBlock(i + 15, j + 1, k + 0, Blocks.netherrack);
			world.setBlock(i + 15, j + 1, k + 1, Blocks.netherrack);
			world.setBlock(i + 15, j + 1, k + 2, Blocks.netherrack);
			world.setBlock(i + 15, j + 1, k + 3, Blocks.netherrack);
			world.setBlock(i + 15, j + 1, k + 4, Blocks.netherrack);
			world.setBlock(i + 15, j + 1, k + 5, Blocks.netherrack);
			world.setBlock(i + 15, j + 1, k + 6, ROCBlocks.netherrack_bricks);
			world.setBlock(i + 15, j + 1, k + 7, Blocks.air);
			world.setBlock(i + 15, j + 1, k + 8, Blocks.air);
			world.setBlock(i + 15, j + 1, k + 9, ROCBlocks.netherrack_bricks);
			world.setBlock(i + 15, j + 1, k + 10, Blocks.netherrack);
			world.setBlock(i + 15, j + 1, k + 11, Blocks.netherrack);
			world.setBlock(i + 15, j + 1, k + 12, Blocks.netherrack);
			world.setBlock(i + 15, j + 1, k + 13, Blocks.netherrack);
			world.setBlock(i + 15, j + 1, k + 14, Blocks.netherrack);
			world.setBlock(i + 15, j + 1, k + 15, Blocks.netherrack);
			world.setBlock(i + 15, j + 2, k + 0, Blocks.netherrack);
			world.setBlock(i + 15, j + 2, k + 1, Blocks.netherrack);
			world.setBlock(i + 15, j + 2, k + 2, Blocks.netherrack);
			world.setBlock(i + 15, j + 2, k + 3, Blocks.netherrack);
			world.setBlock(i + 15, j + 2, k + 4, Blocks.netherrack);
			world.setBlock(i + 15, j + 2, k + 5, Blocks.netherrack);
			world.setBlock(i + 15, j + 2, k + 6, ROCBlocks.netherrack_bricks);
			world.setBlock(i + 15, j + 2, k + 7, Blocks.air);
			world.setBlock(i + 15, j + 2, k + 8, Blocks.air);
			world.setBlock(i + 15, j + 2, k + 9, ROCBlocks.netherrack_bricks);
			world.setBlock(i + 15, j + 2, k + 10, Blocks.netherrack);
			world.setBlock(i + 15, j + 2, k + 11, Blocks.netherrack);
			world.setBlock(i + 15, j + 2, k + 12, Blocks.netherrack);
			world.setBlock(i + 15, j + 2, k + 13, Blocks.netherrack);
			world.setBlock(i + 15, j + 2, k + 14, Blocks.netherrack);
			world.setBlock(i + 15, j + 2, k + 15, Blocks.netherrack);
			world.setBlock(i + 15, j + 3, k + 0, Blocks.netherrack);
			world.setBlock(i + 15, j + 3, k + 1, Blocks.netherrack);
			world.setBlock(i + 15, j + 3, k + 2, Blocks.netherrack);
			world.setBlock(i + 15, j + 3, k + 3, Blocks.netherrack);
			world.setBlock(i + 15, j + 3, k + 4, Blocks.netherrack);
			world.setBlock(i + 15, j + 3, k + 5, Blocks.netherrack);
			world.setBlock(i + 15, j + 3, k + 6, ROCBlocks.netherrack_bricks);
			world.setBlock(i + 15, j + 3, k + 7, Blocks.air);
			world.setBlock(i + 15, j + 3, k + 8, Blocks.air);
			world.setBlock(i + 15, j + 3, k + 9, ROCBlocks.netherrack_bricks);
			world.setBlock(i + 15, j + 3, k + 10, Blocks.netherrack);
			world.setBlock(i + 15, j + 3, k + 11, Blocks.netherrack);
			world.setBlock(i + 15, j + 3, k + 12, Blocks.netherrack);
			world.setBlock(i + 15, j + 3, k + 13, Blocks.netherrack);
			world.setBlock(i + 15, j + 3, k + 14, Blocks.netherrack);
			world.setBlock(i + 15, j + 3, k + 15, Blocks.netherrack);
			world.setBlock(i + 15, j + 4, k + 0, Blocks.netherrack);
			world.setBlock(i + 15, j + 4, k + 1, Blocks.netherrack);
			world.setBlock(i + 15, j + 4, k + 2, Blocks.netherrack);
			world.setBlock(i + 15, j + 4, k + 3, Blocks.netherrack);
			world.setBlock(i + 15, j + 4, k + 4, Blocks.netherrack);
			world.setBlock(i + 15, j + 4, k + 5, Blocks.netherrack);
			world.setBlock(i + 15, j + 4, k + 6, ROCBlocks.netherrack_bricks);
			world.setBlock(i + 15, j + 4, k + 7, Blocks.nether_brick);
			world.setBlock(i + 15, j + 4, k + 8, Blocks.nether_brick);
			world.setBlock(i + 15, j + 4, k + 9, ROCBlocks.netherrack_bricks);
			world.setBlock(i + 15, j + 4, k + 10, Blocks.netherrack);
			world.setBlock(i + 15, j + 4, k + 11, Blocks.netherrack);
			world.setBlock(i + 15, j + 4, k + 12, Blocks.netherrack);
			world.setBlock(i + 15, j + 4, k + 13, Blocks.netherrack);
			world.setBlock(i + 15, j + 4, k + 14, Blocks.netherrack);
			world.setBlock(i + 15, j + 4, k + 15, Blocks.netherrack);
			world.setBlock(i + 16, j + 0, k + 0, Blocks.netherrack);
			world.setBlock(i + 16, j + 0, k + 1, Blocks.netherrack);
			world.setBlock(i + 16, j + 0, k + 2, Blocks.netherrack);
			world.setBlock(i + 16, j + 0, k + 3, Blocks.netherrack);
			world.setBlock(i + 16, j + 0, k + 4, Blocks.netherrack);
			world.setBlock(i + 16, j + 0, k + 5, Blocks.netherrack);
			world.setBlock(i + 16, j + 0, k + 6, ROCBlocks.netherrack_bricks);
			world.setBlock(i + 16, j + 0, k + 7, Blocks.nether_brick);
			world.setBlock(i + 16, j + 0, k + 8, Blocks.nether_brick);
			world.setBlock(i + 16, j + 0, k + 9, ROCBlocks.netherrack_bricks);
			world.setBlock(i + 16, j + 0, k + 10, Blocks.netherrack);
			world.setBlock(i + 16, j + 0, k + 11, Blocks.netherrack);
			world.setBlock(i + 16, j + 0, k + 12, Blocks.netherrack);
			world.setBlock(i + 16, j + 0, k + 13, Blocks.netherrack);
			world.setBlock(i + 16, j + 0, k + 14, Blocks.netherrack);
			world.setBlock(i + 16, j + 0, k + 15, Blocks.netherrack);
			world.setBlock(i + 16, j + 1, k + 0, Blocks.netherrack);
			world.setBlock(i + 16, j + 1, k + 1, Blocks.netherrack);
			world.setBlock(i + 16, j + 1, k + 2, Blocks.netherrack);
			world.setBlock(i + 16, j + 1, k + 3, Blocks.netherrack);
			world.setBlock(i + 16, j + 1, k + 4, Blocks.netherrack);
			world.setBlock(i + 16, j + 1, k + 5, Blocks.netherrack);
			world.setBlock(i + 16, j + 1, k + 6, ROCBlocks.netherrack_bricks);
			world.setBlock(i + 16, j + 1, k + 7, Blocks.air);
			world.setBlock(i + 16, j + 1, k + 8, Blocks.air);
			world.setBlock(i + 16, j + 1, k + 9, ROCBlocks.netherrack_bricks);
			world.setBlock(i + 16, j + 1, k + 10, Blocks.netherrack);
			world.setBlock(i + 16, j + 1, k + 11, Blocks.netherrack);
			world.setBlock(i + 16, j + 1, k + 12, Blocks.netherrack);
			world.setBlock(i + 16, j + 1, k + 13, Blocks.netherrack);
			world.setBlock(i + 16, j + 1, k + 14, Blocks.netherrack);
			world.setBlock(i + 16, j + 1, k + 15, Blocks.netherrack);
			world.setBlock(i + 16, j + 2, k + 0, Blocks.netherrack);
			world.setBlock(i + 16, j + 2, k + 1, Blocks.netherrack);
			world.setBlock(i + 16, j + 2, k + 2, Blocks.netherrack);
			world.setBlock(i + 16, j + 2, k + 3, Blocks.netherrack);
			world.setBlock(i + 16, j + 2, k + 4, Blocks.netherrack);
			world.setBlock(i + 16, j + 2, k + 5, Blocks.netherrack);
			world.setBlock(i + 16, j + 2, k + 6, ROCBlocks.netherrack_bricks);
			world.setBlock(i + 16, j + 2, k + 7, Blocks.air);
			world.setBlock(i + 16, j + 2, k + 8, Blocks.air);
			world.setBlock(i + 16, j + 2, k + 9, ROCBlocks.netherrack_bricks);
			world.setBlock(i + 16, j + 2, k + 10, Blocks.netherrack);
			world.setBlock(i + 16, j + 2, k + 11, Blocks.netherrack);
			world.setBlock(i + 16, j + 2, k + 12, Blocks.netherrack);
			world.setBlock(i + 16, j + 2, k + 13, Blocks.netherrack);
			world.setBlock(i + 16, j + 2, k + 14, Blocks.netherrack);
			world.setBlock(i + 16, j + 2, k + 15, Blocks.netherrack);
			world.setBlock(i + 16, j + 3, k + 0, Blocks.netherrack);
			world.setBlock(i + 16, j + 3, k + 1, Blocks.netherrack);
			world.setBlock(i + 16, j + 3, k + 2, Blocks.netherrack);
			world.setBlock(i + 16, j + 3, k + 3, Blocks.netherrack);
			world.setBlock(i + 16, j + 3, k + 4, Blocks.netherrack);
			world.setBlock(i + 16, j + 3, k + 5, Blocks.netherrack);
			world.setBlock(i + 16, j + 3, k + 6, ROCBlocks.netherrack_bricks);
			world.setBlock(i + 16, j + 3, k + 7, Blocks.air);
			world.setBlock(i + 16, j + 3, k + 8, Blocks.air);
			world.setBlock(i + 16, j + 3, k + 9, ROCBlocks.netherrack_bricks);
			world.setBlock(i + 16, j + 3, k + 10, Blocks.netherrack);
			world.setBlock(i + 16, j + 3, k + 11, Blocks.netherrack);
			world.setBlock(i + 16, j + 3, k + 12, Blocks.netherrack);
			world.setBlock(i + 16, j + 3, k + 13, Blocks.netherrack);
			world.setBlock(i + 16, j + 3, k + 14, Blocks.netherrack);
			world.setBlock(i + 16, j + 3, k + 15, Blocks.netherrack);
			world.setBlock(i + 16, j + 4, k + 0, Blocks.netherrack);
			world.setBlock(i + 16, j + 4, k + 1, Blocks.netherrack);
			world.setBlock(i + 16, j + 4, k + 2, Blocks.netherrack);
			world.setBlock(i + 16, j + 4, k + 3, Blocks.netherrack);
			world.setBlock(i + 16, j + 4, k + 4, Blocks.netherrack);
			world.setBlock(i + 16, j + 4, k + 5, Blocks.netherrack);
			world.setBlock(i + 16, j + 4, k + 6, ROCBlocks.netherrack_bricks);
			world.setBlock(i + 16, j + 4, k + 7, Blocks.nether_brick);
			world.setBlock(i + 16, j + 4, k + 8, Blocks.nether_brick);
			world.setBlock(i + 16, j + 4, k + 9, ROCBlocks.netherrack_bricks);
			world.setBlock(i + 16, j + 4, k + 10, Blocks.netherrack);
			world.setBlock(i + 16, j + 4, k + 11, Blocks.netherrack);
			world.setBlock(i + 16, j + 4, k + 12, Blocks.netherrack);
			world.setBlock(i + 16, j + 4, k + 13, Blocks.netherrack);
			world.setBlock(i + 16, j + 4, k + 14, Blocks.netherrack);
			world.setBlock(i + 16, j + 4, k + 15, Blocks.netherrack);
			world.setBlock(i + 17, j + 0, k + 0, Blocks.netherrack);
			world.setBlock(i + 17, j + 0, k + 1, Blocks.netherrack);
			world.setBlock(i + 17, j + 0, k + 2, Blocks.netherrack);
			world.setBlock(i + 17, j + 0, k + 3, Blocks.netherrack);
			world.setBlock(i + 17, j + 0, k + 4, Blocks.netherrack);
			world.setBlock(i + 17, j + 0, k + 5, Blocks.netherrack);
			world.setBlock(i + 17, j + 0, k + 6, ROCBlocks.netherrack_bricks);
			world.setBlock(i + 17, j + 0, k + 7, Blocks.nether_brick);
			world.setBlock(i + 17, j + 0, k + 8, Blocks.nether_brick);
			world.setBlock(i + 17, j + 0, k + 9, ROCBlocks.netherrack_bricks);
			world.setBlock(i + 17, j + 0, k + 10, Blocks.netherrack);
			world.setBlock(i + 17, j + 0, k + 11, Blocks.netherrack);
			world.setBlock(i + 17, j + 0, k + 12, Blocks.netherrack);
			world.setBlock(i + 17, j + 0, k + 13, Blocks.netherrack);
			world.setBlock(i + 17, j + 0, k + 14, Blocks.netherrack);
			world.setBlock(i + 17, j + 0, k + 15, Blocks.netherrack);
			world.setBlock(i + 17, j + 1, k + 0, Blocks.netherrack);
			world.setBlock(i + 17, j + 1, k + 1, Blocks.netherrack);
			world.setBlock(i + 17, j + 1, k + 2, Blocks.netherrack);
			world.setBlock(i + 17, j + 1, k + 3, Blocks.netherrack);
			world.setBlock(i + 17, j + 1, k + 4, Blocks.netherrack);
			world.setBlock(i + 17, j + 1, k + 5, Blocks.netherrack);
			world.setBlock(i + 17, j + 1, k + 6, ROCBlocks.netherrack_bricks);
			world.setBlock(i + 17, j + 1, k + 7, Blocks.air);
			world.setBlock(i + 17, j + 1, k + 8, Blocks.air);
			world.setBlock(i + 17, j + 1, k + 9, ROCBlocks.netherrack_bricks);
			world.setBlock(i + 17, j + 1, k + 10, Blocks.netherrack);
			world.setBlock(i + 17, j + 1, k + 11, Blocks.netherrack);
			world.setBlock(i + 17, j + 1, k + 12, Blocks.netherrack);
			world.setBlock(i + 17, j + 1, k + 13, Blocks.netherrack);
			world.setBlock(i + 17, j + 1, k + 14, Blocks.netherrack);
			world.setBlock(i + 17, j + 1, k + 15, Blocks.netherrack);
			world.setBlock(i + 17, j + 2, k + 0, Blocks.netherrack);
			world.setBlock(i + 17, j + 2, k + 1, Blocks.netherrack);
			world.setBlock(i + 17, j + 2, k + 2, Blocks.netherrack);
			world.setBlock(i + 17, j + 2, k + 3, Blocks.netherrack);
			world.setBlock(i + 17, j + 2, k + 4, Blocks.netherrack);
			world.setBlock(i + 17, j + 2, k + 5, Blocks.netherrack);
			world.setBlock(i + 17, j + 2, k + 6, ROCBlocks.netherrack_bricks);
			world.setBlock(i + 17, j + 2, k + 7, Blocks.air);
			world.setBlock(i + 17, j + 2, k + 8, Blocks.air);
			world.setBlock(i + 17, j + 2, k + 9, ROCBlocks.netherrack_bricks);
			world.setBlock(i + 17, j + 2, k + 10, Blocks.netherrack);
			world.setBlock(i + 17, j + 2, k + 11, Blocks.netherrack);
			world.setBlock(i + 17, j + 2, k + 12, Blocks.netherrack);
			world.setBlock(i + 17, j + 2, k + 13, Blocks.netherrack);
			world.setBlock(i + 17, j + 2, k + 14, Blocks.netherrack);
			world.setBlock(i + 17, j + 2, k + 15, Blocks.netherrack);
			world.setBlock(i + 17, j + 3, k + 0, Blocks.netherrack);
			world.setBlock(i + 17, j + 3, k + 1, Blocks.netherrack);
			world.setBlock(i + 17, j + 3, k + 2, Blocks.netherrack);
			world.setBlock(i + 17, j + 3, k + 3, Blocks.netherrack);
			world.setBlock(i + 17, j + 3, k + 4, Blocks.netherrack);
			world.setBlock(i + 17, j + 3, k + 5, Blocks.netherrack);
			world.setBlock(i + 17, j + 3, k + 6, ROCBlocks.netherrack_bricks);
			world.setBlock(i + 17, j + 3, k + 7, Blocks.air);
			world.setBlock(i + 17, j + 3, k + 8, Blocks.air);
			world.setBlock(i + 17, j + 3, k + 9, ROCBlocks.netherrack_bricks);
			world.setBlock(i + 17, j + 3, k + 10, Blocks.netherrack);
			world.setBlock(i + 17, j + 3, k + 11, Blocks.netherrack);
			world.setBlock(i + 17, j + 3, k + 12, Blocks.netherrack);
			world.setBlock(i + 17, j + 3, k + 13, Blocks.netherrack);
			world.setBlock(i + 17, j + 3, k + 14, Blocks.netherrack);
			world.setBlock(i + 17, j + 3, k + 15, Blocks.netherrack);
			world.setBlock(i + 17, j + 4, k + 0, Blocks.netherrack);
			world.setBlock(i + 17, j + 4, k + 1, Blocks.netherrack);
			world.setBlock(i + 17, j + 4, k + 2, Blocks.netherrack);
			world.setBlock(i + 17, j + 4, k + 3, Blocks.netherrack);
			world.setBlock(i + 17, j + 4, k + 4, Blocks.netherrack);
			world.setBlock(i + 17, j + 4, k + 5, Blocks.netherrack);
			world.setBlock(i + 17, j + 4, k + 6, ROCBlocks.netherrack_bricks);
			world.setBlock(i + 17, j + 4, k + 7, Blocks.nether_brick);
			world.setBlock(i + 17, j + 4, k + 8, Blocks.nether_brick);
			world.setBlock(i + 17, j + 4, k + 9, ROCBlocks.netherrack_bricks);
			world.setBlock(i + 17, j + 4, k + 10, Blocks.netherrack);
			world.setBlock(i + 17, j + 4, k + 11, Blocks.netherrack);
			world.setBlock(i + 17, j + 4, k + 12, Blocks.netherrack);
			world.setBlock(i + 17, j + 4, k + 13, Blocks.netherrack);
			world.setBlock(i + 17, j + 4, k + 14, Blocks.netherrack);
			world.setBlock(i + 17, j + 4, k + 15, Blocks.netherrack);
			world.setBlock(i + 18, j + 0, k + 0, Blocks.netherrack);
			world.setBlock(i + 18, j + 0, k + 1, Blocks.netherrack);
			world.setBlock(i + 18, j + 0, k + 2, Blocks.netherrack);
			world.setBlock(i + 18, j + 0, k + 3, Blocks.netherrack);
			world.setBlock(i + 18, j + 0, k + 4, Blocks.netherrack);
			world.setBlock(i + 18, j + 0, k + 5, Blocks.netherrack);
			world.setBlock(i + 18, j + 0, k + 6, ROCBlocks.netherrack_bricks);
			world.setBlock(i + 18, j + 0, k + 7, Blocks.nether_brick);
			world.setBlock(i + 18, j + 0, k + 8, Blocks.nether_brick);
			world.setBlock(i + 18, j + 0, k + 9, ROCBlocks.netherrack_bricks);
			world.setBlock(i + 18, j + 0, k + 10, Blocks.netherrack);
			world.setBlock(i + 18, j + 0, k + 11, Blocks.netherrack);
			world.setBlock(i + 18, j + 0, k + 12, Blocks.netherrack);
			world.setBlock(i + 18, j + 0, k + 13, Blocks.netherrack);
			world.setBlock(i + 18, j + 0, k + 14, Blocks.netherrack);
			world.setBlock(i + 18, j + 0, k + 15, Blocks.netherrack);
			world.setBlock(i + 18, j + 1, k + 0, Blocks.netherrack);
			world.setBlock(i + 18, j + 1, k + 1, Blocks.netherrack);
			world.setBlock(i + 18, j + 1, k + 2, Blocks.netherrack);
			world.setBlock(i + 18, j + 1, k + 3, Blocks.netherrack);
			world.setBlock(i + 18, j + 1, k + 4, Blocks.netherrack);
			world.setBlock(i + 18, j + 1, k + 5, Blocks.netherrack);
			world.setBlock(i + 18, j + 1, k + 6, ROCBlocks.netherrack_bricks);
			world.setBlock(i + 18, j + 1, k + 7, Blocks.air);
			world.setBlock(i + 18, j + 1, k + 8, Blocks.air);
			world.setBlock(i + 18, j + 1, k + 9, ROCBlocks.netherrack_bricks);
			world.setBlock(i + 18, j + 1, k + 10, Blocks.netherrack);
			world.setBlock(i + 18, j + 1, k + 11, Blocks.netherrack);
			world.setBlock(i + 18, j + 1, k + 12, Blocks.netherrack);
			world.setBlock(i + 18, j + 1, k + 13, Blocks.netherrack);
			world.setBlock(i + 18, j + 1, k + 14, Blocks.netherrack);
			world.setBlock(i + 18, j + 1, k + 15, Blocks.netherrack);
			world.setBlock(i + 18, j + 2, k + 0, Blocks.netherrack);
			world.setBlock(i + 18, j + 2, k + 1, Blocks.netherrack);
			world.setBlock(i + 18, j + 2, k + 2, Blocks.netherrack);
			world.setBlock(i + 18, j + 2, k + 3, Blocks.netherrack);
			world.setBlock(i + 18, j + 2, k + 4, Blocks.netherrack);
			world.setBlock(i + 18, j + 2, k + 5, Blocks.netherrack);
			world.setBlock(i + 18, j + 2, k + 6, ROCBlocks.netherrack_bricks);
			world.setBlock(i + 18, j + 2, k + 7, Blocks.air);
			world.setBlock(i + 18, j + 2, k + 8, Blocks.air);
			world.setBlock(i + 18, j + 2, k + 9, ROCBlocks.netherrack_bricks);
			world.setBlock(i + 18, j + 2, k + 10, Blocks.netherrack);
			world.setBlock(i + 18, j + 2, k + 11, Blocks.netherrack);
			world.setBlock(i + 18, j + 2, k + 12, Blocks.netherrack);
			world.setBlock(i + 18, j + 2, k + 13, Blocks.netherrack);
			world.setBlock(i + 18, j + 2, k + 14, Blocks.netherrack);
			world.setBlock(i + 18, j + 2, k + 15, Blocks.netherrack);
			world.setBlock(i + 18, j + 3, k + 0, Blocks.netherrack);
			world.setBlock(i + 18, j + 3, k + 1, Blocks.netherrack);
			world.setBlock(i + 18, j + 3, k + 2, Blocks.netherrack);
			world.setBlock(i + 18, j + 3, k + 3, Blocks.netherrack);
			world.setBlock(i + 18, j + 3, k + 4, Blocks.netherrack);
			world.setBlock(i + 18, j + 3, k + 5, Blocks.netherrack);
			world.setBlock(i + 18, j + 3, k + 6, ROCBlocks.netherrack_bricks);
			world.setBlock(i + 18, j + 3, k + 7, Blocks.air);
			world.setBlock(i + 18, j + 3, k + 8, Blocks.air);
			world.setBlock(i + 18, j + 3, k + 9, ROCBlocks.netherrack_bricks);
			world.setBlock(i + 18, j + 3, k + 10, Blocks.netherrack);
			world.setBlock(i + 18, j + 3, k + 11, Blocks.netherrack);
			world.setBlock(i + 18, j + 3, k + 12, Blocks.netherrack);
			world.setBlock(i + 18, j + 3, k + 13, Blocks.netherrack);
			world.setBlock(i + 18, j + 3, k + 14, Blocks.netherrack);
			world.setBlock(i + 18, j + 3, k + 15, Blocks.netherrack);
			world.setBlock(i + 18, j + 4, k + 0, Blocks.netherrack);
			world.setBlock(i + 18, j + 4, k + 1, Blocks.netherrack);
			world.setBlock(i + 18, j + 4, k + 2, Blocks.netherrack);
			world.setBlock(i + 18, j + 4, k + 3, Blocks.netherrack);
			world.setBlock(i + 18, j + 4, k + 4, Blocks.netherrack);
			world.setBlock(i + 18, j + 4, k + 5, Blocks.netherrack);
			world.setBlock(i + 18, j + 4, k + 6, ROCBlocks.netherrack_bricks);
			world.setBlock(i + 18, j + 4, k + 7, Blocks.nether_brick);
			world.setBlock(i + 18, j + 4, k + 8, Blocks.nether_brick);
			world.setBlock(i + 18, j + 4, k + 9, ROCBlocks.netherrack_bricks);
			world.setBlock(i + 18, j + 4, k + 10, Blocks.netherrack);
			world.setBlock(i + 18, j + 4, k + 11, Blocks.netherrack);
			world.setBlock(i + 18, j + 4, k + 12, Blocks.netherrack);
			world.setBlock(i + 18, j + 4, k + 13, Blocks.netherrack);
			world.setBlock(i + 18, j + 4, k + 14, Blocks.netherrack);
			world.setBlock(i + 18, j + 4, k + 15, Blocks.netherrack);
			world.setBlock(i + 19, j + 0, k + 0, Blocks.netherrack);
			world.setBlock(i + 19, j + 0, k + 1, Blocks.netherrack);
			world.setBlock(i + 19, j + 0, k + 2, Blocks.netherrack);
			world.setBlock(i + 19, j + 0, k + 3, Blocks.netherrack);
			world.setBlock(i + 19, j + 0, k + 4, Blocks.netherrack);
			world.setBlock(i + 19, j + 0, k + 5, Blocks.netherrack);
			world.setBlock(i + 19, j + 0, k + 6, ROCBlocks.netherrack_bricks);
			world.setBlock(i + 19, j + 0, k + 7, Blocks.nether_brick);
			world.setBlock(i + 19, j + 0, k + 8, Blocks.nether_brick);
			world.setBlock(i + 19, j + 0, k + 9, ROCBlocks.netherrack_bricks);
			world.setBlock(i + 19, j + 0, k + 10, Blocks.netherrack);
			world.setBlock(i + 19, j + 0, k + 11, Blocks.netherrack);
			world.setBlock(i + 19, j + 0, k + 12, Blocks.netherrack);
			world.setBlock(i + 19, j + 0, k + 13, Blocks.netherrack);
			world.setBlock(i + 19, j + 0, k + 14, Blocks.netherrack);
			world.setBlock(i + 19, j + 0, k + 15, Blocks.netherrack);
			world.setBlock(i + 19, j + 1, k + 0, Blocks.netherrack);
			world.setBlock(i + 19, j + 1, k + 1, Blocks.netherrack);
			world.setBlock(i + 19, j + 1, k + 2, Blocks.netherrack);
			world.setBlock(i + 19, j + 1, k + 3, Blocks.netherrack);
			world.setBlock(i + 19, j + 1, k + 4, Blocks.netherrack);
			world.setBlock(i + 19, j + 1, k + 5, Blocks.netherrack);
			world.setBlock(i + 19, j + 1, k + 6, ROCBlocks.netherrack_bricks);
			world.setBlock(i + 19, j + 1, k + 7, Blocks.air);
			world.setBlock(i + 19, j + 1, k + 8, Blocks.air);
			world.setBlock(i + 19, j + 1, k + 9, ROCBlocks.netherrack_bricks);
			world.setBlock(i + 19, j + 1, k + 10, Blocks.netherrack);
			world.setBlock(i + 19, j + 1, k + 11, Blocks.netherrack);
			world.setBlock(i + 19, j + 1, k + 12, Blocks.netherrack);
			world.setBlock(i + 19, j + 1, k + 13, Blocks.netherrack);
			world.setBlock(i + 19, j + 1, k + 14, Blocks.netherrack);
			world.setBlock(i + 19, j + 1, k + 15, Blocks.netherrack);
			world.setBlock(i + 19, j + 2, k + 0, Blocks.netherrack);
			world.setBlock(i + 19, j + 2, k + 1, Blocks.netherrack);
			world.setBlock(i + 19, j + 2, k + 2, Blocks.netherrack);
			world.setBlock(i + 19, j + 2, k + 3, Blocks.netherrack);
			world.setBlock(i + 19, j + 2, k + 4, Blocks.netherrack);
			world.setBlock(i + 19, j + 2, k + 5, Blocks.netherrack);
			world.setBlock(i + 19, j + 2, k + 6, ROCBlocks.netherrack_bricks);
			world.setBlock(i + 19, j + 2, k + 7, Blocks.air);
			world.setBlock(i + 19, j + 2, k + 8, Blocks.air);
			world.setBlock(i + 19, j + 2, k + 9, ROCBlocks.netherrack_bricks);
			world.setBlock(i + 19, j + 2, k + 10, Blocks.netherrack);
			world.setBlock(i + 19, j + 2, k + 11, Blocks.netherrack);
			world.setBlock(i + 19, j + 2, k + 12, Blocks.netherrack);
			world.setBlock(i + 19, j + 2, k + 13, Blocks.netherrack);
			world.setBlock(i + 19, j + 2, k + 14, Blocks.netherrack);
			world.setBlock(i + 19, j + 2, k + 15, Blocks.netherrack);
			world.setBlock(i + 19, j + 3, k + 0, Blocks.netherrack);
			world.setBlock(i + 19, j + 3, k + 1, Blocks.netherrack);
			world.setBlock(i + 19, j + 3, k + 2, Blocks.netherrack);
			world.setBlock(i + 19, j + 3, k + 3, Blocks.netherrack);
			world.setBlock(i + 19, j + 3, k + 4, Blocks.netherrack);
			world.setBlock(i + 19, j + 3, k + 5, Blocks.netherrack);
			world.setBlock(i + 19, j + 3, k + 6, ROCBlocks.netherrack_bricks);
			world.setBlock(i + 19, j + 3, k + 7, Blocks.air);
			world.setBlock(i + 19, j + 3, k + 8, Blocks.air);
			world.setBlock(i + 19, j + 3, k + 9, ROCBlocks.netherrack_bricks);
			world.setBlock(i + 19, j + 3, k + 10, Blocks.netherrack);
			world.setBlock(i + 19, j + 3, k + 11, Blocks.netherrack);
			world.setBlock(i + 19, j + 3, k + 12, Blocks.netherrack);
			world.setBlock(i + 19, j + 3, k + 13, Blocks.netherrack);
			world.setBlock(i + 19, j + 3, k + 14, Blocks.netherrack);
			world.setBlock(i + 19, j + 3, k + 15, Blocks.netherrack);
			world.setBlock(i + 19, j + 4, k + 0, Blocks.netherrack);
			world.setBlock(i + 19, j + 4, k + 1, Blocks.netherrack);
			world.setBlock(i + 19, j + 4, k + 2, Blocks.netherrack);
			world.setBlock(i + 19, j + 4, k + 3, Blocks.netherrack);
			world.setBlock(i + 19, j + 4, k + 4, Blocks.netherrack);
			world.setBlock(i + 19, j + 4, k + 5, Blocks.netherrack);
			world.setBlock(i + 19, j + 4, k + 6, ROCBlocks.netherrack_bricks);
			world.setBlock(i + 19, j + 4, k + 7, Blocks.nether_brick);
			world.setBlock(i + 19, j + 4, k + 8, Blocks.nether_brick);
			world.setBlock(i + 19, j + 4, k + 9, ROCBlocks.netherrack_bricks);
			world.setBlock(i + 19, j + 4, k + 10, Blocks.netherrack);
			world.setBlock(i + 19, j + 4, k + 11, Blocks.netherrack);
			world.setBlock(i + 19, j + 4, k + 12, Blocks.netherrack);
			world.setBlock(i + 19, j + 4, k + 13, Blocks.netherrack);
			world.setBlock(i + 19, j + 4, k + 14, Blocks.netherrack);
			world.setBlock(i + 19, j + 4, k + 15, Blocks.netherrack);
			world.setBlock(i + 20, j + 0, k + 0, Blocks.netherrack);
			world.setBlock(i + 20, j + 0, k + 1, Blocks.netherrack);
			world.setBlock(i + 20, j + 0, k + 2, Blocks.netherrack);
			world.setBlock(i + 20, j + 0, k + 3, Blocks.netherrack);
			world.setBlock(i + 20, j + 0, k + 4, Blocks.netherrack);
			world.setBlock(i + 20, j + 0, k + 5, Blocks.netherrack);
			world.setBlock(i + 20, j + 0, k + 6, ROCBlocks.netherrack_bricks);
			world.setBlock(i + 20, j + 0, k + 7, Blocks.nether_brick);
			world.setBlock(i + 20, j + 0, k + 8, Blocks.nether_brick);
			world.setBlock(i + 20, j + 0, k + 9, ROCBlocks.netherrack_bricks);
			world.setBlock(i + 20, j + 0, k + 10, Blocks.netherrack);
			world.setBlock(i + 20, j + 0, k + 11, Blocks.netherrack);
			world.setBlock(i + 20, j + 0, k + 12, Blocks.netherrack);
			world.setBlock(i + 20, j + 0, k + 13, Blocks.netherrack);
			world.setBlock(i + 20, j + 0, k + 14, Blocks.netherrack);
			world.setBlock(i + 20, j + 0, k + 15, Blocks.netherrack);
			world.setBlock(i + 20, j + 1, k + 0, Blocks.netherrack);
			world.setBlock(i + 20, j + 1, k + 1, Blocks.netherrack);
			world.setBlock(i + 20, j + 1, k + 2, Blocks.netherrack);
			world.setBlock(i + 20, j + 1, k + 3, Blocks.netherrack);
			world.setBlock(i + 20, j + 1, k + 4, Blocks.netherrack);
			world.setBlock(i + 20, j + 1, k + 5, Blocks.netherrack);
